Workbook
Name echantillon: '3) Estimation valeur espérée'!#REF!
Name echantillon: '3) Estimation valeur espérée'!#REF!

Sheet Instructions
A2: Considérer une compagnie d'assurance qui souhaite décider des primes annuelles exigées pour une assurance sur la valeur totale d'une propriété en cas de sinistre grave. Le contrat d'assurance en question stipule que la valeur remboursée est égale à la valeur de la propriété telle qu'évaluée par un expert la veille du sinistre. La compagnie considère que trois critères influencent la valeur d'une propriété résidentielle : la distance du centre-ville (en km), la grandeur du terrain (en pieds carrés) et la présence d'une piscine. Des données récentes sont utilisées pour définir notre connaissance de la valeur des maisons sur ce territoire. La probabilité d'un sinistre (dans la prochaine année) est estimée en utilisant des données sur les 31 dernières années pour la région. La probabilité d'un sinistre (dans la prochaine année) est estimée en utilisant des données sur les 31 dernières années pour la région.
A3: Un client appelle pour recevoir un estimé de la prime annuelle qu'il aurait à payer pour cette assurance, il habite à 10 km du centre-ville, son terrain est de 5 000 pieds carrés et ne possède pas de piscine.
A5: Est-ce que la compagnie d'assurance peut se permettre d'offrir une prime de 2 000 $ sans déductible?
A8: Étapes de manipulation du chiffrier :
A10: 1) Déterminer un modèle stochastique pour une variable aléatoire capturant notre connaissance de la valeur d'une propriété dépendamment des informations reçues à son sujet.
A12: 1.a) Appliquer une régression linéaire sur les données « d'inférence » afin de déterminer une loi pour la distribution de la valeur de la maison conditionellement à la connaissance des trois variables influentes.
B13: - À l'aide du Solveur, déterminer la valeur des paramètres de régression qui minimise la moyenne des erreurs au carré entre la prévision du modèle et la valeur de chacune des propriétés.
B34: - Estimer une loi normale pour le terme d'erreur de cette régression par maximisation de la vraisemblance.
A42: 1.b) À partir des données « d'évaluation », vérifier si la loi obtenue est bien calibrée pour un intervalle de confiance de 80 %.
B43: - Vérifier à la cellule J76 que la proportion de fois qu'une donnée d'évaluation tombe dans l'intervalle de confiance prévu par le modèle est près de 80 %.
A45: 2) Déterminer un modèle stochastique à partir de l'approche Bayesienne pour la variable aléatoire décrivant s'il y aura un sinistre dans la région de l'appel.
A47: 2.1) Faire l'hypothèse que notre connaissance de la probabilité d'un sinistre avant d'observer les données historiques est bien capturée par la loi Beta(1,1).
A48: 2.2) Faire l'hypothèse que chacun des sites observés dans les données pour chacune des années avait la même probabilité d'avoir un « sinistre grave » que le site de l'appel cette année.
A49: 2.3) Utiliser les données historiques pour établir la connaissance a posteriori de la probabilité de « sinistre grave » cette année au site de l'appel.
B50: - Considérer que le « alpha = 1+nombre de sinistres observés » et que le paramètre « beta= 1 + nombre d'occasions où il n'y a pas eu de sinistre » tel que suggéré par l'approche Bayesienne.

Sheet    

Sheet Valeur maison - Données
A1: Instruction: Voici les données
A8: Échantillon pour inférence
A9: index | B9: Distance Centre-Ville (D) | C9: Grandeur terrain (T) | D9: Piscine présente (P) | E9: Valeur propriété (V)
A10: 1 | B10: 26 | C10: 5200 | D10: 1 | E10: 575000
A11: 2 | B11: 14 | C11: 4500 | D11: 0 | E11: 411000
A12: 3 | B12: 13 | C12: 2400 | D12: 0 | E12: 323000
A13: 4 | B13: 1 | C13: 2400 | D13: 0 | E13: 667000
A14: 5 | B14: 25 | C14: 9800 | D14: 0 | E14: 555000
A15: 6 | B15: 2 | C15: 1800 | D15: 0 | E15: 539000
A16: 7 | B16: 18 | C16: 5000 | D16: 1 | E16: 375000
A17: 8 | B17: 32 | C17: 7400 | D17: 0 | E17: 254000
A18: 9 | B18: 28 | C18: 6700 | D18: 0 | E18: 279000
A19: 10 | B19: 26 | C19: 4800 | D19: 0 | E19: 396000
A20: 11 | B20: 26 | C20: 5200 | D20: 1 | E20: 575000
A21: 12 | B21: 14 | C21: 4500 | D21: 0 | E21: 411000
... A34: 25 | B34: 22 | C34: 7200 | D34: 1 | E34: 600000
A38: Échantillon pour évaluation du modèle
A39: index | B39: D | C39: T | D39: P | E39: V
A40: 26 | B40: 24 | C40: 4800 | D40: 0 | E40: 491000
A41: 27 | B41: 34 | C41: 13400 | D41: 1 | E41: 665000
A42: 28 | B42: 29 | C42: 10100 | D42: 1 | E42: 505000
A43: 29 | B43: 35 | C43: 17200 | D43: 1 | E43: 1049000
A44: 30 | B44: 38 | C44: 17200 | D44: 1 | E44: 619000
A45: 31 | B45: 25 | C45: 7600 | D45: 0 | E45: 447000
A46: 32 | B46: 33 | C46: 8200 | D46: 1 | E46: 486000
A47: 33 | B47: 20 | C47: 6900 | D47: 1 | E47: 505000
A48: 34 | B48: 16 | C48: 5800 | D48: 1 | E48: 639000
A49: 35 | B49: 27 | C49: 6100 | D49: 0 | E49: 420000
A50: 36 | B50: 15 | C50: 5300 | D50: 1 | E50: 675000
A51: 37 | B51: 12 | C51: 3000 | D51: 0 | E51: 332000
... A64: 50 | B64: 31 | C64: 13700 | D64: 1 | E64: 765000

Sheet 1) Régression sur D, T et P
A4: Modélisation de influence de D, T et P sur V
A6: Régression V = a + bD + cT + dP + epsilon
A8: a | B8: b | C8: c | D8: d
A9: 0 | B9: 0 | C9: 0 | D9: 0
A12: index | B12: Abscisse à l'origine | C12: D | D12: T | E12: P | F12: a + bD + cT + dP | G12: V | H12: epsilon | I12: epsilon carré
A13: 1 | B13: 1 | C13: ='Valeur maison - Données'!B10 -> 26 | D13: ='Valeur maison - Données'!C10 -> 5200 | E13: ='Valeur maison - Données'!D10 -> 1 | F13: =SUMPRODUCT($A$9:$D$9,B13:E13) -> 0 | G13: ='Valeur maison - Données'!E10 -> 575000 | H13: =G13-F13 -> 575000 | I13: =H13^2 -> 330625000000
A14: 2 | B14: 1 | C14: ='Valeur maison - Données'!B11 -> 14 | D14: ='Valeur maison - Données'!C11 -> 4500 | E14: ='Valeur maison - Données'!D11 -> 0 | F14: =SUMPRODUCT($A$9:$D$9,B14:E14) -> 0 | G14: ='Valeur maison - Données'!E11 -> 411000 | H14: =G14-F14 -> 411000 | I14: =H14^2 -> 168921000000
A15: 3 | B15: 1 | C15: ='Valeur maison - Données'!B12 -> 13 | D15: ='Valeur maison - Données'!C12 -> 2400 | E15: ='Valeur maison - Données'!D12 -> 0 | F15: =SUMPRODUCT($A$9:$D$9,B15:E15) -> 0 | G15: ='Valeur maison - Données'!E12 -> 323000 | H15: =G15-F15 -> 323000 | I15: =H15^2 -> 104329000000
A16: 4 | B16: 1 | C16: ='Valeur maison - Données'!B13 -> 1 | D16: ='Valeur maison - Données'!C13 -> 2400 | E16: ='Valeur maison - Données'!D13 -> 0 | F16: =SUMPRODUCT($A$9:$D$9,B16:E16) -> 0 | G16: ='Valeur maison - Données'!E13 -> 667000 | H16: =G16-F16 -> 667000 | I16: =H16^2 -> 444889000000
A17: 5 | B17: 1 | C17: ='Valeur maison - Données'!B14 -> 25 | D17: ='Valeur maison - Données'!C14 -> 9800 | E17: ='Valeur maison - Données'!D14 -> 0 | F17: =SUMPRODUCT($A$9:$D$9,B17:E17) -> 0 | G17: ='Valeur maison - Données'!E14 -> 555000 | H17: =G17-F17 -> 555000 | I17: =H17^2 -> 308025000000
A18: 6 | B18: 1 | C18: ='Valeur maison - Données'!B15 -> 2 | D18: ='Valeur maison - Données'!C15 -> 1800 | E18: ='Valeur maison - Données'!D15 -> 0 | F18: =SUMPRODUCT($A$9:$D$9,B18:E18) -> 0 | G18: ='Valeur maison - Données'!E15 -> 539000 | H18: =G18-F18 -> 539000 | I18: =H18^2 -> 290521000000
A19: 7 | B19: 1 | C19: ='Valeur maison - Données'!B16 -> 18 | D19: ='Valeur maison - Données'!C16 -> 5000 | E19: ='Valeur maison - Données'!D16 -> 1 | F19: =SUMPRODUCT($A$9:$D$9,B19:E19) -> 0 | G19: ='Valeur maison - Données'!E16 -> 375000 | H19: =G19-F19 -> 375000 | I19: =H19^2 -> 140625000000
A20: 8 | B20: 1 | C20: ='Valeur maison - Données'!B17 -> 32 | D20: ='Valeur maison - Données'!C17 -> 7400 | E20: ='Valeur maison - Données'!D17 -> 0 | F20: =SUMPRODUCT($A$9:$D$9,B20:E20) -> 0 | G20: ='Valeur maison - Données'!E17 -> 254000 | H20: =G20-F20 -> 254000 | I20: =H20^2 -> 64516000000
A21: 9 | B21: 1 | C21: ='Valeur maison - Données'!B18 -> 28 | D21: ='Valeur maison - Données'!C18 -> 6700 | E21: ='Valeur maison - Données'!D18 -> 0 | F21: =SUMPRODUCT($A$9:$D$9,B21:E21) -> 0 | G21: ='Valeur maison - Données'!E18 -> 279000 | H21: =G21-F21 -> 279000 | I21: =H21^2 -> 77841000000
A22: 10 | B22: 1 | C22: ='Valeur maison - Données'!B19 -> 26 | D22: ='Valeur maison - Données'!C19 -> 4800 | E22: ='Valeur maison - Données'!D19 -> 0 | F22: =SUMPRODUCT($A$9:$D$9,B22:E22) -> 0 | G22: ='Valeur maison - Données'!E19 -> 396000 | H22: =G22-F22 -> 396000 | I22: =H22^2 -> 156816000000
A23: 11 | B23: 1 | C23: ='Valeur maison - Données'!B20 -> 26 | D23: ='Valeur maison - Données'!C20 -> 5200 | E23: ='Valeur maison - Données'!D20 -> 1 | F23: =SUMPRODUCT($A$9:$D$9,B23:E23) -> 0 | G23: ='Valeur maison - Données'!E20 -> 575000 | H23: =G23-F23 -> 575000 | I23: =H23^2 -> 330625000000
A24: 12 | B24: 1 | C24: ='Valeur maison - Données'!B21 -> 14 | D24: ='Valeur maison - Données'!C21 -> 4500 | E24: ='Valeur maison - Données'!D21 -> 0 | F24: =SUMPRODUCT($A$9:$D$9,B24:E24) -> 0 | G24: ='Valeur maison - Données'!E21 -> 411000 | H24: =G24-F24 -> 411000 | I24: =H24^2 -> 168921000000
... A37: 25 | B37: 1 | C37: ='Valeur maison - Données'!B34 -> 22 | D37: ='Valeur maison - Données'!C34 -> 7200 | E37: ='Valeur maison - Données'!D34 -> 1 | F37: =SUMPRODUCT($A$9:$D$9,B37:E37) -> 0 | G37: ='Valeur maison - Données'!E34 -> 600000 | H37: =G37-F37 -> 600000 | I37: =H37^2 -> 360000000000
A39: Objectif de régression
A40: =AVERAGE(I13:I37) -> 233514320000
A43: Modélisation de epsilon
A44: (hypothèse normale)
A45: moyenne | B45: std dev
A46: =AVERAGE(H13:H37) -> 461600 | B46: =STDEV(H13:H37) -> 145915.79 | C46: (solution analytique)
A49: Calibration | H49: Intervalle confiance 80%
A50: index | B50: Abscisse à l'origine | C50: D | D50: T | E50: P | F50: E[V] | G50: Écart type de V | H50: Borne inf V | I50: Borne sup V | J50: Vrai V | K50: L'intervalle contient vrai V
A51: 26 | B51: 1 | C51: ='Valeur maison - Données'!B40 -> 24 | D51: ='Valeur maison - Données'!C40 -> 4800 | E51: ='Valeur maison - Données'!D40 -> 0 | F51: =SUMPRODUCT(B51:E51,$A$9:$D$9)+$A$46 -> 461600 | G51: =$B$46 -> 145915.79 | H51: =NORMINV(0.1,F51,G51) -> 274601.4 | I51: =NORMINV(0.9,F51,G51) -> 648598.6 | J51: ='Valeur maison - Données'!E40 -> 491000 | K51: =IF(J51>=H51,IF(J51<=I51,1,0),0) -> 1
A52: 27 | B52: 1 | C52: ='Valeur maison - Données'!B41 -> 34 | D52: ='Valeur maison - Données'!C41 -> 13400 | E52: ='Valeur maison - Données'!D41 -> 1 | F52: =SUMPRODUCT(B52:E52,$A$9:$D$9)+$A$46 -> 461600 | G52: =$B$46 -> 145915.79 | H52: =NORMINV(0.1,F52,G52) -> 274601.4 | I52: =NORMINV(0.9,F52,G52) -> 648598.6 | J52: ='Valeur maison - Données'!E41 -> 665000 | K52: =IF(J52>=H52,IF(J52<=I52,1,0),0) -> 0
A53: 28 | B53: 1 | C53: ='Valeur maison - Données'!B42 -> 29 | D53: ='Valeur maison - Données'!C42 -> 10100 | E53: ='Valeur maison - Données'!D42 -> 1 | F53: =SUMPRODUCT(B53:E53,$A$9:$D$9)+$A$46 -> 461600 | G53: =$B$46 -> 145915.79 | H53: =NORMINV(0.1,F53,G53) -> 274601.4 | I53: =NORMINV(0.9,F53,G53) -> 648598.6 | J53: ='Valeur maison - Données'!E42 -> 505000 | K53: =IF(J53>=H53,IF(J53<=I53,1,0),0) -> 1
A54: 29 | B54: 1 | C54: ='Valeur maison - Données'!B43 -> 35 | D54: ='Valeur maison - Données'!C43 -> 17200 | E54: ='Valeur maison - Données'!D43 -> 1 | F54: =SUMPRODUCT(B54:E54,$A$9:$D$9)+$A$46 -> 461600 | G54: =$B$46 -> 145915.79 | H54: =NORMINV(0.1,F54,G54) -> 274601.4 | I54: =NORMINV(0.9,F54,G54) -> 648598.6 | J54: ='Valeur maison - Données'!E43 -> 1049000 | K54: =IF(J54>=H54,IF(J54<=I54,1,0),0) -> 0
A55: 30 | B55: 1 | C55: ='Valeur maison - Données'!B44 -> 38 | D55: ='Valeur maison - Données'!C44 -> 17200 | E55: ='Valeur maison - Données'!D44 -> 1 | F55: =SUMPRODUCT(B55:E55,$A$9:$D$9)+$A$46 -> 461600 | G55: =$B$46 -> 145915.79 | H55: =NORMINV(0.1,F55,G55) -> 274601.4 | I55: =NORMINV(0.9,F55,G55) -> 648598.6 | J55: ='Valeur maison - Données'!E44 -> 619000 | K55: =IF(J55>=H55,IF(J55<=I55,1,0),0) -> 1
A56: 31 | B56: 1 | C56: ='Valeur maison - Données'!B45 -> 25 | D56: ='Valeur maison - Données'!C45 -> 7600 | E56: ='Valeur maison - Données'!D45 -> 0 | F56: =SUMPRODUCT(B56:E56,$A$9:$D$9)+$A$46 -> 461600 | G56: =$B$46 -> 145915.79 | H56: =NORMINV(0.1,F56,G56) -> 274601.4 | I56: =NORMINV(0.9,F56,G56) -> 648598.6 | J56: ='Valeur maison - Données'!E45 -> 447000 | K56: =IF(J56>=H56,IF(J56<=I56,1,0),0) -> 1
A57: 32 | B57: 1 | C57: ='Valeur maison - Données'!B46 -> 33 | D57: ='Valeur maison - Données'!C46 -> 8200 | E57: ='Valeur maison - Données'!D46 -> 1 | F57: =SUMPRODUCT(B57:E57,$A$9:$D$9)+$A$46 -> 461600 | G57: =$B$46 -> 145915.79 | H57: =NORMINV(0.1,F57,G57) -> 274601.4 | I57: =NORMINV(0.9,F57,G57) -> 648598.6 | J57: ='Valeur maison - Données'!E46 -> 486000 | K57: =IF(J57>=H57,IF(J57<=I57,1,0),0) -> 1
A58: 33 | B58: 1 | C58: ='Valeur maison - Données'!B47 -> 20 | D58: ='Valeur maison - Données'!C47 -> 6900 | E58: ='Valeur maison - Données'!D47 -> 1 | F58: =SUMPRODUCT(B58:E58,$A$9:$D$9)+$A$46 -> 461600 | G58: =$B$46 -> 145915.79 | H58: =NORMINV(0.1,F58,G58) -> 274601.4 | I58: =NORMINV(0.9,F58,G58) -> 648598.6 | J58: ='Valeur maison - Données'!E47 -> 505000 | K58: =IF(J58>=H58,IF(J58<=I58,1,0),0) -> 1
A59: 34 | B59: 1 | C59: ='Valeur maison - Données'!B48 -> 16 | D59: ='Valeur maison - Données'!C48 -> 5800 | E59: ='Valeur maison - Données'!D48 -> 1 | F59: =SUMPRODUCT(B59:E59,$A$9:$D$9)+$A$46 -> 461600 | G59: =$B$46 -> 145915.79 | H59: =NORMINV(0.1,F59,G59) -> 274601.4 | I59: =NORMINV(0.9,F59,G59) -> 648598.6 | J59: ='Valeur maison - Données'!E48 -> 639000 | K59: =IF(J59>=H59,IF(J59<=I59,1,0),0) -> 1
A60: 35 | B60: 1 | C60: ='Valeur maison - Données'!B49 -> 27 | D60: ='Valeur maison - Données'!C49 -> 6100 | E60: ='Valeur maison - Données'!D49 -> 0 | F60: =SUMPRODUCT(B60:E60,$A$9:$D$9)+$A$46 -> 461600 | G60: =$B$46 -> 145915.79 | H60: =NORMINV(0.1,F60,G60) -> 274601.4 | I60: =NORMINV(0.9,F60,G60) -> 648598.6 | J60: ='Valeur maison - Données'!E49 -> 420000 | K60: =IF(J60>=H60,IF(J60<=I60,1,0),0) -> 1
A61: 36 | B61: 1 | C61: ='Valeur maison - Données'!B50 -> 15 | D61: ='Valeur maison - Données'!C50 -> 5300 | E61: ='Valeur maison - Données'!D50 -> 1 | F61: =SUMPRODUCT(B61:E61,$A$9:$D$9)+$A$46 -> 461600 | G61: =$B$46 -> 145915.79 | H61: =NORMINV(0.1,F61,G61) -> 274601.4 | I61: =NORMINV(0.9,F61,G61) -> 648598.6 | J61: ='Valeur maison - Données'!E50 -> 675000 | K61: =IF(J61>=H61,IF(J61<=I61,1,0),0) -> 0
A62: 37 | B62: 1 | C62: ='Valeur maison - Données'!B51 -> 12 | D62: ='Valeur maison - Données'!C51 -> 3000 | E62: ='Valeur maison - Données'!D51 -> 0 | F62: =SUMPRODUCT(B62:E62,$A$9:$D$9)+$A$46 -> 461600 | G62: =$B$46 -> 145915.79 | H62: =NORMINV(0.1,F62,G62) -> 274601.4 | I62: =NORMINV(0.9,F62,G62) -> 648598.6 | J62: ='Valeur maison - Données'!E51 -> 332000 | K62: =IF(J62>=H62,IF(J62<=I62,1,0),0) -> 1
... A75: 50 | B75: 1 | C75: ='Valeur maison - Données'!B64 -> 31 | D75: ='Valeur maison - Données'!C64 -> 13700 | E75: ='Valeur maison - Données'!D64 -> 1 | F75: =SUMPRODUCT(B75:E75,$A$9:$D$9)+$A$46 -> 461600 | G75: =$B$46 -> 145915.79 | H75: =NORMINV(0.1,F75,G75) -> 274601.4 | I75: =NORMINV(0.9,F75,G75) -> 648598.6 | J75: ='Valeur maison - Données'!E64 -> 765000 | K75: =IF(J75>=H75,IF(J75<=I75,1,0),0) -> 0
J76: Proportion: | K76: =AVERAGE(K51:K75) -> 0.76
...

Sheet 1.2) Régression avec P discret
A4: Modélisation de influence de D, T et P sur V à l'aide de transformation non-linéaires des variables observées
A6: Régression V = (P=0)*(a + bD + cT) + (P=1)(d + eD+ fT) + epsilon
A8: a | B8: b | C8: c | D8: d | E8: e | F8: f
A9: 521982.84 | B9: -17098.368 | C9: 43.797906 | D9: 53625.099 | E9: 20844.328 | F9: -2.8636289
F11: a | G11: b | H11: c | I11: d | J11: e | K11: f
A12: index | B12: Abscisse à l'origine | C12: D | D12: T | E12: P | F12: (P=0) | G12: D*(P=0) | H12: T*(P=0) | I12: (P=1) | J12: D*(P=1) | K12: T*(P=1) | L12: combinaison linéaire | M12: V | N12: epsilon | O12: epsilon carré
A13: 1 | B13: 1 | C13: ='Valeur maison - Données'!B10 -> 26 | D13: ='Valeur maison - Données'!C10 -> 5200 | E13: ='Valeur maison - Données'!D10 -> 1 | F13: =IF(E13=0,1,0) -> 0 | G13: =C13*F13 -> 0 | H13: =D13*F13 -> 0 | I13: =IF(E13=1,1,0) -> 1 | J13: =C13*I13 -> 26 | K13: =D13*I13 -> 5200 | L13: =SUMPRODUCT($A$9:$F$9,F13:K13) -> 580686.76 | M13: ='Valeur maison - Données'!E10 -> 575000 | N13: =M13-L13 -> -5686.765 | O13: =N13^2 -> 32339296
A14: 2 | B14: 1 | C14: ='Valeur maison - Données'!B11 -> 14 | D14: ='Valeur maison - Données'!C11 -> 4500 | E14: ='Valeur maison - Données'!D11 -> 0 | F14: =IF(E14=0,1,0) -> 1 | G14: =C14*F14 -> 14 | H14: =D14*F14 -> 4500 | I14: =IF(E14=1,1,0) -> 0 | J14: =C14*I14 -> 0 | K14: =D14*I14 -> 0 | L14: =SUMPRODUCT($A$9:$F$9,F14:K14) -> 479696.26 | M14: ='Valeur maison - Données'!E11 -> 411000 | N14: =M14-L14 -> -68696.261 | O14: =N14^2 -> 4.7191763e+09
A15: 3 | B15: 1 | C15: ='Valeur maison - Données'!B12 -> 13 | D15: ='Valeur maison - Données'!C12 -> 2400 | E15: ='Valeur maison - Données'!D12 -> 0 | F15: =IF(E15=0,1,0) -> 1 | G15: =C15*F15 -> 13 | H15: =D15*F15 -> 2400 | I15: =IF(E15=1,1,0) -> 0 | J15: =C15*I15 -> 0 | K15: =D15*I15 -> 0 | L15: =SUMPRODUCT($A$9:$F$9,F15:K15) -> 404819.03 | M15: ='Valeur maison - Données'!E12 -> 323000 | N15: =M15-L15 -> -81819.027 | O15: =N15^2 -> 6.6943531e+09
A16: 4 | B16: 1 | C16: ='Valeur maison - Données'!B13 -> 1 | D16: ='Valeur maison - Données'!C13 -> 2400 | E16: ='Valeur maison - Données'!D13 -> 0 | F16: =IF(E16=0,1,0) -> 1 | G16: =C16*F16 -> 1 | H16: =D16*F16 -> 2400 | I16: =IF(E16=1,1,0) -> 0 | J16: =C16*I16 -> 0 | K16: =D16*I16 -> 0 | L16: =SUMPRODUCT($A$9:$F$9,F16:K16) -> 609999.44 | M16: ='Valeur maison - Données'!E13 -> 667000 | N16: =M16-L16 -> 57000.558 | O16: =N16^2 -> 3.2490636e+09
A17: 5 | B17: 1 | C17: ='Valeur maison - Données'!B14 -> 25 | D17: ='Valeur maison - Données'!C14 -> 9800 | E17: ='Valeur maison - Données'!D14 -> 0 | F17: =IF(E17=0,1,0) -> 1 | G17: =C17*F17 -> 25 | H17: =D17*F17 -> 9800 | I17: =IF(E17=1,1,0) -> 0 | J17: =C17*I17 -> 0 | K17: =D17*I17 -> 0 | L17: =SUMPRODUCT($A$9:$F$9,F17:K17) -> 523743.11 | M17: ='Valeur maison - Données'!E14 -> 555000 | N17: =M17-L17 -> 31256.885 | O17: =N17^2 -> 9.7699289e+08
A18: 6 | B18: 1 | C18: ='Valeur maison - Données'!B15 -> 2 | D18: ='Valeur maison - Données'!C15 -> 1800 | E18: ='Valeur maison - Données'!D15 -> 0 | F18: =IF(E18=0,1,0) -> 1 | G18: =C18*F18 -> 2 | H18: =D18*F18 -> 1800 | I18: =IF(E18=1,1,0) -> 0 | J18: =C18*I18 -> 0 | K18: =D18*I18 -> 0 | L18: =SUMPRODUCT($A$9:$F$9,F18:K18) -> 566622.33 | M18: ='Valeur maison - Données'!E15 -> 539000 | N18: =M18-L18 -> -27622.33 | O18: =N18^2 -> 7.6299314e+08
A19: 7 | B19: 1 | C19: ='Valeur maison - Données'!B16 -> 18 | D19: ='Valeur maison - Données'!C16 -> 5000 | E19: ='Valeur maison - Données'!D16 -> 1 | F19: =IF(E19=0,1,0) -> 0 | G19: =C19*F19 -> 0 | H19: =D19*F19 -> 0 | I19: =IF(E19=1,1,0) -> 1 | J19: =C19*I19 -> 18 | K19: =D19*I19 -> 5000 | L19: =SUMPRODUCT($A$9:$F$9,F19:K19) -> 414504.86 | M19: ='Valeur maison - Données'!E16 -> 375000 | N19: =M19-L19 -> -39504.864 | O19: =N19^2 -> 1.5606343e+09
A20: 8 | B20: 1 | C20: ='Valeur maison - Données'!B17 -> 32 | D20: ='Valeur maison - Données'!C17 -> 7400 | E20: ='Valeur maison - Données'!D17 -> 0 | F20: =IF(E20=0,1,0) -> 1 | G20: =C20*F20 -> 32 | H20: =D20*F20 -> 7400 | I20: =IF(E20=1,1,0) -> 0 | J20: =C20*I20 -> 0 | K20: =D20*I20 -> 0 | L20: =SUMPRODUCT($A$9:$F$9,F20:K20) -> 298939.57 | M20: ='Valeur maison - Données'!E17 -> 254000 | N20: =M20-L20 -> -44939.565 | O20: =N20^2 -> 2.0195645e+09
A21: 9 | B21: 1 | C21: ='Valeur maison - Données'!B18 -> 28 | D21: ='Valeur maison - Données'!C18 -> 6700 | E21: ='Valeur maison - Données'!D18 -> 0 | F21: =IF(E21=0,1,0) -> 1 | G21: =C21*F21 -> 28 | H21: =D21*F21 -> 6700 | I21: =IF(E21=1,1,0) -> 0 | J21: =C21*I21 -> 0 | K21: =D21*I21 -> 0 | L21: =SUMPRODUCT($A$9:$F$9,F21:K21) -> 336674.5 | M21: ='Valeur maison - Données'!E18 -> 279000 | N21: =M21-L21 -> -57674.503 | O21: =N21^2 -> 3.3263483e+09
A22: 10 | B22: 1 | C22: ='Valeur maison - Données'!B19 -> 26 | D22: ='Valeur maison - Données'!C19 -> 4800 | E22: ='Valeur maison - Données'!D19 -> 0 | F22: =IF(E22=0,1,0) -> 1 | G22: =C22*F22 -> 26 | H22: =D22*F22 -> 4800 | I22: =IF(E22=1,1,0) -> 0 | J22: =C22*I22 -> 0 | K22: =D22*I22 -> 0 | L22: =SUMPRODUCT($A$9:$F$9,F22:K22) -> 287655.22 | M22: ='Valeur maison - Données'!E19 -> 396000 | N22: =M22-L22 -> 108344.78 | O22: =N22^2 -> 1.1738592e+10
A23: 11 | B23: 1 | C23: ='Valeur maison - Données'!B20 -> 26 | D23: ='Valeur maison - Données'!C20 -> 5200 | E23: ='Valeur maison - Données'!D20 -> 1 | F23: =IF(E23=0,1,0) -> 0 | G23: =C23*F23 -> 0 | H23: =D23*F23 -> 0 | I23: =IF(E23=1,1,0) -> 1 | J23: =C23*I23 -> 26 | K23: =D23*I23 -> 5200 | L23: =SUMPRODUCT($A$9:$F$9,F23:K23) -> 580686.76 | M23: ='Valeur maison - Données'!E20 -> 575000 | N23: =M23-L23 -> -5686.765 | O23: =N23^2 -> 32339296
A24: 12 | B24: 1 | C24: ='Valeur maison - Données'!B21 -> 14 | D24: ='Valeur maison - Données'!C21 -> 4500 | E24: ='Valeur maison - Données'!D21 -> 0 | F24: =IF(E24=0,1,0) -> 1 | G24: =C24*F24 -> 14 | H24: =D24*F24 -> 4500 | I24: =IF(E24=1,1,0) -> 0 | J24: =C24*I24 -> 0 | K24: =D24*I24 -> 0 | L24: =SUMPRODUCT($A$9:$F$9,F24:K24) -> 479696.26 | M24: ='Valeur maison - Données'!E21 -> 411000 | N24: =M24-L24 -> -68696.261 | O24: =N24^2 -> 4.7191763e+09
... A37: 25 | B37: 1 | C37: ='Valeur maison - Données'!B34 -> 22 | D37: ='Valeur maison - Données'!C34 -> 7200 | E37: ='Valeur maison - Données'!D34 -> 1 | F37: =IF(E37=0,1,0) -> 0 | G37: =C37*F37 -> 0 | H37: =D37*F37 -> 0 | I37: =IF(E37=1,1,0) -> 1 | J37: =C37*I37 -> 22 | K37: =D37*I37 -> 7200 | L37: =SUMPRODUCT($A$9:$F$9,F37:K37) -> 491582.19 | M37: ='Valeur maison - Données'!E34 -> 600000 | N37: =M37-L37 -> 108417.81 | O37: =N37^2 -> 1.1754421e+10
A39: Objectif de régression
A40: =AVERAGE(O13:O37) -> 4.3715166e+09
A43: Modélisation de epsilon
A44: (hypothèse normale)
A45: moyenne | B45: std dev
A46: =AVERAGE(N13:N37) -> 0.17282546 | B46: =STDEV(N13:N37) -> 67480.835 | C46: (solution analytique)
A49: Calibration | N49: Intervalle confiance 80%
A50: index | B50: Abscisse à l'origine | C50: D | D50: T | E50: P | F50: (P=0) | G50: D*(P=0) | H50: T*(P=0) | I50: (P=1) | J50: D*(P=0) | K50: T*(P=0) | L50: E[V] | M50: Écart type de V | N50: Borne inf V | O50: Borne sup V | P50: Vrai V | Q50: L'intervalle contient vrai V
A51: 26 | B51: 1 | C51: ='Valeur maison - Données'!B40 -> 24 | D51: ='Valeur maison - Données'!C40 -> 4800 | E51: ='Valeur maison - Données'!D40 -> 0 | F51: =IF(E51=0,1,0) -> 1 | G51: =C51*F51 -> 24 | H51: =D51*F51 -> 4800 | I51: =IF(E51=1,1,0) -> 0 | J51: =C51*I51 -> 0 | K51: =D51*I51 -> 0 | L51: =SUMPRODUCT($A$9:$F$9,F51:K51)+$A$46 -> 321852.13 | M51: =$B$46 -> 67480.835 | N51: =NORMINV(0.1,L51,M51) -> 235371.96 | O51: =NORMINV(0.9,L51,M51) -> 408332.3 | P51: ='Valeur maison - Données'!E40 -> 491000 | Q51: =IF(P51>=N51,IF(P51<=O51,1,0),0) -> 0
A52: 27 | B52: 1 | C52: ='Valeur maison - Données'!B41 -> 34 | D52: ='Valeur maison - Données'!C41 -> 13400 | E52: ='Valeur maison - Données'!D41 -> 1 | F52: =IF(E52=0,1,0) -> 0 | G52: =C52*F52 -> 0 | H52: =D52*F52 -> 0 | I52: =IF(E52=1,1,0) -> 1 | J52: =C52*I52 -> 34 | K52: =D52*I52 -> 13400 | L52: =SUMPRODUCT($A$9:$F$9,F52:K52)+$A$46 -> 723959.81 | M52: =$B$46 -> 67480.835 | N52: =NORMINV(0.1,L52,M52) -> 637479.64 | O52: =NORMINV(0.9,L52,M52) -> 810439.98 | P52: ='Valeur maison - Données'!E41 -> 665000 | Q52: =IF(P52>=N52,IF(P52<=O52,1,0),0) -> 1
A53: 28 | B53: 1 | C53: ='Valeur maison - Données'!B42 -> 29 | D53: ='Valeur maison - Données'!C42 -> 10100 | E53: ='Valeur maison - Données'!D42 -> 1 | F53: =IF(E53=0,1,0) -> 0 | G53: =C53*F53 -> 0 | H53: =D53*F53 -> 0 | I53: =IF(E53=1,1,0) -> 1 | J53: =C53*I53 -> 29 | K53: =D53*I53 -> 10100 | L53: =SUMPRODUCT($A$9:$F$9,F53:K53)+$A$46 -> 629188.14 | M53: =$B$46 -> 67480.835 | N53: =NORMINV(0.1,L53,M53) -> 542707.97 | O53: =NORMINV(0.9,L53,M53) -> 715668.31 | P53: ='Valeur maison - Données'!E42 -> 505000 | Q53: =IF(P53>=N53,IF(P53<=O53,1,0),0) -> 0
A54: 29 | B54: 1 | C54: ='Valeur maison - Données'!B43 -> 35 | D54: ='Valeur maison - Données'!C43 -> 17200 | E54: ='Valeur maison - Données'!D43 -> 1 | F54: =IF(E54=0,1,0) -> 0 | G54: =C54*F54 -> 0 | H54: =D54*F54 -> 0 | I54: =IF(E54=1,1,0) -> 1 | J54: =C54*I54 -> 35 | K54: =D54*I54 -> 17200 | L54: =SUMPRODUCT($A$9:$F$9,F54:K54)+$A$46 -> 733922.35 | M54: =$B$46 -> 67480.835 | N54: =NORMINV(0.1,L54,M54) -> 647442.18 | O54: =NORMINV(0.9,L54,M54) -> 820402.52 | P54: ='Valeur maison - Données'!E43 -> 1049000 | Q54: =IF(P54>=N54,IF(P54<=O54,1,0),0) -> 0
A55: 30 | B55: 1 | C55: ='Valeur maison - Données'!B44 -> 38 | D55: ='Valeur maison - Données'!C44 -> 17200 | E55: ='Valeur maison - Données'!D44 -> 1 | F55: =IF(E55=0,1,0) -> 0 | G55: =C55*F55 -> 0 | H55: =D55*F55 -> 0 | I55: =IF(E55=1,1,0) -> 1 | J55: =C55*I55 -> 38 | K55: =D55*I55 -> 17200 | L55: =SUMPRODUCT($A$9:$F$9,F55:K55)+$A$46 -> 796455.33 | M55: =$B$46 -> 67480.835 | N55: =NORMINV(0.1,L55,M55) -> 709975.16 | O55: =NORMINV(0.9,L55,M55) -> 882935.5 | P55: ='Valeur maison - Données'!E44 -> 619000 | Q55: =IF(P55>=N55,IF(P55<=O55,1,0),0) -> 0
A56: 31 | B56: 1 | C56: ='Valeur maison - Données'!B45 -> 25 | D56: ='Valeur maison - Données'!C45 -> 7600 | E56: ='Valeur maison - Données'!D45 -> 0 | F56: =IF(E56=0,1,0) -> 1 | G56: =C56*F56 -> 25 | H56: =D56*F56 -> 7600 | I56: =IF(E56=1,1,0) -> 0 | J56: =C56*I56 -> 0 | K56: =D56*I56 -> 0 | L56: =SUMPRODUCT($A$9:$F$9,F56:K56)+$A$46 -> 427387.89 | M56: =$B$46 -> 67480.835 | N56: =NORMINV(0.1,L56,M56) -> 340907.72 | O56: =NORMINV(0.9,L56,M56) -> 513868.06 | P56: ='Valeur maison - Données'!E45 -> 447000 | Q56: =IF(P56>=N56,IF(P56<=O56,1,0),0) -> 1
A57: 32 | B57: 1 | C57: ='Valeur maison - Données'!B46 -> 33 | D57: ='Valeur maison - Données'!C46 -> 8200 | E57: ='Valeur maison - Données'!D46 -> 1 | F57: =IF(E57=0,1,0) -> 0 | G57: =C57*F57 -> 0 | H57: =D57*F57 -> 0 | I57: =IF(E57=1,1,0) -> 1 | J57: =C57*I57 -> 33 | K57: =D57*I57 -> 8200 | L57: =SUMPRODUCT($A$9:$F$9,F57:K57)+$A$46 -> 718006.35 | M57: =$B$46 -> 67480.835 | N57: =NORMINV(0.1,L57,M57) -> 631526.18 | O57: =NORMINV(0.9,L57,M57) -> 804486.52 | P57: ='Valeur maison - Données'!E46 -> 486000 | Q57: =IF(P57>=N57,IF(P57<=O57,1,0),0) -> 0
A58: 33 | B58: 1 | C58: ='Valeur maison - Données'!B47 -> 20 | D58: ='Valeur maison - Données'!C47 -> 6900 | E58: ='Valeur maison - Données'!D47 -> 1 | F58: =IF(E58=0,1,0) -> 0 | G58: =C58*F58 -> 0 | H58: =D58*F58 -> 0 | I58: =IF(E58=1,1,0) -> 1 | J58: =C58*I58 -> 20 | K58: =D58*I58 -> 6900 | L58: =SUMPRODUCT($A$9:$F$9,F58:K58)+$A$46 -> 450752.8 | M58: =$B$46 -> 67480.835 | N58: =NORMINV(0.1,L58,M58) -> 364272.63 | O58: =NORMINV(0.9,L58,M58) -> 537232.97 | P58: ='Valeur maison - Données'!E47 -> 505000 | Q58: =IF(P58>=N58,IF(P58<=O58,1,0),0) -> 1
A59: 34 | B59: 1 | C59: ='Valeur maison - Données'!B48 -> 16 | D59: ='Valeur maison - Données'!C48 -> 5800 | E59: ='Valeur maison - Données'!D48 -> 1 | F59: =IF(E59=0,1,0) -> 0 | G59: =C59*F59 -> 0 | H59: =D59*F59 -> 0 | I59: =IF(E59=1,1,0) -> 1 | J59: =C59*I59 -> 16 | K59: =D59*I59 -> 5800 | L59: =SUMPRODUCT($A$9:$F$9,F59:K59)+$A$46 -> 370525.48 | M59: =$B$46 -> 67480.835 | N59: =NORMINV(0.1,L59,M59) -> 284045.31 | O59: =NORMINV(0.9,L59,M59) -> 457005.65 | P59: ='Valeur maison - Données'!E48 -> 639000 | Q59: =IF(P59>=N59,IF(P59<=O59,1,0),0) -> 0
A60: 35 | B60: 1 | C60: ='Valeur maison - Données'!B49 -> 27 | D60: ='Valeur maison - Données'!C49 -> 6100 | E60: ='Valeur maison - Données'!D49 -> 0 | F60: =IF(E60=0,1,0) -> 1 | G60: =C60*F60 -> 27 | H60: =D60*F60 -> 6100 | I60: =IF(E60=1,1,0) -> 0 | J60: =C60*I60 -> 0 | K60: =D60*I60 -> 0 | L60: =SUMPRODUCT($A$9:$F$9,F60:K60)+$A$46 -> 327494.3 | M60: =$B$46 -> 67480.835 | N60: =NORMINV(0.1,L60,M60) -> 241014.13 | O60: =NORMINV(0.9,L60,M60) -> 413974.47 | P60: ='Valeur maison - Données'!E49 -> 420000 | Q60: =IF(P60>=N60,IF(P60<=O60,1,0),0) -> 0
A61: 36 | B61: 1 | C61: ='Valeur maison - Données'!B50 -> 15 | D61: ='Valeur maison - Données'!C50 -> 5300 | E61: ='Valeur maison - Données'!D50 -> 1 | F61: =IF(E61=0,1,0) -> 0 | G61: =C61*F61 -> 0 | H61: =D61*F61 -> 0 | I61: =IF(E61=1,1,0) -> 1 | J61: =C61*I61 -> 15 | K61: =D61*I61 -> 5300 | L61: =SUMPRODUCT($A$9:$F$9,F61:K61)+$A$46 -> 351112.96 | M61: =$B$46 -> 67480.835 | N61: =NORMINV(0.1,L61,M61) -> 264632.79 | O61: =NORMINV(0.9,L61,M61) -> 437593.13 | P61: ='Valeur maison - Données'!E50 -> 675000 | Q61: =IF(P61>=N61,IF(P61<=O61,1,0),0) -> 0
A62: 37 | B62: 1 | C62: ='Valeur maison - Données'!B51 -> 12 | D62: ='Valeur maison - Données'!C51 -> 3000 | E62: ='Valeur maison - Données'!D51 -> 0 | F62: =IF(E62=0,1,0) -> 1 | G62: =C62*F62 -> 12 | H62: =D62*F62 -> 3000 | I62: =IF(E62=1,1,0) -> 0 | J62: =C62*I62 -> 0 | K62: =D62*I62 -> 0 | L62: =SUMPRODUCT($A$9:$F$9,F62:K62)+$A$46 -> 448196.31 | M62: =$B$46 -> 67480.835 | N62: =NORMINV(0.1,L62,M62) -> 361716.14 | O62: =NORMINV(0.9,L62,M62) -> 534676.48 | P62: ='Valeur maison - Données'!E51 -> 332000 | Q62: =IF(P62>=N62,IF(P62<=O62,1,0),0) -> 0
... A75: 50 | B75: 1 | C75: ='Valeur maison - Données'!B64 -> 31 | D75: ='Valeur maison - Données'!C64 -> 13700 | E75: ='Valeur maison - Données'!D64 -> 1 | F75: =IF(E75=0,1,0) -> 0 | G75: =C75*F75 -> 0 | H75: =D75*F75 -> 0 | I75: =IF(E75=1,1,0) -> 1 | J75: =C75*I75 -> 31 | K75: =D75*I75 -> 13700 | L75: =SUMPRODUCT($A$9:$F$9,F75:K75)+$A$46 -> 660567.73 | M75: =$B$46 -> 67480.835 | N75: =NORMINV(0.1,L75,M75) -> 574087.56 | O75: =NORMINV(0.9,L75,M75) -> 747047.9 | P75: ='Valeur maison - Données'!E64 -> 765000 | Q75: =IF(P75>=N75,IF(P75<=O75,1,0),0) -> 0
...

Sheet               

Sheet Sinistre - données
A2: Observations
B3: 1980 | C3: 1981 | D3: 1982 | E3: 1983 | F3: 1984 | G3: 1985 | H3: 1986 | I3: 1987 | J3: 1988 | K3: 1989 | L3: 1990 | M3: 1991 | N3: 1992 | O3: 1993 | P3: 1994 | Q3: 1995 | R3: 1996 | S3: 1997 | T3: 1998 | U3: 1999 | V3: 2000 | W3: 2001 | X3: 2002 | Y3: 2003 | Z3: 2004 | AA3: 2005 | AB3: 2006 | AC3: 2007 | AD3: 2008 | AE3: 2009 | AF3: 2010
A4: Sites 1 à 100 | B4: 0 | C4: 0 | D4: 0 | E4: 0 | F4: 1 | G4: 1 | H4: 1 | I4: 0 | J4: 0 | K4: 0 | L4: 1 | M4: 0 | N4: 0 | O4: 0 | P4: 1 | Q4: 1 | R4: 0 | S4: 1 | T4: 0 | U4: 0 | V4: 0 | W4: 1 | X4: 0 | Y4: 0 | Z4: 0 | AA4: 0 | AB4: 0 | AC4: 0 | AD4: 0 | AE4: 0 | AF4: 0
A5: Sites 101 à 200 | B5: 1 | C5: 0 | D5: 0 | E5: 0 | F5: 0 | G5: 0 | H5: 0 | I5: 0 | J5: 1 | K5: 0 | L5: 1 | M5: 0 | N5: 0 | O5: 0 | P5: 0 | Q5: 0 | R5: 0 | S5: 0 | T5: 0 | U5: 0 | V5: 0 | W5: 0 | X5: 1 | Y5: 1 | Z5: 0 | AA5: 0 | AB5: 1 | AC5: 0 | AD5: 0 | AE5: 1 | AF5: 0
A6: Sites 201 à 300 | B6: 0 | C6: 0 | D6: 0 | E6: 1 | F6: 0 | G6: 0 | H6: 0 | I6: 0 | J6: 0 | K6: 1 | L6: 1 | M6: 1 | N6: 0 | O6: 1 | P6: 0 | Q6: 0 | R6: 2 | S6: 0 | T6: 1 | U6: 0 | V6: 1 | W6: 0 | X6: 0 | Y6: 0 | Z6: 0 | AA6: 0 | AB6: 1 | AC6: 0 | AD6: 0 | AE6: 0 | AF6: 1
A7: Sites 301 à 400 | B7: 0 | C7: 0 | D7: 0 | E7: 0 | F7: 0 | G7: 0 | H7: 1 | I7: 0 | J7: 1 | K7: 1 | L7: 0 | M7: 0 | N7: 1 | O7: 0 | P7: 0 | Q7: 0 | R7: 1 | S7: 1 | T7: 0 | U7: 0 | V7: 1 | W7: 0 | X7: 0 | Y7: 0 | Z7: 0 | AA7: 0 | AB7: 0 | AC7: 0 | AD7: 0 | AE7: 2 | AF7: 0
A8: Sites 401 à 500 | B8: 0 | C8: 0 | D8: 0 | E8: 0 | F8: 0 | G8: 0 | H8: 1 | I8: 0 | J8: 0 | K8: 0 | L8: 0 | M8: 1 | N8: 0 | O8: 0 | P8: 0 | Q8: 1 | R8: 0 | S8: 1 | T8: 0 | U8: 0 | V8: 0 | W8: 0 | X8: 2 | Y8: 0 | Z8: 0 | AA8: 0 | AB8: 0 | AC8: 0 | AD8: 0 | AE8: 0 | AF8: 0
A9: Sites 501 à 600 | B9: 0 | C9: 1 | D9: 0 | E9: 0 | F9: 0 | G9: 0 | H9: 0 | I9: 0 | J9: 0 | K9: 0 | L9: 1 | M9: 0 | N9: 2 | O9: 0 | P9: 1 | Q9: 0 | R9: 0 | S9: 1 | T9: 0 | U9: 0 | V9: 0 | W9: 0 | X9: 1 | Y9: 1 | Z9: 3 | AA9: 0 | AB9: 0 | AC9: 0 | AD9: 0 | AE9: 0 | AF9: 0
A10: Sites 601 à 700 | B10: 1 | C10: 0 | D10: 0 | E10: 1 | F10: 0 | G10: 1 | H10: 0 | I10: 0 | J10: 0 | K10: 0 | L10: 0 | M10: 0 | N10: 0 | O10: 1 | P10: 1 | Q10: 0 | R10: 0 | S10: 0 | T10: 0 | U10: 1 | V10: 0 | W10: 1 | X10: 1 | Y10: 0 | Z10: 0 | AA10: 0 | AB10: 0 | AC10: 0 | AD10: 0 | AE10: 0 | AF10: 0
A11: Sites 701 à 800 | B11: 0 | C11: 0 | D11: 0 | E11: 1 | F11: 0 | G11: 0 | H11: 0 | I11: 1 | J11: 0 | K11: 0 | L11: 0 | M11: 1 | N11: 0 | O11: 1 | P11: 1 | Q11: 0 | R11: 0 | S11: 0 | T11: 0 | U11: 0 | V11: 0 | W11: 0 | X11: 0 | Y11: 0 | Z11: 0 | AA11: 1 | AB11: 0 | AC11: 1 | AD11: 0 | AE11: 0 | AF11: 0
A12: Sites 801 à 900 | B12: 2 | C12: 0 | D12: 2 | E12: 0 | F12: 2 | G12: 0 | H12: 0 | I12: 1 | J12: 1 | K12: 0 | L12: 0 | M12: 0 | N12: 0 | O12: 0 | P12: 2 | Q12: 1 | R12: 1 | S12: 0 | T12: 0 | U12: 0 | V12: 1 | W12: 0 | X12: 0 | Y12: 0 | Z12: 1 | AA12: 1 | AB12: 1 | AC12: 0 | AD12: 0 | AE12: 0 | AF12: 0
A13: Sites 901 à 1000 | B13: 0 | C13: 0 | D13: 0 | E13: 0 | F13: 0 | G13: 0 | H13: 0 | I13: 0 | J13: 1 | K13: 0 | L13: 1 | M13: 0 | N13: 0 | O13: 1 | P13: 0 | Q13: 0 | R13: 0 | S13: 0 | T13: 0 | U13: 0 | V13: 0 | W13: 0 | X13: 0 | Y13: 1 | Z13: 0 | AA13: 1 | AB13: 0 | AC13: 0 | AD13: 0 | AE13: 0 | AF13: 0
A14: Sites 1001 à 1100 | B14: 1 | C14: 1 | D14: 1 | E14: 0 | F14: 2 | G14: 0 | H14: 1 | I14: 0 | J14: 0 | K14: 0 | L14: 3 | M14: 1 | N14: 0 | O14: 0 | P14: 0 | Q14: 0 | R14: 0 | S14: 0 | T14: 0 | U14: 0 | V14: 1 | W14: 0 | X14: 0 | Y14: 0 | Z14: 0 | AA14: 0 | AB14: 1 | AC14: 0 | AD14: 0 | AE14: 2 | AF14: 0
A15: Sites 1101 à 1200 | B15: 0 | C15: 0 | D15: 0 | E15: 0 | F15: 0 | G15: 0 | H15: 0 | I15: 0 | J15: 0 | K15: 1 | L15: 0 | M15: 0 | N15: 0 | O15: 1 | P15: 0 | Q15: 0 | R15: 0 | S15: 0 | T15: 0 | U15: 0 | V15: 0 | W15: 1 | X15: 1 | Y15: 0 | Z15: 0 | AA15: 0 | AB15: 0 | AC15: 0 | AD15: 0 | AE15: 0 | AF15: 0
... A23: Sites 1901 à 2000 | B23: 0 | C23: 0 | D23: 1 | E23: 0 | F23: 1 | G23: 0 | H23: 1 | I23: 0 | J23: 0 | K23: 0 | L23: 1 | M23: 0 | N23: 0 | O23: 0 | P23: 0 | Q23: 0 | R23: 1 | S23: 1 | T23: 0 | U23: 0 | V23: 1 | W23: 1 | X23: 0 | Y23: 0 | Z23: 0 | AA23: 0 | AB23: 0 | AC23: 0 | AD23: 0 | AE23: 0 | AF23: 0

Sheet 2) Sinistre - solution
A2: Observations
B3: 1980 | C3: 1981 | D3: 1982 | E3: 1983 | F3: 1984 | G3: 1985 | H3: 1986 | I3: 1987 | J3: 1988 | K3: 1989 | L3: 1990 | M3: 1991 | N3: 1992 | O3: 1993 | P3: 1994 | Q3: 1995 | R3: 1996 | S3: 1997 | T3: 1998 | U3: 1999 | V3: 2000 | W3: 2001 | X3: 2002 | Y3: 2003 | Z3: 2004 | AA3: 2005 | AB3: 2006 | AC3: 2007 | AD3: 2008 | AE3: 2009 | AF3: 2010
A4: Sites 1 à 100 | B4: 0 | C4: 0 | D4: 0 | E4: 0 | F4: 1 | G4: 1 | H4: 1 | I4: 0 | J4: 0 | K4: 0 | L4: 1 | M4: 0 | N4: 0 | O4: 0 | P4: 1 | Q4: 1 | R4: 0 | S4: 1 | T4: 0 | U4: 0 | V4: 0 | W4: 1 | X4: 0 | Y4: 0 | Z4: 0 | AA4: 0 | AB4: 0 | AC4: 0 | AD4: 0 | AE4: 0 | AF4: 0
A5: Sites 101 à 200 | B5: 1 | C5: 0 | D5: 0 | E5: 0 | F5: 0 | G5: 0 | H5: 0 | I5: 0 | J5: 1 | K5: 0 | L5: 1 | M5: 0 | N5: 0 | O5: 0 | P5: 0 | Q5: 0 | R5: 0 | S5: 0 | T5: 0 | U5: 0 | V5: 0 | W5: 0 | X5: 1 | Y5: 1 | Z5: 0 | AA5: 0 | AB5: 1 | AC5: 0 | AD5: 0 | AE5: 1 | AF5: 0
A6: Sites 201 à 300 | B6: 0 | C6: 0 | D6: 0 | E6: 1 | F6: 0 | G6: 0 | H6: 0 | I6: 0 | J6: 0 | K6: 1 | L6: 1 | M6: 1 | N6: 0 | O6: 1 | P6: 0 | Q6: 0 | R6: 2 | S6: 0 | T6: 1 | U6: 0 | V6: 1 | W6: 0 | X6: 0 | Y6: 0 | Z6: 0 | AA6: 0 | AB6: 1 | AC6: 0 | AD6: 0 | AE6: 0 | AF6: 1
A7: Sites 301 à 400 | B7: 0 | C7: 0 | D7: 0 | E7: 0 | F7: 0 | G7: 0 | H7: 1 | I7: 0 | J7: 1 | K7: 1 | L7: 0 | M7: 0 | N7: 1 | O7: 0 | P7: 0 | Q7: 0 | R7: 1 | S7: 1 | T7: 0 | U7: 0 | V7: 1 | W7: 0 | X7: 0 | Y7: 0 | Z7: 0 | AA7: 0 | AB7: 0 | AC7: 0 | AD7: 0 | AE7: 2 | AF7: 0
A8: Sites 401 à 500 | B8: 0 | C8: 0 | D8: 0 | E8: 0 | F8: 0 | G8: 0 | H8: 1 | I8: 0 | J8: 0 | K8: 0 | L8: 0 | M8: 1 | N8: 0 | O8: 0 | P8: 0 | Q8: 1 | R8: 0 | S8: 1 | T8: 0 | U8: 0 | V8: 0 | W8: 0 | X8: 2 | Y8: 0 | Z8: 0 | AA8: 0 | AB8: 0 | AC8: 0 | AD8: 0 | AE8: 0 | AF8: 0
A9: Sites 501 à 600 | B9: 0 | C9: 1 | D9: 0 | E9: 0 | F9: 0 | G9: 0 | H9: 0 | I9: 0 | J9: 0 | K9: 0 | L9: 1 | M9: 0 | N9: 2 | O9: 0 | P9: 1 | Q9: 0 | R9: 0 | S9: 1 | T9: 0 | U9: 0 | V9: 0 | W9: 0 | X9: 1 | Y9: 1 | Z9: 3 | AA9: 0 | AB9: 0 | AC9: 0 | AD9: 0 | AE9: 0 | AF9: 0
A10: Sites 601 à 700 | B10: 1 | C10: 0 | D10: 0 | E10: 1 | F10: 0 | G10: 1 | H10: 0 | I10: 0 | J10: 0 | K10: 0 | L10: 0 | M10: 0 | N10: 0 | O10: 1 | P10: 1 | Q10: 0 | R10: 0 | S10: 0 | T10: 0 | U10: 1 | V10: 0 | W10: 1 | X10: 1 | Y10: 0 | Z10: 0 | AA10: 0 | AB10: 0 | AC10: 0 | AD10: 0 | AE10: 0 | AF10: 0
A11: Sites 701 à 800 | B11: 0 | C11: 0 | D11: 0 | E11: 1 | F11: 0 | G11: 0 | H11: 0 | I11: 1 | J11: 0 | K11: 0 | L11: 0 | M11: 1 | N11: 0 | O11: 1 | P11: 1 | Q11: 0 | R11: 0 | S11: 0 | T11: 0 | U11: 0 | V11: 0 | W11: 0 | X11: 0 | Y11: 0 | Z11: 0 | AA11: 1 | AB11: 0 | AC11: 1 | AD11: 0 | AE11: 0 | AF11: 0
A12: Sites 801 à 900 | B12: 2 | C12: 0 | D12: 2 | E12: 0 | F12: 2 | G12: 0 | H12: 0 | I12: 1 | J12: 1 | K12: 0 | L12: 0 | M12: 0 | N12: 0 | O12: 0 | P12: 2 | Q12: 1 | R12: 1 | S12: 0 | T12: 0 | U12: 0 | V12: 1 | W12: 0 | X12: 0 | Y12: 0 | Z12: 1 | AA12: 1 | AB12: 1 | AC12: 0 | AD12: 0 | AE12: 0 | AF12: 0
A13: Sites 901 à 1000 | B13: 0 | C13: 0 | D13: 0 | E13: 0 | F13: 0 | G13: 0 | H13: 0 | I13: 0 | J13: 1 | K13: 0 | L13: 1 | M13: 0 | N13: 0 | O13: 1 | P13: 0 | Q13: 0 | R13: 0 | S13: 0 | T13: 0 | U13: 0 | V13: 0 | W13: 0 | X13: 0 | Y13: 1 | Z13: 0 | AA13: 1 | AB13: 0 | AC13: 0 | AD13: 0 | AE13: 0 | AF13: 0
A14: Sites 1001 à 1100 | B14: 1 | C14: 1 | D14: 1 | E14: 0 | F14: 2 | G14: 0 | H14: 1 | I14: 0 | J14: 0 | K14: 0 | L14: 3 | M14: 1 | N14: 0 | O14: 0 | P14: 0 | Q14: 0 | R14: 0 | S14: 0 | T14: 0 | U14: 0 | V14: 1 | W14: 0 | X14: 0 | Y14: 0 | Z14: 0 | AA14: 0 | AB14: 1 | AC14: 0 | AD14: 0 | AE14: 2 | AF14: 0
A15: Sites 1101 à 1200 | B15: 0 | C15: 0 | D15: 0 | E15: 0 | F15: 0 | G15: 0 | H15: 0 | I15: 0 | J15: 0 | K15: 1 | L15: 0 | M15: 0 | N15: 0 | O15: 1 | P15: 0 | Q15: 0 | R15: 0 | S15: 0 | T15: 0 | U15: 0 | V15: 0 | W15: 1 | X15: 1 | Y15: 0 | Z15: 0 | AA15: 0 | AB15: 0 | AC15: 0 | AD15: 0 | AE15: 0 | AF15: 0
... A23: Sites 1901 à 2000 | B23: 0 | C23: 0 | D23: 1 | E23: 0 | F23: 1 | G23: 0 | H23: 1 | I23: 0 | J23: 0 | K23: 0 | L23: 1 | M23: 0 | N23: 0 | O23: 0 | P23: 0 | Q23: 0 | R23: 1 | S23: 1 | T23: 0 | U23: 0 | V23: 1 | W23: 1 | X23: 0 | Y23: 0 | Z23: 0 | AA23: 0 | AB23: 0 | AC23: 0 | AD23: 0 | AE23: 0 | AF23: 0
A25: Nombre de sinistre | B25: =SUM(B4:AF23) -> 187
A26: Nombre de non-sinistre | B26: =100*COUNT(B4:AF23)-B25 -> 61813
B28: alpha | C28: beta
A29: Beta apriori | B29: 1 | C29: 1
A30: Beta aposteriori | B30: 1 | C30: 1
A31: Probabilité moyenne | B31: =B30/(B30+C30) -> 0.5 | C31: (i.e. alpha/(alpha+beta))
A32: Écart type | B32: =SQRT((B30*C30)/(B30+C30)^2/(B30+C30+1)) -> 0.28867513
A33: Fonction de répartition | B33: max | C33: =MIN(1,2*B31) -> 1
A34: index | B34: x | C34: P(X<= x) | D34: f(x)
A35: 0 | B35: =$C$33*A35/(COUNT($A$35:$A$55)-1)+10^(-6) -> 1e-06 | C35: =BETADIST(B35,$B$30,$C$30) -> 1e-06 | D35: =_xlfn.BETA.DIST(B35,$B$30,$C$30,FALSE) -> 1
A36: =1+A35 -> 1 | B36: =$C$33*A36/(COUNT($A$35:$A$55)-1) -> 0.05 | C36: =BETADIST(B36,$B$30,$C$30) -> 0.05 | D36: =_xlfn.BETA.DIST(B36,$B$30,$C$30,FALSE) -> 1
A37: =1+A36 -> 2 | B37: =$C$33*A37/(COUNT($A$35:$A$55)-1) -> 0.1 | C37: =BETADIST(B37,$B$30,$C$30) -> 0.1 | D37: =_xlfn.BETA.DIST(B37,$B$30,$C$30,FALSE) -> 1
A38: =1+A37 -> 3 | B38: =$C$33*A38/(COUNT($A$35:$A$55)-1) -> 0.15 | C38: =BETADIST(B38,$B$30,$C$30) -> 0.15 | D38: =_xlfn.BETA.DIST(B38,$B$30,$C$30,FALSE) -> 1
A39: =1+A38 -> 4 | B39: =$C$33*A39/(COUNT($A$35:$A$55)-1) -> 0.2 | C39: =BETADIST(B39,$B$30,$C$30) -> 0.2 | D39: =_xlfn.BETA.DIST(B39,$B$30,$C$30,FALSE) -> 1
A40: =1+A39 -> 5 | B40: =$C$33*A40/(COUNT($A$35:$A$55)-1) -> 0.25 | C40: =BETADIST(B40,$B$30,$C$30) -> 0.25 | D40: =_xlfn.BETA.DIST(B40,$B$30,$C$30,FALSE) -> 1
A41: =1+A40 -> 6 | B41: =$C$33*A41/(COUNT($A$35:$A$55)-1) -> 0.3 | C41: =BETADIST(B41,$B$30,$C$30) -> 0.3 | D41: =_xlfn.BETA.DIST(B41,$B$30,$C$30,FALSE) -> 1
A42: =1+A41 -> 7 | B42: =$C$33*A42/(COUNT($A$35:$A$55)-1) -> 0.35 | C42: =BETADIST(B42,$B$30,$C$30) -> 0.35 | D42: =_xlfn.BETA.DIST(B42,$B$30,$C$30,FALSE) -> 1
A43: =1+A42 -> 8 | B43: =$C$33*A43/(COUNT($A$35:$A$55)-1) -> 0.4 | C43: =BETADIST(B43,$B$30,$C$30) -> 0.4 | D43: =_xlfn.BETA.DIST(B43,$B$30,$C$30,FALSE) -> 1
A44: =1+A43 -> 9 | B44: =$C$33*A44/(COUNT($A$35:$A$55)-1) -> 0.45 | C44: =BETADIST(B44,$B$30,$C$30) -> 0.45 | D44: =_xlfn.BETA.DIST(B44,$B$30,$C$30,FALSE) -> 1
A45: =1+A44 -> 10 | B45: =$C$33*A45/(COUNT($A$35:$A$55)-1) -> 0.5 | C45: =BETADIST(B45,$B$30,$C$30) -> 0.5 | D45: =_xlfn.BETA.DIST(B45,$B$30,$C$30,FALSE) -> 1
A46: =1+A45 -> 11 | B46: =$C$33*A46/(COUNT($A$35:$A$55)-1) -> 0.55 | C46: =BETADIST(B46,$B$30,$C$30) -> 0.55 | D46: =_xlfn.BETA.DIST(B46,$B$30,$C$30,FALSE) -> 1
A47: =1+A46 -> 12 | B47: =$C$33*A47/(COUNT($A$35:$A$55)-1) -> 0.6 | C47: =BETADIST(B47,$B$30,$C$30) -> 0.6 | D47: =_xlfn.BETA.DIST(B47,$B$30,$C$30,FALSE) -> 1
... A54: =1+A53 -> 19 | B54: =$C$33*A54/(COUNT($A$35:$A$55)-1) -> 0.95 | C54: =BETADIST(B54,$B$30,$C$30) -> 0.95 | D54: =_xlfn.BETA.DIST(B54,$B$30,$C$30,FALSE) -> 1
A55: =1+A54 -> 20 | B55: =$C$33*A55/(COUNT($A$35:$A$55)-1)-10^(-6) -> 0.999999 | C55: =BETADIST(B55,$B$30,$C$30) -> 0.999999 | D55: =_xlfn.BETA.DIST(B55,$B$30,$C$30,FALSE) -> 1

Sheet                 

Sheet 3) Estimation valeur espérée
A1: Un client appel pour recevoir un estimé de la prime qu'il aurait à payer pour cette assurance, il habite à 10 km du centre-ville, son terrain est de 5 000 pieds carrés et ne possède pas de piscine.
A4: Abscisse à l'origine | B4: D | C4: T | D4: P
A5: 1 | B5: 10 | C5: 5000 | D5: 0
D7: E[V] | E7: Écart type
A8: Valeur de la maison: | D8: =SUMPRODUCT('1) Régression sur D, T et P'!$A$9:$D$9,$A$5:$D$5)+'1) Régression sur D, T et P'!$A$46 -> 461600 | E8: ='1) Régression sur D, T et P'!$B$46 -> 145915.79
D9: alpha | E9: beta
A10: Probabilité d'un sinistre | D10: ='2) Sinistre - solution'!$B$30 -> 1 | E10: ='2) Sinistre - solution'!$C$30 -> 1
A14: Valeur espérée de la maison E[V] | D14: =D8 -> 461600 | F14: E[V] = a + bD + cT + dP + E[epsilon]
A15: Probabilité moyenne d'un sinistre E[S] | D15: =D10/(D10+E10) -> 0.5
A16: Prime d'assurance minimale (i.e. E[V∙S]=E[V]E[S]) | D16: =D15*D14 -> 230800
A17: * ici on assume que V indépendant de S
