Workbook

Sheet données0
A1: 1.1956768
A2: -0.96440945
A3: 0.97602563
A4: -0.17323445
A5: 0.75767452
A6: 0.078803471
A7: -1.0865878
A8: -0.84379214
A9: 0.50315429
A10: -0.27748089
A11: 1.0118689
A12: 1.4974858
... A100: -1.395002

Sheet hypothèse normale
A1: =données0!A1 -> 1.1956768
A2: =données0!A2 -> -0.96440945
A3: =données0!A3 -> 0.97602563 | C3: Hypothèse de loi normale
A4: =données0!A4 -> -0.17323445 | C4: mu | D4: sigma
A5: =données0!A5 -> 0.75767452 | C5: =AVERAGE(A1:A100) -> -0.028860734 | D5: =STDEV(A1:A100) -> 0.96128555
A6: =données0!A6 -> 0.078803471
A7: =données0!A7 -> -1.0865878 | C7: Valeurs de x | D7: Plages | E7: Fréquence | F7: Prob prévue | G7: erreur^2 relative
A8: =données0!A8 -> -0.84379214 | C8: -2 | D8: =CONCATENATE("<",C8) -> <-2 | E8: =COUNTIF($A$1:$A$100,D8)/COUNT($A$1:$A$100) -> 0.02 | F8: =_xlfn.NORM.DIST(C8,$C$5,$D$5,TRUE) -> 0.020156653 | G8: =(F8-E8)^2/F8 -> 1.2174746e-06
A9: =données0!A9 -> 0.50315429 | C9: =C8+0.2 -> -1.8 | D9: =CONCATENATE("[",C8,", ",C9,"]") -> [-2, -1,8] | E9: =COUNTIF($A$1:$A$100,CONCATENATE("<",C9))/COUNT($A$1:$A$100)-SUM($E$8:E8) -> 0.01 | F9: =_xlfn.NORM.DIST(C9,$C$5,$D$5,TRUE)-SUM($F$8:F8) -> 0.012546602 | G9: =(F9-E9)^2/F9 -> 0.00051688741
A10: =données0!A10 -> -0.27748089 | C10: =C9+0.2 -> -1.6 | D10: =CONCATENATE("[",C9,", ",C10,"]") -> [-1,8, -1,6] | E10: =COUNTIF($A$1:$A$100,CONCATENATE("<",C10))/COUNT($A$1:$A$100)-SUM($E$8:E9) -> 0.06 | F10: =_xlfn.NORM.DIST(C10,$C$5,$D$5,TRUE)-SUM($F$8:F9) -> 0.018382643 | G10: =(F10-E10)^2/F10 -> 0.09421955
A11: =données0!A11 -> 1.0118689 | C11: =C10+0.2 -> -1.4 | D11: =CONCATENATE("[",C10,", ",C11,"]") -> [-1,6, -1,4] | E11: =COUNTIF($A$1:$A$100,CONCATENATE("<",C11))/COUNT($A$1:$A$100)-SUM($E$8:E10) -> 0.01 | F11: =_xlfn.NORM.DIST(C11,$C$5,$D$5,TRUE)-SUM($F$8:F10) -> 0.025796327 | G11: =(F11-E11)^2/F11 -> 0.0096728479
A12: =données0!A12 -> 1.4974858 | C12: =C11+0.2 -> -1.2 | D12: =CONCATENATE("[",C11,", ",C12,"]") -> [-1,4, -1,2] | E12: =COUNTIF($A$1:$A$100,CONCATENATE("<",C12))/COUNT($A$1:$A$100)-SUM($E$8:E11) -> 0.03 | F12: =_xlfn.NORM.DIST(C12,$C$5,$D$5,TRUE)-SUM($F$8:F11) -> 0.034671766 | G12: =(F12-E12)^2/F12 -> 0.00062948611
A13: =données0!A13 -> -2.286849 | C13: =C12+0.2 -> -1 | D13: =CONCATENATE("[",C12,", ",C13,"]") -> [-1,2, -1] | E13: =COUNTIF($A$1:$A$100,CONCATENATE("<",C13))/COUNT($A$1:$A$100)-SUM($E$8:E12) -> 0.04 | F13: =_xlfn.NORM.DIST(C13,$C$5,$D$5,TRUE)-SUM($F$8:F12) -> 0.044633639 | G13: =(F13-E13)^2/F13 -> 0.00048104105
A14: =données0!A14 -> 0.29639911 | C14: =C13+0.2 -> -0.8 | D14: =CONCATENATE("[",C13,", ",C14,"]") -> [-1, -0,8] | E14: =COUNTIF($A$1:$A$100,CONCATENATE("<",C14))/COUNT($A$1:$A$100)-SUM($E$8:E13) -> 0.04 | F14: =_xlfn.NORM.DIST(C14,$C$5,$D$5,TRUE)-SUM($F$8:F13) -> 0.055032212 | G14: =(F14-E14)^2/F14 -> 0.0041060932
A15: =données0!A15 -> -1.9130227 | C15: =C14+0.2 -> -0.6 | D15: =CONCATENATE("[",C14,", ",C15,"]") -> [-0,8, -0,6] | E15: =COUNTIF($A$1:$A$100,CONCATENATE("<",C15))/COUNT($A$1:$A$100)-SUM($E$8:E14) -> 0.03 | F15: =_xlfn.NORM.DIST(C15,$C$5,$D$5,TRUE)-SUM($F$8:F14) -> 0.064989025 | G15: =(F15-E15)^2/F15 -> 0.018837517
A16: =données0!A16 -> 0.89368855 | C16: =C15+0.2 -> -0.4 | D16: =CONCATENATE("[",C15,", ",C16,"]") -> [-0,6, -0,4] | E16: =COUNTIF($A$1:$A$100,CONCATENATE("<",C16))/COUNT($A$1:$A$100)-SUM($E$8:E15) -> 0.09 | F16: =_xlfn.NORM.DIST(C16,$C$5,$D$5,TRUE)-SUM($F$8:F15) -> 0.073507478 | G16: =(F16-E16)^2/F16 -> 0.0037003486
A17: =données0!A17 -> -1.2090154 | C17: =C16+0.2 -> -0.2 | D17: =CONCATENATE("[",C16,", ",C17,"]") -> [-0,4, -0,2] | E17: =COUNTIF($A$1:$A$100,CONCATENATE("<",C17))/COUNT($A$1:$A$100)-SUM($E$8:E16) -> 0.06 | F17: =_xlfn.NORM.DIST(C17,$C$5,$D$5,TRUE)-SUM($F$8:F16) -> 0.079632709 | G17: =(F17-E17)^2/F17 -> 0.0048402632
A18: =données0!A18 -> 1.2121842 | C18: =C17+0.2 -> -2.7755576e-16 | D18: =CONCATENATE("[",C17,", ",C18,"]") -> [-0,2, -2,77555756156289E-16] | E18: =COUNTIF($A$1:$A$100,CONCATENATE("<",C18))/COUNT($A$1:$A$100)-SUM($E$8:E17) -> 0.11 | F18: =_xlfn.NORM.DIST(C18,$C$5,$D$5,TRUE)-SUM($F$8:F17) -> 0.082626615 | G18: =(F18-E18)^2/F18 -> 0.0090685335
A19: =données0!A19 -> -0.53615236 | C19: =C18+0.2 -> 0.2 | D19: =CONCATENATE("[",C18,", ",C19,"]") -> [-2,77555756156289E-16, 0,2] | E19: =COUNTIF($A$1:$A$100,CONCATENATE("<",C19))/COUNT($A$1:$A$100)-SUM($E$8:E18) -> 0.1 | F19: =_xlfn.NORM.DIST(C19,$C$5,$D$5,TRUE)-SUM($F$8:F18) -> 0.082113949 | G19: =(F19-E19)^2/F19 -> 0.0038959377
A20: =données0!A20 -> 0.020314962 | C20: =C19+0.2 -> 0.4 | D20: =CONCATENATE("[",C19,", ",C20,"]") -> [0,2, 0,4] | E20: =COUNTIF($A$1:$A$100,CONCATENATE("<",C20))/COUNT($A$1:$A$100)-SUM($E$8:E19) -> 0.09 | F20: =_xlfn.NORM.DIST(C20,$C$5,$D$5,TRUE)-SUM($F$8:F19) -> 0.078159617 | G20: =(F20-E20)^2/F20 -> 0.0017936971
... A28: =données0!A28 -> -1.7598654 | C28: =C27+0.2 -> 2 | D28: =CONCATENATE("[",C27,", ",C28,"]") -> [1,8, 2] | E28: =COUNTIF($A$1:$A$100,CONCATENATE("<",C28))/COUNT($A$1:$A$100)-SUM($E$8:E27) -> 0.01 | F28: =_xlfn.NORM.DIST(C28,$C$5,$D$5,TRUE)-SUM($F$8:F27) -> 0.011147261 | G28: =(F28-E28)^2/F28 -> 0.00011807452
A29: =données0!A29 -> 0.34657906 | D29: =CONCATENATE(">",C28) -> >2 | E29: =1-SUM($E$8:E28) -> 0 | F29: =1-SUM($F$8:F28) -> 0.017404631 | G29: =(F29-E29)^2/F29 -> 0.017404631
A30: =données0!A30 -> 1.317266
A31: =données0!A31 -> 1.0875471 | F31: X_0^2 | G31: =SUM(G8:G29) -> 0.23189414
A32: =données0!A32 -> -0.72249164
A33: =données0!A33 -> -1.0941588
A34: =données0!A34 -> -1.0655924
A35: =données0!A35 -> -2.0803522
A36: =données0!A36 -> -0.42549583
A37: =données0!A37 -> 0.24328073
A38: =données0!A38 -> -0.57136633
A39: =données0!A39 -> 1.942904
A40: =données0!A40 -> 0.31237752
A41: =données0!A41 -> -0.52004455
A42: =données0!A42 -> -0.056480867
A43: =données0!A43 -> 1.1953315
... A100: =données0!A100 -> -1.395002

Sheet hyp.norm. bootstrap
A1: =_xlfn.NORM.INV(RAND(),'hypothèse normale'!$C$5,'hypothèse normale'!$D$5) -> -0.061072665
A2: =_xlfn.NORM.INV(RAND(),'hypothèse normale'!$C$5,'hypothèse normale'!$D$5) -> 1.3496289
A3: =_xlfn.NORM.INV(RAND(),'hypothèse normale'!$C$5,'hypothèse normale'!$D$5) -> 1.2819667 | C3: Hypothèse de loi normale
A4: =_xlfn.NORM.INV(RAND(),'hypothèse normale'!$C$5,'hypothèse normale'!$D$5) -> -1.2770968 | C4: mu | D4: sigma
A5: =_xlfn.NORM.INV(RAND(),'hypothèse normale'!$C$5,'hypothèse normale'!$D$5) -> 1.8766685 | C5: =AVERAGE(A1:A20) -> 0.22461805 | D5: =STDEV(A1:A20) -> 1.3525895
A6: =_xlfn.NORM.INV(RAND(),'hypothèse normale'!$C$5,'hypothèse normale'!$D$5) -> -0.6088449
A7: =_xlfn.NORM.INV(RAND(),'hypothèse normale'!$C$5,'hypothèse normale'!$D$5) -> 0.43981551 | C7: Valeurs de x | D7: Plages | E7: Fréquence | F7: Prob prévue | G7: erreur^2 relative
A8: =_xlfn.NORM.INV(RAND(),'hypothèse normale'!$C$5,'hypothèse normale'!$D$5) -> -3.180153 | C8: -2 | D8: =CONCATENATE("<",C8) -> <-2 | E8: =COUNTIF($A$1:$A$100,D8)/COUNT($A$1:$A$100) -> 0.03 | F8: =_xlfn.NORM.DIST(C8,$C$5,$D$5,TRUE) -> 0.050014773 | G8: =(F8-E8)^2/F8 -> 0.0080094566
A9: =_xlfn.NORM.INV(RAND(),'hypothèse normale'!$C$5,'hypothèse normale'!$D$5) -> 0.17469331 | C9: =C8+0.2 -> -1.8 | D9: =CONCATENATE("[",C8,", ",C9,"]") -> [-2, -1,8] | E9: =COUNTIF($A$1:$A$100,CONCATENATE("<",C9))/COUNT($A$1:$A$100)-SUM($E$8:E8) -> 0.03 | F9: =_xlfn.NORM.DIST(C9,$C$5,$D$5,TRUE)-SUM($F$8:F8) -> 0.017201909 | G9: =(F9-E9)^2/F9 -> 0.0095216836
A10: =_xlfn.NORM.INV(RAND(),'hypothèse normale'!$C$5,'hypothèse normale'!$D$5) -> -0.57730968 | C10: =C9+0.2 -> -1.6 | D10: =CONCATENATE("[",C9,", ",C10,"]") -> [-1,8, -1,6] | E10: =COUNTIF($A$1:$A$100,CONCATENATE("<",C10))/COUNT($A$1:$A$100)-SUM($E$8:E9) -> 0.01 | F10: =_xlfn.NORM.DIST(C10,$C$5,$D$5,TRUE)-SUM($F$8:F9) -> 0.021454794 | G10: =(F10-E10)^2/F10 -> 0.006115757
A11: =_xlfn.NORM.INV(RAND(),'hypothèse normale'!$C$5,'hypothèse normale'!$D$5) -> 2.6050202 | C11: =C10+0.2 -> -1.4 | D11: =CONCATENATE("[",C10,", ",C11,"]") -> [-1,6, -1,4] | E11: =COUNTIF($A$1:$A$100,CONCATENATE("<",C11))/COUNT($A$1:$A$100)-SUM($E$8:E10) -> 0 | F11: =_xlfn.NORM.DIST(C11,$C$5,$D$5,TRUE)-SUM($F$8:F10) -> 0.026181464 | G11: =(F11-E11)^2/F11 -> 0.026181464
A12: =_xlfn.NORM.INV(RAND(),'hypothèse normale'!$C$5,'hypothèse normale'!$D$5) -> -0.94761026 | C12: =C11+0.2 -> -1.2 | D12: =CONCATENATE("[",C11,", ",C12,"]") -> [-1,4, -1,2] | E12: =COUNTIF($A$1:$A$100,CONCATENATE("<",C12))/COUNT($A$1:$A$100)-SUM($E$8:E11) -> 0.03 | F12: =_xlfn.NORM.DIST(C12,$C$5,$D$5,TRUE)-SUM($F$8:F11) -> 0.031259742 | G12: =(F12-E12)^2/F12 -> 5.0766548e-05
A13: =_xlfn.NORM.INV(RAND(),'hypothèse normale'!$C$5,'hypothèse normale'!$D$5) -> 2.0298998 | C13: =C12+0.2 -> -1 | D13: =CONCATENATE("[",C12,", ",C13,"]") -> [-1,2, -1] | E13: =COUNTIF($A$1:$A$100,CONCATENATE("<",C13))/COUNT($A$1:$A$100)-SUM($E$8:E12) -> 0.05 | F13: =_xlfn.NORM.DIST(C13,$C$5,$D$5,TRUE)-SUM($F$8:F12) -> 0.036517306 | G13: =(F13-E13)^2/F13 -> 0.0049779972
A14: =_xlfn.NORM.INV(RAND(),'hypothèse normale'!$C$5,'hypothèse normale'!$D$5) -> -0.41964524 | C14: =C13+0.2 -> -0.8 | D14: =CONCATENATE("[",C13,", ",C14,"]") -> [-1, -0,8] | E14: =COUNTIF($A$1:$A$100,CONCATENATE("<",C14))/COUNT($A$1:$A$100)-SUM($E$8:E13) -> 0.06 | F14: =_xlfn.NORM.DIST(C14,$C$5,$D$5,TRUE)-SUM($F$8:F13) -> 0.041738224 | G14: =(F14-E14)^2/F14 -> 0.0079900975
A15: =_xlfn.NORM.INV(RAND(),'hypothèse normale'!$C$5,'hypothèse normale'!$D$5) -> 1.3656414 | C15: =C14+0.2 -> -0.6 | D15: =CONCATENATE("[",C14,", ",C15,"]") -> [-0,8, -0,6] | E15: =COUNTIF($A$1:$A$100,CONCATENATE("<",C15))/COUNT($A$1:$A$100)-SUM($E$8:E14) -> 0.03 | F15: =_xlfn.NORM.DIST(C15,$C$5,$D$5,TRUE)-SUM($F$8:F14) -> 0.046675727 | G15: =(F15-E15)^2/F15 -> 0.0059576978
A16: =_xlfn.NORM.INV(RAND(),'hypothèse normale'!$C$5,'hypothèse normale'!$D$5) -> 0.6734097 | C16: =C15+0.2 -> -0.4 | D16: =CONCATENATE("[",C15,", ",C16,"]") -> [-0,6, -0,4] | E16: =COUNTIF($A$1:$A$100,CONCATENATE("<",C16))/COUNT($A$1:$A$100)-SUM($E$8:E15) -> 0.11 | F16: =_xlfn.NORM.DIST(C16,$C$5,$D$5,TRUE)-SUM($F$8:F15) -> 0.051070502 | G16: =(F16-E16)^2/F16 -> 0.067997879
A17: =_xlfn.NORM.INV(RAND(),'hypothèse normale'!$C$5,'hypothèse normale'!$D$5) -> 0.44981945 | C17: =C16+0.2 -> -0.2 | D17: =CONCATENATE("[",C16,", ",C17,"]") -> [-0,4, -0,2] | E17: =COUNTIF($A$1:$A$100,CONCATENATE("<",C17))/COUNT($A$1:$A$100)-SUM($E$8:E16) -> 0.05 | F17: =_xlfn.NORM.DIST(C17,$C$5,$D$5,TRUE)-SUM($F$8:F16) -> 0.054672768 | G17: =(F17-E17)^2/F17 -> 0.00039937172
A18: =_xlfn.NORM.INV(RAND(),'hypothèse normale'!$C$5,'hypothèse normale'!$D$5) -> -0.78678804 | C18: =C17+0.2 -> -2.7755576e-16 | D18: =CONCATENATE("[",C17,", ",C18,"]") -> [-0,2, -2,77555756156289E-16] | E18: =COUNTIF($A$1:$A$100,CONCATENATE("<",C18))/COUNT($A$1:$A$100)-SUM($E$8:E17) -> 0.07 | F18: =_xlfn.NORM.DIST(C18,$C$5,$D$5,TRUE)-SUM($F$8:F17) -> 0.057265611 | G18: =(F18-E18)^2/F18 -> 0.0028317982
A19: =_xlfn.NORM.INV(RAND(),'hypothèse normale'!$C$5,'hypothèse normale'!$D$5) -> 0.75242285 | C19: =C18+0.2 -> 0.2 | D19: =CONCATENATE("[",C18,", ",C19,"]") -> [-2,77555756156289E-16, 0,2] | E19: =COUNTIF($A$1:$A$100,CONCATENATE("<",C19))/COUNT($A$1:$A$100)-SUM($E$8:E18) -> 0.05 | F19: =_xlfn.NORM.DIST(C19,$C$5,$D$5,TRUE)-SUM($F$8:F18) -> 0.05868656 | G19: =(F19-E19)^2/F19 -> 0.0012857513
A20: =_xlfn.NORM.INV(RAND(),'hypothèse normale'!$C$5,'hypothèse normale'!$D$5) -> -0.64810453 | C20: =C19+0.2 -> 0.4 | D20: =CONCATENATE("[",C19,", ",C20,"]") -> [0,2, 0,4] | E20: =COUNTIF($A$1:$A$100,CONCATENATE("<",C20))/COUNT($A$1:$A$100)-SUM($E$8:E19) -> 0.06 | F20: =_xlfn.NORM.DIST(C20,$C$5,$D$5,TRUE)-SUM($F$8:F19) -> 0.058844424 | G20: =(F20-E20)^2/F20 -> 2.2693003e-05
... A28: =_xlfn.NORM.INV(RAND(),'hypothèse normale'!$C$5,'hypothèse normale'!$D$5) -> 0.67954312 | C28: =C27+0.2 -> 2 | D28: =CONCATENATE("[",C27,", ",C28,"]") -> [1,8, 2] | E28: =COUNTIF($A$1:$A$100,CONCATENATE("<",C28))/COUNT($A$1:$A$100)-SUM($E$8:E27) -> 0.02 | F28: =_xlfn.NORM.DIST(C28,$C$5,$D$5,TRUE)-SUM($F$8:F27) -> 0.027404834 | G28: =(F28-E28)^2/F28 -> 0.0020007992
A29: =_xlfn.NORM.INV(RAND(),'hypothèse normale'!$C$5,'hypothèse normale'!$D$5) -> 0.38915531 | D29: =CONCATENATE(">",C28) -> >2 | E29: =1-SUM($E$8:E28) -> 0.04 | F29: =1-SUM($F$8:F28) -> 0.094662257 | G29: =(F29-E29)^2/F29 -> 0.031564453
A30: =_xlfn.NORM.INV(RAND(),'hypothèse normale'!$C$5,'hypothèse normale'!$D$5) -> 0.49964469
A31: =_xlfn.NORM.INV(RAND(),'hypothèse normale'!$C$5,'hypothèse normale'!$D$5) -> 0.70655784 | F31: X_i^2 | G31: =SUM(G8:G29) -> 0.32438613
A32: =_xlfn.NORM.INV(RAND(),'hypothèse normale'!$C$5,'hypothèse normale'!$D$5) -> 2.4035131 | F32: X_0^2 | G32: ='hypothèse normale'!G31 -> 0.23189414
A33: =_xlfn.NORM.INV(RAND(),'hypothèse normale'!$C$5,'hypothèse normale'!$D$5) -> -1.7846473
A34: =_xlfn.NORM.INV(RAND(),'hypothèse normale'!$C$5,'hypothèse normale'!$D$5) -> -1.097472 | C34: Table de bootstrap | F34: Probabilité(X_i^2>=X_0^2)
A35: =_xlfn.NORM.INV(RAND(),'hypothèse normale'!$C$5,'hypothèse normale'!$D$5) -> 0.62081088 | C35: Expérience | D35: X_i^2 | F35: p-value | G35: =COUNTIF(D36:D136,CONCATENATE(">",G32))/COUNT(D36:D136) -> 0.64356436
A36: =_xlfn.NORM.INV(RAND(),'hypothèse normale'!$C$5,'hypothèse normale'!$D$5) -> 0.27578527 | D36: =G31 -> 0.32438613
A37: =_xlfn.NORM.INV(RAND(),'hypothèse normale'!$C$5,'hypothèse normale'!$D$5) -> 1.5843532 | C37: 1 | D37: 0.40265936
A38: =_xlfn.NORM.INV(RAND(),'hypothèse normale'!$C$5,'hypothèse normale'!$D$5) -> 0.49379625 | C38: 2 | D38: 0.34276475
A39: =_xlfn.NORM.INV(RAND(),'hypothèse normale'!$C$5,'hypothèse normale'!$D$5) -> 1.8797736 | C39: 3 | D39: 0.30095786
A40: =_xlfn.NORM.INV(RAND(),'hypothèse normale'!$C$5,'hypothèse normale'!$D$5) -> 1.4249067 | C40: 4 | D40: 0.33308399
A41: =_xlfn.NORM.INV(RAND(),'hypothèse normale'!$C$5,'hypothèse normale'!$D$5) -> -0.3852813 | C41: 5 | D41: 0.26348261
A42: =_xlfn.NORM.INV(RAND(),'hypothèse normale'!$C$5,'hypothèse normale'!$D$5) -> -0.48528103 | C42: 6 | D42: 0.19423928
A43: =_xlfn.NORM.INV(RAND(),'hypothèse normale'!$C$5,'hypothèse normale'!$D$5) -> -0.90111467 | C43: 7 | D43: 1.7359216
A44: =_xlfn.NORM.INV(RAND(),'hypothèse normale'!$C$5,'hypothèse normale'!$D$5) -> -2.2458213 | C44: 8 | D44: 3.3944509
A45: =_xlfn.NORM.INV(RAND(),'hypothèse normale'!$C$5,'hypothèse normale'!$D$5) -> -2.2423307 | C45: 9 | D45: 0.23373873
A46: =_xlfn.NORM.INV(RAND(),'hypothèse normale'!$C$5,'hypothèse normale'!$D$5) -> 1.5236622 | C46: 10 | D46: 0.081872246
A47: =_xlfn.NORM.INV(RAND(),'hypothèse normale'!$C$5,'hypothèse normale'!$D$5) -> -0.8541293 | C47: 11 | D47: 0.20798789
...

Sheet hypothèse uniforme
A1: =données0!A1 -> 1.1956768
A2: =données0!A2 -> -0.96440945
A3: =données0!A3 -> 0.97602563 | C3: Hypothèse de loi uniforme
A4: =données0!A4 -> -0.17323445 | C4: a | D4: b
A5: =données0!A5 -> 0.75767452 | C5: =MIN(A1:A100) -> -2.286849 | D5: =MAX(A4:A100) -> 1.942904
A6: =données0!A6 -> 0.078803471
A7: =données0!A7 -> -1.0865878 | C7: Valeurs de x | D7: Plages | E7: Fréquence | F7: Prob prévue | G7: erreur^2 relative
A8: =données0!A8 -> -0.84379214 | C8: -2 | D8: =CONCATENATE("<",C8) -> <-2 | E8: =COUNTIF($A$1:$A$100,D8)/COUNT($A$1:$A$100) -> 0.02 | F8: =IF(C8>$C$5,IF(C8<$D$5,(C8-$C$5)/($D$5-$C$5),1),0) -> 0.067816961 | G8: =IF(F8<=0,0,(F8-E8)^2/F8) -> 0.03371519
A9: =données0!A9 -> 0.50315429 | C9: =C8+0.2 -> -1.8 | D9: =CONCATENATE("[",C8,", ",C9,"]") -> [-2, -1,8] | E9: =COUNTIF($A$1:$A$100,CONCATENATE("<",C9))/COUNT($A$1:$A$100)-SUM($E$8:E8) -> 0.01 | F9: =IF(C9>$C$5,IF(C9<$D$5,(C9-$C$5)/($D$5-$C$5),1),0)-SUM($F$8:F8) -> 0.047284085 | G9: =IF(F9<=0,0,(F9-E9)^2/F9) -> 0.029398962
A10: =données0!A10 -> -0.27748089 | C10: =C9+0.2 -> -1.6 | D10: =CONCATENATE("[",C9,", ",C10,"]") -> [-1,8, -1,6] | E10: =COUNTIF($A$1:$A$100,CONCATENATE("<",C10))/COUNT($A$1:$A$100)-SUM($E$8:E9) -> 0.06 | F10: =IF(C10>$C$5,IF(C10<$D$5,(C10-$C$5)/($D$5-$C$5),1),0)-SUM($F$8:F9) -> 0.047284085 | G10: =IF(F10<=0,0,(F10-E10)^2/F10) -> 0.0034196386
A11: =données0!A11 -> 1.0118689 | C11: =C10+0.2 -> -1.4 | D11: =CONCATENATE("[",C10,", ",C11,"]") -> [-1,6, -1,4] | E11: =COUNTIF($A$1:$A$100,CONCATENATE("<",C11))/COUNT($A$1:$A$100)-SUM($E$8:E10) -> 0.01 | F11: =IF(C11>$C$5,IF(C11<$D$5,(C11-$C$5)/($D$5-$C$5),1),0)-SUM($F$8:F10) -> 0.047284085 | G11: =IF(F11<=0,0,(F11-E11)^2/F11) -> 0.029398962
A12: =données0!A12 -> 1.4974858 | C12: =C11+0.2 -> -1.2 | D12: =CONCATENATE("[",C11,", ",C12,"]") -> [-1,4, -1,2] | E12: =COUNTIF($A$1:$A$100,CONCATENATE("<",C12))/COUNT($A$1:$A$100)-SUM($E$8:E11) -> 0.03 | F12: =IF(C12>$C$5,IF(C12<$D$5,(C12-$C$5)/($D$5-$C$5),1),0)-SUM($F$8:F11) -> 0.047284085 | G12: =IF(F12<=0,0,(F12-E12)^2/F12) -> 0.0063179737
A13: =données0!A13 -> -2.286849 | C13: =C12+0.2 -> -1 | D13: =CONCATENATE("[",C12,", ",C13,"]") -> [-1,2, -1] | E13: =COUNTIF($A$1:$A$100,CONCATENATE("<",C13))/COUNT($A$1:$A$100)-SUM($E$8:E12) -> 0.04 | F13: =IF(C13>$C$5,IF(C13<$D$5,(C13-$C$5)/($D$5-$C$5),1),0)-SUM($F$8:F12) -> 0.047284085 | G13: =IF(F13<=0,0,(F13-E13)^2/F13) -> 0.001122109
A14: =données0!A14 -> 0.29639911 | C14: =C13+0.2 -> -0.8 | D14: =CONCATENATE("[",C13,", ",C14,"]") -> [-1, -0,8] | E14: =COUNTIF($A$1:$A$100,CONCATENATE("<",C14))/COUNT($A$1:$A$100)-SUM($E$8:E13) -> 0.04 | F14: =IF(C14>$C$5,IF(C14<$D$5,(C14-$C$5)/($D$5-$C$5),1),0)-SUM($F$8:F13) -> 0.047284085 | G14: =IF(F14<=0,0,(F14-E14)^2/F14) -> 0.001122109
A15: =données0!A15 -> -1.9130227 | C15: =C14+0.2 -> -0.6 | D15: =CONCATENATE("[",C14,", ",C15,"]") -> [-0,8, -0,6] | E15: =COUNTIF($A$1:$A$100,CONCATENATE("<",C15))/COUNT($A$1:$A$100)-SUM($E$8:E14) -> 0.03 | F15: =IF(C15>$C$5,IF(C15<$D$5,(C15-$C$5)/($D$5-$C$5),1),0)-SUM($F$8:F14) -> 0.047284085 | G15: =IF(F15<=0,0,(F15-E15)^2/F15) -> 0.0063179737
A16: =données0!A16 -> 0.89368855 | C16: =C15+0.2 -> -0.4 | D16: =CONCATENATE("[",C15,", ",C16,"]") -> [-0,6, -0,4] | E16: =COUNTIF($A$1:$A$100,CONCATENATE("<",C16))/COUNT($A$1:$A$100)-SUM($E$8:E15) -> 0.09 | F16: =IF(C16>$C$5,IF(C16<$D$5,(C16-$C$5)/($D$5-$C$5),1),0)-SUM($F$8:F15) -> 0.047284085 | G16: =IF(F16<=0,0,(F16-E16)^2/F16) -> 0.03858908
A17: =données0!A17 -> -1.2090154 | C17: =C16+0.2 -> -0.2 | D17: =CONCATENATE("[",C16,", ",C17,"]") -> [-0,4, -0,2] | E17: =COUNTIF($A$1:$A$100,CONCATENATE("<",C17))/COUNT($A$1:$A$100)-SUM($E$8:E16) -> 0.06 | F17: =IF(C17>$C$5,IF(C17<$D$5,(C17-$C$5)/($D$5-$C$5),1),0)-SUM($F$8:F16) -> 0.047284085 | G17: =IF(F17<=0,0,(F17-E17)^2/F17) -> 0.0034196386
A18: =données0!A18 -> 1.2121842 | C18: =C17+0.2 -> -2.7755576e-16 | D18: =CONCATENATE("[",C17,", ",C18,"]") -> [-0,2, -2,77555756156289E-16] | E18: =COUNTIF($A$1:$A$100,CONCATENATE("<",C18))/COUNT($A$1:$A$100)-SUM($E$8:E17) -> 0.11 | F18: =IF(C18>$C$5,IF(C18<$D$5,(C18-$C$5)/($D$5-$C$5),1),0)-SUM($F$8:F17) -> 0.047284085 | G18: =IF(F18<=0,0,(F18-E18)^2/F18) -> 0.083184139
A19: =données0!A19 -> -0.53615236 | C19: =C18+0.2 -> 0.2 | D19: =CONCATENATE("[",C18,", ",C19,"]") -> [-2,77555756156289E-16, 0,2] | E19: =COUNTIF($A$1:$A$100,CONCATENATE("<",C19))/COUNT($A$1:$A$100)-SUM($E$8:E18) -> 0.1 | F19: =IF(C19>$C$5,IF(C19<$D$5,(C19-$C$5)/($D$5-$C$5),1),0)-SUM($F$8:F18) -> 0.047284085 | G19: =IF(F19<=0,0,(F19-E19)^2/F19) -> 0.058771733
A20: =données0!A20 -> 0.020314962 | C20: =C19+0.2 -> 0.4 | D20: =CONCATENATE("[",C19,", ",C20,"]") -> [0,2, 0,4] | E20: =COUNTIF($A$1:$A$100,CONCATENATE("<",C20))/COUNT($A$1:$A$100)-SUM($E$8:E19) -> 0.09 | F20: =IF(C20>$C$5,IF(C20<$D$5,(C20-$C$5)/($D$5-$C$5),1),0)-SUM($F$8:F19) -> 0.047284085 | G20: =IF(F20<=0,0,(F20-E20)^2/F20) -> 0.03858908
... A28: =données0!A28 -> -1.7598654 | C28: =C27+0.2 -> 2 | D28: =CONCATENATE("[",C27,", ",C28,"]") -> [1,8, 2] | E28: =COUNTIF($A$1:$A$100,CONCATENATE("<",C28))/COUNT($A$1:$A$100)-SUM($E$8:E27) -> 0.01 | F28: =IF(C28>$C$5,IF(C28<$D$5,(C28-$C$5)/($D$5-$C$5),1),0)-SUM($F$8:F27) -> 0.033785417 | G28: =IF(F28<=0,0,(F28-E28)^2/F28) -> 0.016745274
A29: =données0!A29 -> 0.34657906 | D29: =CONCATENATE(">",C28) -> >2 | E29: =1-SUM($E$8:E28) -> 0 | F29: =1-SUM($F$8:F28) -> 0 | G29: =IF(F29<=0,0,(F29-E29)^2/F29) -> 0
A30: =données0!A30 -> 1.317266
A31: =données0!A31 -> 1.0875471 | F31: X_0^2 | G31: =SUM(G8:G29) -> 0.41525095
A32: =données0!A32 -> -0.72249164
A33: =données0!A33 -> -1.0941588
A34: =données0!A34 -> -1.0655924
A35: =données0!A35 -> -2.0803522
A36: =données0!A36 -> -0.42549583
A37: =données0!A37 -> 0.24328073
A38: =données0!A38 -> -0.57136633
A39: =données0!A39 -> 1.942904
A40: =données0!A40 -> 0.31237752
A41: =données0!A41 -> -0.52004455
A42: =données0!A42 -> -0.056480867
A43: =données0!A43 -> 1.1953315
... A100: =données0!A100 -> -1.395002

Sheet hyp.unif. bootstrap
A1: ='hypothèse uniforme'!$C$5+('hypothèse uniforme'!$D$5-'hypothèse uniforme'!$C$5)*RAND() -> -0.36803913
A2: ='hypothèse uniforme'!$C$5+('hypothèse uniforme'!$D$5-'hypothèse uniforme'!$C$5)*RAND() -> -0.042278926
A3: ='hypothèse uniforme'!$C$5+('hypothèse uniforme'!$D$5-'hypothèse uniforme'!$C$5)*RAND() -> 1.794602 | C3: Hypothèse de loi uniforme
A4: ='hypothèse uniforme'!$C$5+('hypothèse uniforme'!$D$5-'hypothèse uniforme'!$C$5)*RAND() -> -0.54126086 | C4: a | D4: b
A5: ='hypothèse uniforme'!$C$5+('hypothèse uniforme'!$D$5-'hypothèse uniforme'!$C$5)*RAND() -> -1.8775974 | C5: =MIN(A1:A100) -> -2.2818001 | D5: =MAX(A4:A100) -> 1.9105586
A6: ='hypothèse uniforme'!$C$5+('hypothèse uniforme'!$D$5-'hypothèse uniforme'!$C$5)*RAND() -> -0.52205958
A7: ='hypothèse uniforme'!$C$5+('hypothèse uniforme'!$D$5-'hypothèse uniforme'!$C$5)*RAND() -> -0.32427828 | C7: Valeurs de x | D7: Plages | E7: Fréquence | F7: Prob prévue | G7: erreur^2 relative
A8: ='hypothèse uniforme'!$C$5+('hypothèse uniforme'!$D$5-'hypothèse uniforme'!$C$5)*RAND() -> -0.74160157 | C8: -2 | D8: =CONCATENATE("<",C8) -> <-2 | E8: =COUNTIF($A$1:$A$100,D8)/COUNT($A$1:$A$100) -> 0.08 | F8: =IF(C8>$C$5,IF(C8<$D$5,(C8-$C$5)/($D$5-$C$5),1),0) -> 0.067217548 | G8: =IF(F8<=0,0,(F8-E8)^2/F8) -> 0.0024307803
A9: ='hypothèse uniforme'!$C$5+('hypothèse uniforme'!$D$5-'hypothèse uniforme'!$C$5)*RAND() -> 1.8722508 | C9: =C8+0.2 -> -1.8 | D9: =CONCATENATE("[",C8,", ",C9,"]") -> [-2, -1,8] | E9: =COUNTIF($A$1:$A$100,CONCATENATE("<",C9))/COUNT($A$1:$A$100)-SUM($E$8:E8) -> 0.04 | F9: =IF(C9>$C$5,IF(C9<$D$5,(C9-$C$5)/($D$5-$C$5),1),0)-SUM($F$8:F8) -> 0.047705843 | G9: =IF(F9<=0,0,(F9-E9)^2/F9) -> 0.0012447115
A10: ='hypothèse uniforme'!$C$5+('hypothèse uniforme'!$D$5-'hypothèse uniforme'!$C$5)*RAND() -> -1.1143546 | C10: =C9+0.2 -> -1.6 | D10: =CONCATENATE("[",C9,", ",C10,"]") -> [-1,8, -1,6] | E10: =COUNTIF($A$1:$A$100,CONCATENATE("<",C10))/COUNT($A$1:$A$100)-SUM($E$8:E9) -> 0.01 | F10: =IF(C10>$C$5,IF(C10<$D$5,(C10-$C$5)/($D$5-$C$5),1),0)-SUM($F$8:F9) -> 0.047705843 | G10: =IF(F10<=0,0,(F10-E10)^2/F10) -> 0.029802022
A11: ='hypothèse uniforme'!$C$5+('hypothèse uniforme'!$D$5-'hypothèse uniforme'!$C$5)*RAND() -> -1.3495999 | C11: =C10+0.2 -> -1.4 | D11: =CONCATENATE("[",C10,", ",C11,"]") -> [-1,6, -1,4] | E11: =COUNTIF($A$1:$A$100,CONCATENATE("<",C11))/COUNT($A$1:$A$100)-SUM($E$8:E10) -> 0.03 | F11: =IF(C11>$C$5,IF(C11<$D$5,(C11-$C$5)/($D$5-$C$5),1),0)-SUM($F$8:F10) -> 0.047705843 | G11: =IF(F11<=0,0,(F11-E11)^2/F11) -> 0.0065714563
A12: ='hypothèse uniforme'!$C$5+('hypothèse uniforme'!$D$5-'hypothèse uniforme'!$C$5)*RAND() -> -0.98539852 | C12: =C11+0.2 -> -1.2 | D12: =CONCATENATE("[",C11,", ",C12,"]") -> [-1,4, -1,2] | E12: =COUNTIF($A$1:$A$100,CONCATENATE("<",C12))/COUNT($A$1:$A$100)-SUM($E$8:E11) -> 0.06 | F12: =IF(C12>$C$5,IF(C12<$D$5,(C12-$C$5)/($D$5-$C$5),1),0)-SUM($F$8:F11) -> 0.047705843 | G12: =IF(F12<=0,0,(F12-E12)^2/F12) -> 0.0031682976
A13: ='hypothèse uniforme'!$C$5+('hypothèse uniforme'!$D$5-'hypothèse uniforme'!$C$5)*RAND() -> 0.84512019 | C13: =C12+0.2 -> -1 | D13: =CONCATENATE("[",C12,", ",C13,"]") -> [-1,2, -1] | E13: =COUNTIF($A$1:$A$100,CONCATENATE("<",C13))/COUNT($A$1:$A$100)-SUM($E$8:E12) -> 0.06 | F13: =IF(C13>$C$5,IF(C13<$D$5,(C13-$C$5)/($D$5-$C$5),1),0)-SUM($F$8:F12) -> 0.047705843 | G13: =IF(F13<=0,0,(F13-E13)^2/F13) -> 0.0031682976
A14: ='hypothèse uniforme'!$C$5+('hypothèse uniforme'!$D$5-'hypothèse uniforme'!$C$5)*RAND() -> -0.84615283 | C14: =C13+0.2 -> -0.8 | D14: =CONCATENATE("[",C13,", ",C14,"]") -> [-1, -0,8] | E14: =COUNTIF($A$1:$A$100,CONCATENATE("<",C14))/COUNT($A$1:$A$100)-SUM($E$8:E13) -> 0.04 | F14: =IF(C14>$C$5,IF(C14<$D$5,(C14-$C$5)/($D$5-$C$5),1),0)-SUM($F$8:F13) -> 0.047705843 | G14: =IF(F14<=0,0,(F14-E14)^2/F14) -> 0.0012447115
A15: ='hypothèse uniforme'!$C$5+('hypothèse uniforme'!$D$5-'hypothèse uniforme'!$C$5)*RAND() -> 1.042503 | C15: =C14+0.2 -> -0.6 | D15: =CONCATENATE("[",C14,", ",C15,"]") -> [-0,8, -0,6] | E15: =COUNTIF($A$1:$A$100,CONCATENATE("<",C15))/COUNT($A$1:$A$100)-SUM($E$8:E14) -> 0.03 | F15: =IF(C15>$C$5,IF(C15<$D$5,(C15-$C$5)/($D$5-$C$5),1),0)-SUM($F$8:F14) -> 0.047705843 | G15: =IF(F15<=0,0,(F15-E15)^2/F15) -> 0.0065714563
A16: ='hypothèse uniforme'!$C$5+('hypothèse uniforme'!$D$5-'hypothèse uniforme'!$C$5)*RAND() -> -0.98038553 | C16: =C15+0.2 -> -0.4 | D16: =CONCATENATE("[",C15,", ",C16,"]") -> [-0,6, -0,4] | E16: =COUNTIF($A$1:$A$100,CONCATENATE("<",C16))/COUNT($A$1:$A$100)-SUM($E$8:E15) -> 0.08 | F16: =IF(C16>$C$5,IF(C16<$D$5,(C16-$C$5)/($D$5-$C$5),1),0)-SUM($F$8:F15) -> 0.047705843 | G16: =IF(F16<=0,0,(F16-E16)^2/F16) -> 0.021861318
A17: ='hypothèse uniforme'!$C$5+('hypothèse uniforme'!$D$5-'hypothèse uniforme'!$C$5)*RAND() -> -2.2000139 | C17: =C16+0.2 -> -0.2 | D17: =CONCATENATE("[",C16,", ",C17,"]") -> [-0,4, -0,2] | E17: =COUNTIF($A$1:$A$100,CONCATENATE("<",C17))/COUNT($A$1:$A$100)-SUM($E$8:E16) -> 0.05 | F17: =IF(C17>$C$5,IF(C17<$D$5,(C17-$C$5)/($D$5-$C$5),1),0)-SUM($F$8:F16) -> 0.047705843 | G17: =IF(F17<=0,0,(F17-E17)^2/F17) -> 0.00011032524
A18: ='hypothèse uniforme'!$C$5+('hypothèse uniforme'!$D$5-'hypothèse uniforme'!$C$5)*RAND() -> 1.0590981 | C18: =C17+0.2 -> -2.7755576e-16 | D18: =CONCATENATE("[",C17,", ",C18,"]") -> [-0,2, -2,77555756156289E-16] | E18: =COUNTIF($A$1:$A$100,CONCATENATE("<",C18))/COUNT($A$1:$A$100)-SUM($E$8:E17) -> 0.05 | F18: =IF(C18>$C$5,IF(C18<$D$5,(C18-$C$5)/($D$5-$C$5),1),0)-SUM($F$8:F17) -> 0.047705843 | G18: =IF(F18<=0,0,(F18-E18)^2/F18) -> 0.00011032524
A19: ='hypothèse uniforme'!$C$5+('hypothèse uniforme'!$D$5-'hypothèse uniforme'!$C$5)*RAND() -> 0.60950389 | C19: =C18+0.2 -> 0.2 | D19: =CONCATENATE("[",C18,", ",C19,"]") -> [-2,77555756156289E-16, 0,2] | E19: =COUNTIF($A$1:$A$100,CONCATENATE("<",C19))/COUNT($A$1:$A$100)-SUM($E$8:E18) -> 0.05 | F19: =IF(C19>$C$5,IF(C19<$D$5,(C19-$C$5)/($D$5-$C$5),1),0)-SUM($F$8:F18) -> 0.047705843 | G19: =IF(F19<=0,0,(F19-E19)^2/F19) -> 0.00011032524
A20: ='hypothèse uniforme'!$C$5+('hypothèse uniforme'!$D$5-'hypothèse uniforme'!$C$5)*RAND() -> -2.1194989 | C20: =C19+0.2 -> 0.4 | D20: =CONCATENATE("[",C19,", ",C20,"]") -> [0,2, 0,4] | E20: =COUNTIF($A$1:$A$100,CONCATENATE("<",C20))/COUNT($A$1:$A$100)-SUM($E$8:E19) -> 0.04 | F20: =IF(C20>$C$5,IF(C20<$D$5,(C20-$C$5)/($D$5-$C$5),1),0)-SUM($F$8:F19) -> 0.047705843 | G20: =IF(F20<=0,0,(F20-E20)^2/F20) -> 0.0012447115
... A28: ='hypothèse uniforme'!$C$5+('hypothèse uniforme'!$D$5-'hypothèse uniforme'!$C$5)*RAND() -> 1.2002183 | C28: =C27+0.2 -> 2 | D28: =CONCATENATE("[",C27,", ",C28,"]") -> [1,8, 2] | E28: =COUNTIF($A$1:$A$100,CONCATENATE("<",C28))/COUNT($A$1:$A$100)-SUM($E$8:E27) -> 0.03 | F28: =IF(C28>$C$5,IF(C28<$D$5,(C28-$C$5)/($D$5-$C$5),1),0)-SUM($F$8:F27) -> 0.026371444 | G28: =IF(F28<=0,0,(F28-E28)^2/F28) -> 0.00049926788
A29: ='hypothèse uniforme'!$C$5+('hypothèse uniforme'!$D$5-'hypothèse uniforme'!$C$5)*RAND() -> -0.51573081 | D29: =CONCATENATE(">",C28) -> >2 | E29: =1-SUM($E$8:E28) -> 0 | F29: =1-SUM($F$8:F28) -> 0 | G29: =IF(F29<=0,0,(F29-E29)^2/F29) -> 0
A30: ='hypothèse uniforme'!$C$5+('hypothèse uniforme'!$D$5-'hypothèse uniforme'!$C$5)*RAND() -> -1.3393965
A31: ='hypothèse uniforme'!$C$5+('hypothèse uniforme'!$D$5-'hypothèse uniforme'!$C$5)*RAND() -> -2.0108303 | F31: X_i^2 | G31: =SUM(G8:G29) -> 0.12921859
A32: ='hypothèse uniforme'!$C$5+('hypothèse uniforme'!$D$5-'hypothèse uniforme'!$C$5)*RAND() -> -1.1566379 | F32: X_0^2 | G32: ='hypothèse uniforme'!G31 -> 0.41525095
A33: ='hypothèse uniforme'!$C$5+('hypothèse uniforme'!$D$5-'hypothèse uniforme'!$C$5)*RAND() -> 0.89170166
A34: ='hypothèse uniforme'!$C$5+('hypothèse uniforme'!$D$5-'hypothèse uniforme'!$C$5)*RAND() -> 1.4395984 | C34: Table de bootstrap | F34: Probabilité(X_i^2>=X_0^2)
A35: ='hypothèse uniforme'!$C$5+('hypothèse uniforme'!$D$5-'hypothèse uniforme'!$C$5)*RAND() -> -2.0913469 | C35: Expérience | D35: X_i^2 | F35: p-value | G35: =COUNTIF(D36:D136,CONCATENATE(">",G32))/COUNT(D36:D136) -> 0
A36: ='hypothèse uniforme'!$C$5+('hypothèse uniforme'!$D$5-'hypothèse uniforme'!$C$5)*RAND() -> 1.2414412 | D36: =G31 -> 0.12921859
A37: ='hypothèse uniforme'!$C$5+('hypothèse uniforme'!$D$5-'hypothèse uniforme'!$C$5)*RAND() -> -0.43450691 | C37: 1 | D37: 0.13392429
A38: ='hypothèse uniforme'!$C$5+('hypothèse uniforme'!$D$5-'hypothèse uniforme'!$C$5)*RAND() -> -1.2921729 | C38: 2 | D38: 0.29913243
A39: ='hypothèse uniforme'!$C$5+('hypothèse uniforme'!$D$5-'hypothèse uniforme'!$C$5)*RAND() -> 0.56095781 | C39: 3 | D39: 0.15389336
A40: ='hypothèse uniforme'!$C$5+('hypothèse uniforme'!$D$5-'hypothèse uniforme'!$C$5)*RAND() -> -0.57406721 | C40: 4 | D40: 0.27765162
A41: ='hypothèse uniforme'!$C$5+('hypothèse uniforme'!$D$5-'hypothèse uniforme'!$C$5)*RAND() -> 1.5808618 | C41: 5 | D41: 0.20087808
A42: ='hypothèse uniforme'!$C$5+('hypothèse uniforme'!$D$5-'hypothèse uniforme'!$C$5)*RAND() -> -1.6826295 | C42: 6 | D42: 0.18642123
A43: ='hypothèse uniforme'!$C$5+('hypothèse uniforme'!$D$5-'hypothèse uniforme'!$C$5)*RAND() -> -0.78917077 | C43: 7 | D43: 0.19543715
A44: ='hypothèse uniforme'!$C$5+('hypothèse uniforme'!$D$5-'hypothèse uniforme'!$C$5)*RAND() -> -0.87696249 | C44: 8 | D44: 0.18251029
A45: ='hypothèse uniforme'!$C$5+('hypothèse uniforme'!$D$5-'hypothèse uniforme'!$C$5)*RAND() -> -0.069892043 | C45: 9 | D45: 0.1275475
A46: ='hypothèse uniforme'!$C$5+('hypothèse uniforme'!$D$5-'hypothèse uniforme'!$C$5)*RAND() -> -0.22057215 | C46: 10 | D46: 0.18304405
A47: ='hypothèse uniforme'!$C$5+('hypothèse uniforme'!$D$5-'hypothèse uniforme'!$C$5)*RAND() -> -0.55088759 | C47: 11 | D47: 0.1947749
...
