Workbook
Name echantillon: 'non-uniforme cercle (attention)'!$B$6:$B$505
Name echantillon: 'Prob zone rouge'!$D$5:$D$204
Name echantillon: 'stats du rayon'!$D$4:$D$503

Sheet uniforme cercle (rejet)
A3: Application de la méthode de rejet pour générer des points uniformément répartis sur la surface d'un cercle de rayon 1.
A6: C | B6: =4/PI() -> 1.2732395
A8: Simulation | L8: Échantillons préservés
A9: Numéro échantillon | B9: U - uniforme | C9: V1 - Uniforme | D9: V2 - Uniforme | E9: f_Z(v) | F9: f_V(v) | G9: Accepté | H9: Quantité acceptée | I9: Z1 | J9: Z2 | L9: index | M9: Z1 | N9: Z2 | O9: Distance de zéro
A10: 1 | B10: =RAND() -> 0.37838519 | C10: =2*RAND()-1 -> -0.37065883 | D10: =2*RAND()-1 -> -0.37285529 | E10: =(1/PI())*IF(C10^2+D10^2<=1,1,0) -> 0.31830989 | F10: =1/4 -> 0.25 | G10: =IF($B$6*B10<=E10/F10,1,0) -> 1 | H10: =IF(G10=1,SUM($G$10:G10),"-") -> 1 | I10: =IF($G10,C10,"-") -> -0.37065883 | J10: =IF($G10,D10,"-") -> -0.37285529 | L10: 1 | M10: =VLOOKUP(L10,$H$10:$J$687,2,FALSE) -> -0.37065883 | N10: =VLOOKUP(L10,$H$10:$J$687,3,FALSE) -> -0.37285529 | O10: =SQRT(M10^2+N10^2) -> 0.52574617
A11: =1+A10 -> 2 | B11: =RAND() -> 0.95418604 | C11: =2*RAND()-1 -> -0.090019855 | D11: =2*RAND()-1 -> -0.9067269 | E11: =(1/PI())*IF(C11^2+D11^2<=1,1,0) -> 0.31830989 | F11: =1/4 -> 0.25 | G11: =IF($B$6*B11<=E11/F11,1,0) -> 1 | H11: =IF(G11=1,SUM($G$10:G11),"-") -> 2 | I11: =IF($G11,C11,"-") -> -0.090019855 | J11: =IF($G11,D11,"-") -> -0.9067269 | L11: =1+L10 -> 2 | M11: =VLOOKUP(L11,$H$10:$J$687,2,FALSE) -> -0.090019855 | N11: =VLOOKUP(L11,$H$10:$J$687,3,FALSE) -> -0.9067269 | O11: =SQRT(M11^2+N11^2) -> 0.91118453
A12: =1+A11 -> 3 | B12: =RAND() -> 0.44140354 | C12: =2*RAND()-1 -> -0.2489995 | D12: =2*RAND()-1 -> 0.66272336 | E12: =(1/PI())*IF(C12^2+D12^2<=1,1,0) -> 0.31830989 | F12: =1/4 -> 0.25 | G12: =IF($B$6*B12<=E12/F12,1,0) -> 1 | H12: =IF(G12=1,SUM($G$10:G12),"-") -> 3 | I12: =IF($G12,C12,"-") -> -0.2489995 | J12: =IF($G12,D12,"-") -> 0.66272336 | L12: =1+L11 -> 3 | M12: =VLOOKUP(L12,$H$10:$J$687,2,FALSE) -> -0.2489995 | N12: =VLOOKUP(L12,$H$10:$J$687,3,FALSE) -> 0.66272336 | O12: =SQRT(M12^2+N12^2) -> 0.70795693
A13: =1+A12 -> 4 | B13: =RAND() -> 0.62803987 | C13: =2*RAND()-1 -> 0.068244953 | D13: =2*RAND()-1 -> 0.15403685 | E13: =(1/PI())*IF(C13^2+D13^2<=1,1,0) -> 0.31830989 | F13: =1/4 -> 0.25 | G13: =IF($B$6*B13<=E13/F13,1,0) -> 1 | H13: =IF(G13=1,SUM($G$10:G13),"-") -> 4 | I13: =IF($G13,C13,"-") -> 0.068244953 | J13: =IF($G13,D13,"-") -> 0.15403685 | L13: =1+L12 -> 4 | M13: =VLOOKUP(L13,$H$10:$J$687,2,FALSE) -> 0.068244953 | N13: =VLOOKUP(L13,$H$10:$J$687,3,FALSE) -> 0.15403685 | O13: =SQRT(M13^2+N13^2) -> 0.16847767
A14: =1+A13 -> 5 | B14: =RAND() -> 0.26267245 | C14: =2*RAND()-1 -> 0.6898394 | D14: =2*RAND()-1 -> -0.85452478 | E14: =(1/PI())*IF(C14^2+D14^2<=1,1,0) -> 0 | F14: =1/4 -> 0.25 | G14: =IF($B$6*B14<=E14/F14,1,0) -> 0 | H14: =IF(G14=1,SUM($G$10:G14),"-") -> - | I14: =IF($G14,C14,"-") -> - | J14: =IF($G14,D14,"-") -> - | L14: =1+L13 -> 5 | M14: =VLOOKUP(L14,$H$10:$J$687,2,FALSE) -> 0.22665299 | N14: =VLOOKUP(L14,$H$10:$J$687,3,FALSE) -> 0.44924293 | O14: =SQRT(M14^2+N14^2) -> 0.50318067
A15: =1+A14 -> 6 | B15: =RAND() -> 0.28049223 | C15: =2*RAND()-1 -> 0.22665299 | D15: =2*RAND()-1 -> 0.44924293 | E15: =(1/PI())*IF(C15^2+D15^2<=1,1,0) -> 0.31830989 | F15: =1/4 -> 0.25 | G15: =IF($B$6*B15<=E15/F15,1,0) -> 1 | H15: =IF(G15=1,SUM($G$10:G15),"-") -> 5 | I15: =IF($G15,C15,"-") -> 0.22665299 | J15: =IF($G15,D15,"-") -> 0.44924293 | L15: =1+L14 -> 6 | M15: =VLOOKUP(L15,$H$10:$J$687,2,FALSE) -> 0.28192509 | N15: =VLOOKUP(L15,$H$10:$J$687,3,FALSE) -> -0.74365115 | O15: =SQRT(M15^2+N15^2) -> 0.79529793
A16: =1+A15 -> 7 | B16: =RAND() -> 0.29232516 | C16: =2*RAND()-1 -> 0.28192509 | D16: =2*RAND()-1 -> -0.74365115 | E16: =(1/PI())*IF(C16^2+D16^2<=1,1,0) -> 0.31830989 | F16: =1/4 -> 0.25 | G16: =IF($B$6*B16<=E16/F16,1,0) -> 1 | H16: =IF(G16=1,SUM($G$10:G16),"-") -> 6 | I16: =IF($G16,C16,"-") -> 0.28192509 | J16: =IF($G16,D16,"-") -> -0.74365115 | L16: =1+L15 -> 7 | M16: =VLOOKUP(L16,$H$10:$J$687,2,FALSE) -> 0.32873346 | N16: =VLOOKUP(L16,$H$10:$J$687,3,FALSE) -> 0.69839745 | O16: =SQRT(M16^2+N16^2) -> 0.77189681
A17: =1+A16 -> 8 | B17: =RAND() -> 0.1893526 | C17: =2*RAND()-1 -> 0.75356738 | D17: =2*RAND()-1 -> 0.9217297 | E17: =(1/PI())*IF(C17^2+D17^2<=1,1,0) -> 0 | F17: =1/4 -> 0.25 | G17: =IF($B$6*B17<=E17/F17,1,0) -> 0 | H17: =IF(G17=1,SUM($G$10:G17),"-") -> - | I17: =IF($G17,C17,"-") -> - | J17: =IF($G17,D17,"-") -> - | L17: =1+L16 -> 8 | M17: =VLOOKUP(L17,$H$10:$J$687,2,FALSE) -> -0.85827678 | N17: =VLOOKUP(L17,$H$10:$J$687,3,FALSE) -> 0.085271867 | O17: =SQRT(M17^2+N17^2) -> 0.86250237
A18: =1+A17 -> 9 | B18: =RAND() -> 0.21444888 | C18: =2*RAND()-1 -> 0.32873346 | D18: =2*RAND()-1 -> 0.69839745 | E18: =(1/PI())*IF(C18^2+D18^2<=1,1,0) -> 0.31830989 | F18: =1/4 -> 0.25 | G18: =IF($B$6*B18<=E18/F18,1,0) -> 1 | H18: =IF(G18=1,SUM($G$10:G18),"-") -> 7 | I18: =IF($G18,C18,"-") -> 0.32873346 | J18: =IF($G18,D18,"-") -> 0.69839745 | L18: =1+L17 -> 9 | M18: =VLOOKUP(L18,$H$10:$J$687,2,FALSE) -> 0.18970218 | N18: =VLOOKUP(L18,$H$10:$J$687,3,FALSE) -> -0.64992696 | O18: =SQRT(M18^2+N18^2) -> 0.67704651
A19: =1+A18 -> 10 | B19: =RAND() -> 0.66295432 | C19: =2*RAND()-1 -> -0.85827678 | D19: =2*RAND()-1 -> 0.085271867 | E19: =(1/PI())*IF(C19^2+D19^2<=1,1,0) -> 0.31830989 | F19: =1/4 -> 0.25 | G19: =IF($B$6*B19<=E19/F19,1,0) -> 1 | H19: =IF(G19=1,SUM($G$10:G19),"-") -> 8 | I19: =IF($G19,C19,"-") -> -0.85827678 | J19: =IF($G19,D19,"-") -> 0.085271867 | L19: =1+L18 -> 10 | M19: =VLOOKUP(L19,$H$10:$J$687,2,FALSE) -> 0.36918323 | N19: =VLOOKUP(L19,$H$10:$J$687,3,FALSE) -> 0.39114529 | O19: =SQRT(M19^2+N19^2) -> 0.53785769
A20: =1+A19 -> 11 | B20: =RAND() -> 0.65278825 | C20: =2*RAND()-1 -> 0.18970218 | D20: =2*RAND()-1 -> -0.64992696 | E20: =(1/PI())*IF(C20^2+D20^2<=1,1,0) -> 0.31830989 | F20: =1/4 -> 0.25 | G20: =IF($B$6*B20<=E20/F20,1,0) -> 1 | H20: =IF(G20=1,SUM($G$10:G20),"-") -> 9 | I20: =IF($G20,C20,"-") -> 0.18970218 | J20: =IF($G20,D20,"-") -> -0.64992696 | L20: =1+L19 -> 11 | M20: =VLOOKUP(L20,$H$10:$J$687,2,FALSE) -> -0.24941142 | N20: =VLOOKUP(L20,$H$10:$J$687,3,FALSE) -> 0.093479787 | O20: =SQRT(M20^2+N20^2) -> 0.26635413
A21: =1+A20 -> 12 | B21: =RAND() -> 0.91956291 | C21: =2*RAND()-1 -> 0.36918323 | D21: =2*RAND()-1 -> 0.39114529 | E21: =(1/PI())*IF(C21^2+D21^2<=1,1,0) -> 0.31830989 | F21: =1/4 -> 0.25 | G21: =IF($B$6*B21<=E21/F21,1,0) -> 1 | H21: =IF(G21=1,SUM($G$10:G21),"-") -> 10 | I21: =IF($G21,C21,"-") -> 0.36918323 | J21: =IF($G21,D21,"-") -> 0.39114529 | L21: =1+L20 -> 12 | M21: =VLOOKUP(L21,$H$10:$J$687,2,FALSE) -> -0.82542412 | N21: =VLOOKUP(L21,$H$10:$J$687,3,FALSE) -> -0.19855571 | O21: =SQRT(M21^2+N21^2) -> 0.84896958
A22: =1+A21 -> 13 | B22: =RAND() -> 0.71892285 | C22: =2*RAND()-1 -> -0.24941142 | D22: =2*RAND()-1 -> 0.093479787 | E22: =(1/PI())*IF(C22^2+D22^2<=1,1,0) -> 0.31830989 | F22: =1/4 -> 0.25 | G22: =IF($B$6*B22<=E22/F22,1,0) -> 1 | H22: =IF(G22=1,SUM($G$10:G22),"-") -> 11 | I22: =IF($G22,C22,"-") -> -0.24941142 | J22: =IF($G22,D22,"-") -> 0.093479787 | L22: =1+L21 -> 13 | M22: =VLOOKUP(L22,$H$10:$J$687,2,FALSE) -> -0.43889577 | N22: =VLOOKUP(L22,$H$10:$J$687,3,FALSE) -> -0.78678866 | O22: =SQRT(M22^2+N22^2) -> 0.90092502
... A509: =1+A508 -> 500 | B509: =RAND() -> 0.28257053 | C509: =2*RAND()-1 -> -0.86310444 | D509: =2*RAND()-1 -> 0.50038155 | E509: =(1/PI())*IF(C509^2+D509^2<=1,1,0) -> 0.31830989 | F509: =1/4 -> 0.25 | G509: =IF($B$6*B509<=E509/F509,1,0) -> 1 | H509: =IF(G509=1,SUM($G$10:G509),"-") -> 391 | I509: =IF($G509,C509,"-") -> -0.86310444 | J509: =IF($G509,D509,"-") -> 0.50038155 | L509: =1+L508 -> 500 | M509: =VLOOKUP(L509,$H$10:$J$687,2,FALSE) -> -0.60522426 | N509: =VLOOKUP(L509,$H$10:$J$687,3,FALSE) -> 0.21031972 | O509: =SQRT(M509^2+N509^2) -> 0.64072676
A510: =1+A509 -> 501 | B510: =RAND() -> 0.81237862 | C510: =2*RAND()-1 -> -0.10917981 | D510: =2*RAND()-1 -> -0.17812218 | E510: =(1/PI())*IF(C510^2+D510^2<=1,1,0) -> 0.31830989 | F510: =1/4 -> 0.25 | G510: =IF($B$6*B510<=E510/F510,1,0) -> 1 | H510: =IF(G510=1,SUM($G$10:G510),"-") -> 392 | I510: =IF($G510,C510,"-") -> -0.10917981 | J510: =IF($G510,D510,"-") -> -0.17812218
A511: =1+A510 -> 502 | B511: =RAND() -> 0.73491447 | C511: =2*RAND()-1 -> 0.64169908 | D511: =2*RAND()-1 -> -0.75851401 | E511: =(1/PI())*IF(C511^2+D511^2<=1,1,0) -> 0.31830989 | F511: =1/4 -> 0.25 | G511: =IF($B$6*B511<=E511/F511,1,0) -> 1 | H511: =IF(G511=1,SUM($G$10:G511),"-") -> 393 | I511: =IF($G511,C511,"-") -> 0.64169908 | J511: =IF($G511,D511,"-") -> -0.75851401
A512: =1+A511 -> 503 | B512: =RAND() -> 0.54766089 | C512: =2*RAND()-1 -> -0.90171816 | D512: =2*RAND()-1 -> -0.32770354 | E512: =(1/PI())*IF(C512^2+D512^2<=1,1,0) -> 0.31830989 | F512: =1/4 -> 0.25 | G512: =IF($B$6*B512<=E512/F512,1,0) -> 1 | H512: =IF(G512=1,SUM($G$10:G512),"-") -> 394 | I512: =IF($G512,C512,"-") -> -0.90171816 | J512: =IF($G512,D512,"-") -> -0.32770354
A513: =1+A512 -> 504 | B513: =RAND() -> 0.18362982 | C513: =2*RAND()-1 -> -0.14037416 | D513: =2*RAND()-1 -> 0.82425706 | E513: =(1/PI())*IF(C513^2+D513^2<=1,1,0) -> 0.31830989 | F513: =1/4 -> 0.25 | G513: =IF($B$6*B513<=E513/F513,1,0) -> 1 | H513: =IF(G513=1,SUM($G$10:G513),"-") -> 395 | I513: =IF($G513,C513,"-") -> -0.14037416 | J513: =IF($G513,D513,"-") -> 0.82425706
A514: =1+A513 -> 505 | B514: =RAND() -> 0.56221606 | C514: =2*RAND()-1 -> -0.19873451 | D514: =2*RAND()-1 -> 0.10718982 | E514: =(1/PI())*IF(C514^2+D514^2<=1,1,0) -> 0.31830989 | F514: =1/4 -> 0.25 | G514: =IF($B$6*B514<=E514/F514,1,0) -> 1 | H514: =IF(G514=1,SUM($G$10:G514),"-") -> 396 | I514: =IF($G514,C514,"-") -> -0.19873451 | J514: =IF($G514,D514,"-") -> 0.10718982
A515: =1+A514 -> 506 | B515: =RAND() -> 0.81808634 | C515: =2*RAND()-1 -> -0.27737481 | D515: =2*RAND()-1 -> -0.70463439 | E515: =(1/PI())*IF(C515^2+D515^2<=1,1,0) -> 0.31830989 | F515: =1/4 -> 0.25 | G515: =IF($B$6*B515<=E515/F515,1,0) -> 1 | H515: =IF(G515=1,SUM($G$10:G515),"-") -> 397 | I515: =IF($G515,C515,"-") -> -0.27737481 | J515: =IF($G515,D515,"-") -> -0.70463439
A516: =1+A515 -> 507 | B516: =RAND() -> 0.68368722 | C516: =2*RAND()-1 -> 0.73939638 | D516: =2*RAND()-1 -> -0.073884565 | E516: =(1/PI())*IF(C516^2+D516^2<=1,1,0) -> 0.31830989 | F516: =1/4 -> 0.25 | G516: =IF($B$6*B516<=E516/F516,1,0) -> 1 | H516: =IF(G516=1,SUM($G$10:G516),"-") -> 398 | I516: =IF($G516,C516,"-") -> 0.73939638 | J516: =IF($G516,D516,"-") -> -0.073884565
A517: =1+A516 -> 508 | B517: =RAND() -> 0.84130181 | C517: =2*RAND()-1 -> 0.49300531 | D517: =2*RAND()-1 -> 0.44260515 | E517: =(1/PI())*IF(C517^2+D517^2<=1,1,0) -> 0.31830989 | F517: =1/4 -> 0.25 | G517: =IF($B$6*B517<=E517/F517,1,0) -> 1 | H517: =IF(G517=1,SUM($G$10:G517),"-") -> 399 | I517: =IF($G517,C517,"-") -> 0.49300531 | J517: =IF($G517,D517,"-") -> 0.44260515
A518: =1+A517 -> 509 | B518: =RAND() -> 0.93517876 | C518: =2*RAND()-1 -> 0.33729308 | D518: =2*RAND()-1 -> 0.77149506 | E518: =(1/PI())*IF(C518^2+D518^2<=1,1,0) -> 0.31830989 | F518: =1/4 -> 0.25 | G518: =IF($B$6*B518<=E518/F518,1,0) -> 1 | H518: =IF(G518=1,SUM($G$10:G518),"-") -> 400 | I518: =IF($G518,C518,"-") -> 0.33729308 | J518: =IF($G518,D518,"-") -> 0.77149506
A519: =1+A518 -> 510 | B519: =RAND() -> 0.14372961 | C519: =2*RAND()-1 -> 0.42809798 | D519: =2*RAND()-1 -> -0.38981084 | E519: =(1/PI())*IF(C519^2+D519^2<=1,1,0) -> 0.31830989 | F519: =1/4 -> 0.25 | G519: =IF($B$6*B519<=E519/F519,1,0) -> 1 | H519: =IF(G519=1,SUM($G$10:G519),"-") -> 401 | I519: =IF($G519,C519,"-") -> 0.42809798 | J519: =IF($G519,D519,"-") -> -0.38981084
A520: =1+A519 -> 511 | B520: =RAND() -> 0.4385561 | C520: =2*RAND()-1 -> -0.63588839 | D520: =2*RAND()-1 -> -0.91881623 | E520: =(1/PI())*IF(C520^2+D520^2<=1,1,0) -> 0 | F520: =1/4 -> 0.25 | G520: =IF($B$6*B520<=E520/F520,1,0) -> 0 | H520: =IF(G520=1,SUM($G$10:G520),"-") -> - | I520: =IF($G520,C520,"-") -> - | J520: =IF($G520,D520,"-") -> -
A521: =1+A520 -> 512 | B521: =RAND() -> 0.22090467 | C521: =2*RAND()-1 -> -0.86928324 | D521: =2*RAND()-1 -> 0.46740526 | E521: =(1/PI())*IF(C521^2+D521^2<=1,1,0) -> 0.31830989 | F521: =1/4 -> 0.25 | G521: =IF($B$6*B521<=E521/F521,1,0) -> 1 | H521: =IF(G521=1,SUM($G$10:G521),"-") -> 402 | I521: =IF($G521,C521,"-") -> -0.86928324 | J521: =IF($G521,D521,"-") -> 0.46740526
... A687: =1+A686 -> 678 | B687: =RAND() -> 0.6331804 | C687: =2*RAND()-1 -> 0.31372733 | D687: =2*RAND()-1 -> 0.5034221 | E687: =(1/PI())*IF(C687^2+D687^2<=1,1,0) -> 0.31830989 | F687: =1/4 -> 0.25 | G687: =IF($B$6*B687<=E687/F687,1,0) -> 1 | H687: =IF(G687=1,SUM($G$10:G687),"-") -> 535 | I687: =IF($G687,C687,"-") -> 0.31372733 | J687: =IF($G687,D687,"-") -> 0.5034221

Sheet stats du rayon
H1: Fonction de répartition
H2: Min | I2: =MIN(echantillon) -> 0.038927476
A3: index | B3: Z1 | C3: Z2 | D3: Distance de zéro | H3: Max | I3: =MAX(echantillon) -> 0.99989223
A4: ='uniforme cercle (rejet)'!L10 -> 1 | B4: ='uniforme cercle (rejet)'!M10 -> -0.37065883 | C4: ='uniforme cercle (rejet)'!N10 -> -0.37285529 | D4: ='uniforme cercle (rejet)'!O10 -> 0.52574617 | H4: Nombre de bins | I4: 11
A5: ='uniforme cercle (rejet)'!L11 -> 2 | B5: ='uniforme cercle (rejet)'!M11 -> -0.090019855 | C5: ='uniforme cercle (rejet)'!N11 -> -0.9067269 | D5: ='uniforme cercle (rejet)'!O11 -> 0.91118453 | H5: Bins | I5: x | J5: P(X<=x) | K5: Histogramme
A6: ='uniforme cercle (rejet)'!L12 -> 3 | B6: ='uniforme cercle (rejet)'!M12 -> -0.2489995 | C6: ='uniforme cercle (rejet)'!N12 -> 0.66272336 | D6: ='uniforme cercle (rejet)'!O12 -> 0.70795693 | H6: 0 | I6: =I$2+H6/(I$4-1)*(I$3-I$2) -> 0.038927476 | J6: =COUNTIF(echantillon,"<="&I6)/COUNT(echantillon) -> 0.002 | K6: =J6-0 -> 0.002
A7: ='uniforme cercle (rejet)'!L13 -> 4 | B7: ='uniforme cercle (rejet)'!M13 -> 0.068244953 | C7: ='uniforme cercle (rejet)'!N13 -> 0.15403685 | D7: ='uniforme cercle (rejet)'!O13 -> 0.16847767 | H7: =H6+1 -> 1 | I7: =I$2+H7/(I$4-1)*(I$3-I$2) -> 0.13502395 | J7: =COUNTIF(echantillon,"<="&I7)/COUNT(echantillon) -> 0.026 | K7: =J7-J6 -> 0.024
A8: ='uniforme cercle (rejet)'!L14 -> 5 | B8: ='uniforme cercle (rejet)'!M14 -> 0.22665299 | C8: ='uniforme cercle (rejet)'!N14 -> 0.44924293 | D8: ='uniforme cercle (rejet)'!O14 -> 0.50318067 | H8: =H7+1 -> 2 | I8: =I$2+H8/(I$4-1)*(I$3-I$2) -> 0.23112043 | J8: =COUNTIF(echantillon,"<="&I8)/COUNT(echantillon) -> 0.058 | K8: =J8-J7 -> 0.032
A9: ='uniforme cercle (rejet)'!L15 -> 6 | B9: ='uniforme cercle (rejet)'!M15 -> 0.28192509 | C9: ='uniforme cercle (rejet)'!N15 -> -0.74365115 | D9: ='uniforme cercle (rejet)'!O15 -> 0.79529793 | H9: =H8+1 -> 3 | I9: =I$2+H9/(I$4-1)*(I$3-I$2) -> 0.3272169 | J9: =COUNTIF(echantillon,"<="&I9)/COUNT(echantillon) -> 0.104 | K9: =J9-J8 -> 0.046
A10: ='uniforme cercle (rejet)'!L16 -> 7 | B10: ='uniforme cercle (rejet)'!M16 -> 0.32873346 | C10: ='uniforme cercle (rejet)'!N16 -> 0.69839745 | D10: ='uniforme cercle (rejet)'!O16 -> 0.77189681 | H10: =H9+1 -> 4 | I10: =I$2+H10/(I$4-1)*(I$3-I$2) -> 0.42331338 | J10: =COUNTIF(echantillon,"<="&I10)/COUNT(echantillon) -> 0.166 | K10: =J10-J9 -> 0.062
A11: ='uniforme cercle (rejet)'!L17 -> 8 | B11: ='uniforme cercle (rejet)'!M17 -> -0.85827678 | C11: ='uniforme cercle (rejet)'!N17 -> 0.085271867 | D11: ='uniforme cercle (rejet)'!O17 -> 0.86250237 | H11: =H10+1 -> 5 | I11: =I$2+H11/(I$4-1)*(I$3-I$2) -> 0.51940985 | J11: =COUNTIF(echantillon,"<="&I11)/COUNT(echantillon) -> 0.282 | K11: =J11-J10 -> 0.116
A12: ='uniforme cercle (rejet)'!L18 -> 9 | B12: ='uniforme cercle (rejet)'!M18 -> 0.18970218 | C12: ='uniforme cercle (rejet)'!N18 -> -0.64992696 | D12: ='uniforme cercle (rejet)'!O18 -> 0.67704651 | H12: =H11+1 -> 6 | I12: =I$2+H12/(I$4-1)*(I$3-I$2) -> 0.61550633 | J12: =COUNTIF(echantillon,"<="&I12)/COUNT(echantillon) -> 0.39 | K12: =J12-J11 -> 0.108
A13: ='uniforme cercle (rejet)'!L19 -> 10 | B13: ='uniforme cercle (rejet)'!M19 -> 0.36918323 | C13: ='uniforme cercle (rejet)'!N19 -> 0.39114529 | D13: ='uniforme cercle (rejet)'!O19 -> 0.53785769 | H13: =H12+1 -> 7 | I13: =I$2+H13/(I$4-1)*(I$3-I$2) -> 0.71160281 | J13: =COUNTIF(echantillon,"<="&I13)/COUNT(echantillon) -> 0.526 | K13: =J13-J12 -> 0.136
A14: ='uniforme cercle (rejet)'!L20 -> 11 | B14: ='uniforme cercle (rejet)'!M20 -> -0.24941142 | C14: ='uniforme cercle (rejet)'!N20 -> 0.093479787 | D14: ='uniforme cercle (rejet)'!O20 -> 0.26635413 | H14: =H13+1 -> 8 | I14: =I$2+H14/(I$4-1)*(I$3-I$2) -> 0.80769928 | J14: =COUNTIF(echantillon,"<="&I14)/COUNT(echantillon) -> 0.668 | K14: =J14-J13 -> 0.142
A15: ='uniforme cercle (rejet)'!L21 -> 12 | B15: ='uniforme cercle (rejet)'!M21 -> -0.82542412 | C15: ='uniforme cercle (rejet)'!N21 -> -0.19855571 | D15: ='uniforme cercle (rejet)'!O21 -> 0.84896958 | H15: =H14+1 -> 9 | I15: =I$2+H15/(I$4-1)*(I$3-I$2) -> 0.90379576 | J15: =COUNTIF(echantillon,"<="&I15)/COUNT(echantillon) -> 0.838 | K15: =J15-J14 -> 0.17
A16: ='uniforme cercle (rejet)'!L22 -> 13 | B16: ='uniforme cercle (rejet)'!M22 -> -0.43889577 | C16: ='uniforme cercle (rejet)'!N22 -> -0.78678866 | D16: ='uniforme cercle (rejet)'!O22 -> 0.90092502 | H16: =H15+1 -> 10 | I16: =I$2+H16/(I$4-1)*(I$3-I$2) -> 0.99989223 | J16: =COUNTIF(echantillon,"<="&I16)/COUNT(echantillon) -> 1 | K16: =J16-J15 -> 0.162
A17: ='uniforme cercle (rejet)'!L23 -> 14 | B17: ='uniforme cercle (rejet)'!M23 -> -0.20649895 | C17: ='uniforme cercle (rejet)'!N23 -> -0.52500989 | D17: ='uniforme cercle (rejet)'!O23 -> 0.56416061
A18: ='uniforme cercle (rejet)'!L24 -> 15 | B18: ='uniforme cercle (rejet)'!M24 -> 0.60121368 | C18: ='uniforme cercle (rejet)'!N24 -> -0.22377018 | D18: ='uniforme cercle (rejet)'!O24 -> 0.64150681
A19: ='uniforme cercle (rejet)'!L25 -> 16 | B19: ='uniforme cercle (rejet)'!M25 -> -0.52779177 | C19: ='uniforme cercle (rejet)'!N25 -> -0.74703793 | D19: ='uniforme cercle (rejet)'!O25 -> 0.91467471
A20: ='uniforme cercle (rejet)'!L26 -> 17 | B20: ='uniforme cercle (rejet)'!M26 -> -0.53094322 | C20: ='uniforme cercle (rejet)'!N26 -> 0.321073 | D20: ='uniforme cercle (rejet)'!O26 -> 0.62047447
A21: ='uniforme cercle (rejet)'!L27 -> 18 | B21: ='uniforme cercle (rejet)'!M27 -> 0.26307231 | C21: ='uniforme cercle (rejet)'!N27 -> -0.46918678 | D21: ='uniforme cercle (rejet)'!O27 -> 0.53790638
A22: ='uniforme cercle (rejet)'!L28 -> 19 | B22: ='uniforme cercle (rejet)'!M28 -> -0.24040914 | C22: ='uniforme cercle (rejet)'!N28 -> 0.52205308 | D22: ='uniforme cercle (rejet)'!O28 -> 0.57474862
A23: ='uniforme cercle (rejet)'!L29 -> 20 | B23: ='uniforme cercle (rejet)'!M29 -> -0.2089783 | C23: ='uniforme cercle (rejet)'!N29 -> -0.82735009 | D23: ='uniforme cercle (rejet)'!O29 -> 0.8533347
A24: ='uniforme cercle (rejet)'!L30 -> 21 | B24: ='uniforme cercle (rejet)'!M30 -> -0.67354793 | C24: ='uniforme cercle (rejet)'!N30 -> -0.091083328 | D24: ='uniforme cercle (rejet)'!O30 -> 0.67967859
A25: ='uniforme cercle (rejet)'!L31 -> 22 | B25: ='uniforme cercle (rejet)'!M31 -> 0.57326339 | C25: ='uniforme cercle (rejet)'!N31 -> -0.7997754 | D25: ='uniforme cercle (rejet)'!O31 -> 0.98400794
A26: ='uniforme cercle (rejet)'!L32 -> 23 | B26: ='uniforme cercle (rejet)'!M32 -> 0.69896942 | C26: ='uniforme cercle (rejet)'!N32 -> 0.62631343 | D26: ='uniforme cercle (rejet)'!O32 -> 0.93852371
A27: ='uniforme cercle (rejet)'!L33 -> 24 | B27: ='uniforme cercle (rejet)'!M33 -> 0.28059709 | C27: ='uniforme cercle (rejet)'!N33 -> -0.91679788 | D27: ='uniforme cercle (rejet)'!O33 -> 0.95877687
A28: ='uniforme cercle (rejet)'!L34 -> 25 | B28: ='uniforme cercle (rejet)'!M34 -> 0.30564664 | C28: ='uniforme cercle (rejet)'!N34 -> 0.44065838 | D28: ='uniforme cercle (rejet)'!O34 -> 0.5362832
... A503: ='uniforme cercle (rejet)'!L509 -> 500 | B503: ='uniforme cercle (rejet)'!M509 -> -0.60522426 | C503: ='uniforme cercle (rejet)'!N509 -> 0.21031972 | D503: ='uniforme cercle (rejet)'!O509 -> 0.64072676

Sheet Prob zone rouge
A1: On peut ensuite calculer quel proportion de l'aire d'un cercle tombe dans une région particulière (exemple zone rouge)
A2: Proportion des points dans la zone rouge | G2: =AVERAGE(G5:G504) -> 0.198 | H2: +/- | I2: =_xlfn.NORM.INV(0.95,0,1)*STDEV(G5:G504)/SQRT(500) -> 0.029342476
A4: index | B4: Z1 | C4: Z2 | D4: Distance de zéro | E4: Dist du plan | F4: Distance du point | G4: Point dans zone | H4: Z1 dans zone | I4: Z2 dans zone
A5: ='uniforme cercle (rejet)'!L10 -> 1 | B5: ='uniforme cercle (rejet)'!M10 -> -0.37065883 | C5: ='uniforme cercle (rejet)'!N10 -> -0.37285529 | D5: ='uniforme cercle (rejet)'!O10 -> 0.52574617 | E5: =(B5+C5)^2/SQRT(2*(B5+C5)^2) -> 0.52574388 | F5: =SQRT((B5-0.5)^2+(C5-0.5)^2) -> 1.2328516 | G5: =IF(ABS(F5-E5)<SQRT(2)/2/2,1,0) -> 0 | H5: =IF($G5=1,B5,NA()) -> #N/A | I5: =IF($G5=1,C5,NA()) -> #N/A
A6: ='uniforme cercle (rejet)'!L11 -> 2 | B6: ='uniforme cercle (rejet)'!M11 -> -0.090019855 | C6: ='uniforme cercle (rejet)'!N11 -> -0.9067269 | D6: ='uniforme cercle (rejet)'!O11 -> 0.91118453 | E6: =(B6+C6)^2/SQRT(2*(B6+C6)^2) -> 0.70480639 | F6: =SQRT((B6-0.5)^2+(C6-0.5)^2) -> 1.5254521 | G6: =IF(ABS(F6-E6)<SQRT(2)/2/2,1,0) -> 0 | H6: =IF($G6=1,B6,NA()) -> #N/A | I6: =IF($G6=1,C6,NA()) -> #N/A
A7: ='uniforme cercle (rejet)'!L12 -> 3 | B7: ='uniforme cercle (rejet)'!M12 -> -0.2489995 | C7: ='uniforme cercle (rejet)'!N12 -> 0.66272336 | D7: ='uniforme cercle (rejet)'!O12 -> 0.70795693 | E7: =(B7+C7)^2/SQRT(2*(B7+C7)^2) -> 0.29254695 | F7: =SQRT((B7-0.5)^2+(C7-0.5)^2) -> 0.76647188 | G7: =IF(ABS(F7-E7)<SQRT(2)/2/2,1,0) -> 0 | H7: =IF($G7=1,B7,NA()) -> #N/A | I7: =IF($G7=1,C7,NA()) -> #N/A
A8: ='uniforme cercle (rejet)'!L13 -> 4 | B8: ='uniforme cercle (rejet)'!M13 -> 0.068244953 | C8: ='uniforme cercle (rejet)'!N13 -> 0.15403685 | D8: ='uniforme cercle (rejet)'!O13 -> 0.16847767 | E8: =(B8+C8)^2/SQRT(2*(B8+C8)^2) -> 0.15717697 | F8: =SQRT((B8-0.5)^2+(C8-0.5)^2) -> 0.55326569 | G8: =IF(ABS(F8-E8)<SQRT(2)/2/2,1,0) -> 0 | H8: =IF($G8=1,B8,NA()) -> #N/A | I8: =IF($G8=1,C8,NA()) -> #N/A
A9: ='uniforme cercle (rejet)'!L14 -> 5 | B9: ='uniforme cercle (rejet)'!M14 -> 0.22665299 | C9: ='uniforme cercle (rejet)'!N14 -> 0.44924293 | D9: ='uniforme cercle (rejet)'!O14 -> 0.50318067 | E9: =(B9+C9)^2/SQRT(2*(B9+C9)^2) -> 0.47793059 | F9: =SQRT((B9-0.5)^2+(C9-0.5)^2) -> 0.27801954 | G9: =IF(ABS(F9-E9)<SQRT(2)/2/2,1,0) -> 1 | H9: =IF($G9=1,B9,NA()) -> 0.22665299 | I9: =IF($G9=1,C9,NA()) -> 0.44924293
A10: ='uniforme cercle (rejet)'!L15 -> 6 | B10: ='uniforme cercle (rejet)'!M15 -> 0.28192509 | C10: ='uniforme cercle (rejet)'!N15 -> -0.74365115 | D10: ='uniforme cercle (rejet)'!O15 -> 0.79529793 | E10: =(B10+C10)^2/SQRT(2*(B10+C10)^2) -> 0.32648963 | F10: =SQRT((B10-0.5)^2+(C10-0.5)^2) -> 1.2626262 | G10: =IF(ABS(F10-E10)<SQRT(2)/2/2,1,0) -> 0 | H10: =IF($G10=1,B10,NA()) -> #N/A | I10: =IF($G10=1,C10,NA()) -> #N/A
A11: ='uniforme cercle (rejet)'!L16 -> 7 | B11: ='uniforme cercle (rejet)'!M16 -> 0.32873346 | C11: ='uniforme cercle (rejet)'!N16 -> 0.69839745 | D11: ='uniforme cercle (rejet)'!O16 -> 0.77189681 | E11: =(B11+C11)^2/SQRT(2*(B11+C11)^2) -> 0.72629123 | F11: =SQRT((B11-0.5)^2+(C11-0.5)^2) -> 0.26209497 | G11: =IF(ABS(F11-E11)<SQRT(2)/2/2,1,0) -> 0 | H11: =IF($G11=1,B11,NA()) -> #N/A | I11: =IF($G11=1,C11,NA()) -> #N/A
A12: ='uniforme cercle (rejet)'!L17 -> 8 | B12: ='uniforme cercle (rejet)'!M17 -> -0.85827678 | C12: ='uniforme cercle (rejet)'!N17 -> 0.085271867 | D12: ='uniforme cercle (rejet)'!O17 -> 0.86250237 | E12: =(B12+C12)^2/SQRT(2*(B12+C12)^2) -> 0.54659702 | F12: =SQRT((B12-0.5)^2+(C12-0.5)^2) -> 1.4201814 | G12: =IF(ABS(F12-E12)<SQRT(2)/2/2,1,0) -> 0 | H12: =IF($G12=1,B12,NA()) -> #N/A | I12: =IF($G12=1,C12,NA()) -> #N/A
A13: ='uniforme cercle (rejet)'!L18 -> 9 | B13: ='uniforme cercle (rejet)'!M18 -> 0.18970218 | C13: ='uniforme cercle (rejet)'!N18 -> -0.64992696 | D13: ='uniforme cercle (rejet)'!O18 -> 0.67704651 | E13: =(B13+C13)^2/SQRT(2*(B13+C13)^2) -> 0.32542807 | F13: =SQRT((B13-0.5)^2+(C13-0.5)^2) -> 1.191057 | G13: =IF(ABS(F13-E13)<SQRT(2)/2/2,1,0) -> 0 | H13: =IF($G13=1,B13,NA()) -> #N/A | I13: =IF($G13=1,C13,NA()) -> #N/A
A14: ='uniforme cercle (rejet)'!L19 -> 10 | B14: ='uniforme cercle (rejet)'!M19 -> 0.36918323 | C14: ='uniforme cercle (rejet)'!N19 -> 0.39114529 | D14: ='uniforme cercle (rejet)'!O19 -> 0.53785769 | E14: =(B14+C14)^2/SQRT(2*(B14+C14)^2) -> 0.53763345 | F14: =SQRT((B14-0.5)^2+(C14-0.5)^2) -> 0.17018336 | G14: =IF(ABS(F14-E14)<SQRT(2)/2/2,1,0) -> 0 | H14: =IF($G14=1,B14,NA()) -> #N/A | I14: =IF($G14=1,C14,NA()) -> #N/A
A15: ='uniforme cercle (rejet)'!L20 -> 11 | B15: ='uniforme cercle (rejet)'!M20 -> -0.24941142 | C15: ='uniforme cercle (rejet)'!N20 -> 0.093479787 | D15: ='uniforme cercle (rejet)'!O20 -> 0.26635413 | E15: =(B15+C15)^2/SQRT(2*(B15+C15)^2) -> 0.11026031 | F15: =SQRT((B15-0.5)^2+(C15-0.5)^2) -> 0.85257032 | G15: =IF(ABS(F15-E15)<SQRT(2)/2/2,1,0) -> 0 | H15: =IF($G15=1,B15,NA()) -> #N/A | I15: =IF($G15=1,C15,NA()) -> #N/A
A16: ='uniforme cercle (rejet)'!L21 -> 12 | B16: ='uniforme cercle (rejet)'!M21 -> -0.82542412 | C16: ='uniforme cercle (rejet)'!N21 -> -0.19855571 | D16: ='uniforme cercle (rejet)'!O21 -> 0.84896958 | E16: =(B16+C16)^2/SQRT(2*(B16+C16)^2) -> 0.72406308 | F16: =SQRT((B16-0.5)^2+(C16-0.5)^2) -> 1.498242 | G16: =IF(ABS(F16-E16)<SQRT(2)/2/2,1,0) -> 0 | H16: =IF($G16=1,B16,NA()) -> #N/A | I16: =IF($G16=1,C16,NA()) -> #N/A
... A504: ='uniforme cercle (rejet)'!L509 -> 500 | B504: ='uniforme cercle (rejet)'!M509 -> -0.60522426 | C504: ='uniforme cercle (rejet)'!N509 -> 0.21031972 | D504: ='uniforme cercle (rejet)'!O509 -> 0.64072676 | E504: =(B504+C504)^2/SQRT(2*(B504+C504)^2) -> 0.27923968 | F504: =SQRT((B504-0.5)^2+(C504-0.5)^2) -> 1.1425565 | G504: =IF(ABS(F504-E504)<SQRT(2)/2/2,1,0) -> 0 | H504: =IF($G504=1,B504,NA()) -> #N/A | I504: =IF($G504=1,C504,NA()) -> #N/A

Sheet    

Sheet non-uniforme cercle (attention)
V1: On peut ensuite calculer quel proportion de l'aire d'un cercle tombe dans une région particulière (exemple zone rouge)
A2: Il n'est pas suffisant de généré une longueur de rayon et un angle uniformément et indépendamment | V2: Proportion des points dans la zone rouge | AB2: =AVERAGE(AB6:AB505) -> 0.22 | AC2: +/- | AD2: =_xlfn.NORM.INV(0.95,0,1)*STDEV(AB6:AB505)/SQRT(500) -> 0.030502513
A4: Échantillons | V4: index | W4: Z1 | X4: Z2 | Y4: Distance de zéro | Z4: Dist du plan | AA4: Distance du point | AB4: Point dans zone | AC4: Z1 dans zone | AD4: Z2 dans zone
A5: index | B5: rayon | C5: angle | D5: Z1 | E5: Z2
A6: 1 | B6: =RAND() -> 0.62505179 | C6: =RAND()*2*PI() -> 1.4970219 | D6: =B6*COS(C6) -> 0.046071018 | E6: =B6*SIN(C6) -> 0.62335159 | V6: 1 | W6: =D6 -> 0.046071018 | X6: =E6 -> 0.62335159 | Y6: ='uniforme cercle (rejet)'!AJ10 -> 0 | Z6: =(W6+X6)^2/SQRT(2*(W6+X6)^2) -> 0.47335327 | AA6: =SQRT((W6-0.5)^2+(X6-0.5)^2) -> 0.47039041 | AB6: =IF(ABS(AA6-Z6)<SQRT(2)/2/2,1,0) -> 1 | AC6: =IF($AB6=1,W6,NA()) -> 0.046071018 | AD6: =IF($AB6=1,X6,NA()) -> 0.62335159
A7: =1+A6 -> 2 | B7: =RAND() -> 0.6100418 | C7: =RAND()*2*PI() -> 0.97793256 | D7: =B7*COS(C7) -> 0.34085375 | E7: =B7*SIN(C7) -> 0.5059345 | V7: 2 | W7: =D7 -> 0.34085375 | X7: =E7 -> 0.5059345 | Y7: ='uniforme cercle (rejet)'!AJ11 -> 0 | Z7: =(W7+X7)^2/SQRT(2*(W7+X7)^2) -> 0.59876972 | AA7: =SQRT((W7-0.5)^2+(X7-0.5)^2) -> 0.15925685 | AB7: =IF(ABS(AA7-Z7)<SQRT(2)/2/2,1,0) -> 0 | AC7: =IF($AB7=1,W7,NA()) -> #N/A | AD7: =IF($AB7=1,X7,NA()) -> #N/A
A8: =1+A7 -> 3 | B8: =RAND() -> 0.34166623 | C8: =RAND()*2*PI() -> 3.4429051 | D8: =B8*COS(C8) -> -0.32627342 | E8: =B8*SIN(C8) -> -0.10139757 | V8: 3 | W8: =D8 -> -0.32627342 | X8: =E8 -> -0.10139757 | Y8: ='uniforme cercle (rejet)'!AJ12 -> 0 | Z8: =(W8+X8)^2/SQRT(2*(W8+X8)^2) -> 0.30240906 | AA8: =SQRT((W8-0.5)^2+(X8-0.5)^2) -> 1.0219622 | AB8: =IF(ABS(AA8-Z8)<SQRT(2)/2/2,1,0) -> 0 | AC8: =IF($AB8=1,W8,NA()) -> #N/A | AD8: =IF($AB8=1,X8,NA()) -> #N/A
A9: =1+A8 -> 4 | B9: =RAND() -> 0.50095841 | C9: =RAND()*2*PI() -> 5.8886559 | D9: =B9*COS(C9) -> 0.46247356 | E9: =B9*SIN(C9) -> -0.19255529 | V9: 4 | W9: =D9 -> 0.46247356 | X9: =E9 -> -0.19255529 | Y9: ='uniforme cercle (rejet)'!AJ13 -> 0 | Z9: =(W9+X9)^2/SQRT(2*(W9+X9)^2) -> 0.19086103 | AA9: =SQRT((W9-0.5)^2+(X9-0.5)^2) -> 0.69357124 | AB9: =IF(ABS(AA9-Z9)<SQRT(2)/2/2,1,0) -> 0 | AC9: =IF($AB9=1,W9,NA()) -> #N/A | AD9: =IF($AB9=1,X9,NA()) -> #N/A
A10: =1+A9 -> 5 | B10: =RAND() -> 0.28993059 | C10: =RAND()*2*PI() -> 3.9602143 | D10: =B10*COS(C10) -> -0.19808878 | E10: =B10*SIN(C10) -> -0.21170871 | V10: 5 | W10: =D10 -> -0.19808878 | X10: =E10 -> -0.21170871 | Y10: ='uniforme cercle (rejet)'!AJ14 -> 0 | Z10: =(W10+X10)^2/SQRT(2*(W10+X10)^2) -> 0.28977059 | AA10: =SQRT((W10-0.5)^2+(X10-0.5)^2) -> 0.99692389 | AB10: =IF(ABS(AA10-Z10)<SQRT(2)/2/2,1,0) -> 0 | AC10: =IF($AB10=1,W10,NA()) -> #N/A | AD10: =IF($AB10=1,X10,NA()) -> #N/A
A11: =1+A10 -> 6 | B11: =RAND() -> 0.64619823 | C11: =RAND()*2*PI() -> 6.2257017 | D11: =B11*COS(C11) -> 0.64513088 | E11: =B11*SIN(C11) -> -0.037125379 | V11: 6 | W11: =D11 -> 0.64513088 | X11: =E11 -> -0.037125379 | Y11: ='uniforme cercle (rejet)'!AJ15 -> 0 | Z11: =(W11+X11)^2/SQRT(2*(W11+X11)^2) -> 0.42992481 | AA11: =SQRT((W11-0.5)^2+(X11-0.5)^2) -> 0.55638714 | AB11: =IF(ABS(AA11-Z11)<SQRT(2)/2/2,1,0) -> 1 | AC11: =IF($AB11=1,W11,NA()) -> 0.64513088 | AD11: =IF($AB11=1,X11,NA()) -> -0.037125379
A12: =1+A11 -> 7 | B12: =RAND() -> 0.055221301 | C12: =RAND()*2*PI() -> 1.3222243 | D12: =B12*COS(C12) -> 0.013585549 | E12: =B12*SIN(C12) -> 0.05352406 | V12: 7 | W12: =D12 -> 0.013585549 | X12: =E12 -> 0.05352406 | Y12: ='uniforme cercle (rejet)'!AJ16 -> 0 | Z12: =(W12+X12)^2/SQRT(2*(W12+X12)^2) -> 0.047453659 | AA12: =SQRT((W12-0.5)^2+(X12-0.5)^2) -> 0.66025736 | AB12: =IF(ABS(AA12-Z12)<SQRT(2)/2/2,1,0) -> 0 | AC12: =IF($AB12=1,W12,NA()) -> #N/A | AD12: =IF($AB12=1,X12,NA()) -> #N/A
A13: =1+A12 -> 8 | B13: =RAND() -> 0.27683319 | C13: =RAND()*2*PI() -> 0.91275911 | D13: =B13*COS(C13) -> 0.16930151 | E13: =B13*SIN(C13) -> 0.21902879 | V13: 8 | W13: =D13 -> 0.16930151 | X13: =E13 -> 0.21902879 | Y13: ='uniforme cercle (rejet)'!AJ17 -> 0 | Z13: =(W13+X13)^2/SQRT(2*(W13+X13)^2) -> 0.27459099 | AA13: =SQRT((W13-0.5)^2+(X13-0.5)^2) -> 0.43394275 | AB13: =IF(ABS(AA13-Z13)<SQRT(2)/2/2,1,0) -> 1 | AC13: =IF($AB13=1,W13,NA()) -> 0.16930151 | AD13: =IF($AB13=1,X13,NA()) -> 0.21902879
A14: =1+A13 -> 9 | B14: =RAND() -> 0.70460721 | C14: =RAND()*2*PI() -> 4.6168915 | D14: =B14*COS(C14) -> -0.067185973 | E14: =B14*SIN(C14) -> -0.70139672 | V14: 9 | W14: =D14 -> -0.067185973 | X14: =E14 -> -0.70139672 | Y14: ='uniforme cercle (rejet)'!AJ18 -> 0 | Z14: =(W14+X14)^2/SQRT(2*(W14+X14)^2) -> 0.54347004 | AA14: =SQRT((W14-0.5)^2+(X14-0.5)^2) -> 1.3285534 | AB14: =IF(ABS(AA14-Z14)<SQRT(2)/2/2,1,0) -> 0 | AC14: =IF($AB14=1,W14,NA()) -> #N/A | AD14: =IF($AB14=1,X14,NA()) -> #N/A
A15: =1+A14 -> 10 | B15: =RAND() -> 0.48700706 | C15: =RAND()*2*PI() -> 4.9632193 | D15: =B15*COS(C15) -> 0.12087923 | E15: =B15*SIN(C15) -> -0.47176699 | V15: 10 | W15: =D15 -> 0.12087923 | X15: =E15 -> -0.47176699 | Y15: ='uniforme cercle (rejet)'!AJ19 -> 0 | Z15: =(W15+X15)^2/SQRT(2*(W15+X15)^2) -> 0.24811511 | AA15: =SQRT((W15-0.5)^2+(X15-0.5)^2) -> 1.0431029 | AB15: =IF(ABS(AA15-Z15)<SQRT(2)/2/2,1,0) -> 0 | AC15: =IF($AB15=1,W15,NA()) -> #N/A | AD15: =IF($AB15=1,X15,NA()) -> #N/A
A16: =1+A15 -> 11 | B16: =RAND() -> 0.63828117 | C16: =RAND()*2*PI() -> 5.436276 | D16: =B16*COS(C16) -> 0.42273489 | E16: =B16*SIN(C16) -> -0.47822386 | V16: 11 | W16: =D16 -> 0.42273489 | X16: =E16 -> -0.47822386 | Y16: ='uniforme cercle (rejet)'!AJ20 -> 0 | Z16: =(W16+X16)^2/SQRT(2*(W16+X16)^2) -> 0.039236628 | AA16: =SQRT((W16-0.5)^2+(X16-0.5)^2) -> 0.98127051 | AB16: =IF(ABS(AA16-Z16)<SQRT(2)/2/2,1,0) -> 0 | AC16: =IF($AB16=1,W16,NA()) -> #N/A | AD16: =IF($AB16=1,X16,NA()) -> #N/A
A17: =1+A16 -> 12 | B17: =RAND() -> 0.57211982 | C17: =RAND()*2*PI() -> 1.3663781 | D17: =B17*COS(C17) -> 0.11613893 | E17: =B17*SIN(C17) -> 0.56020785 | V17: 12 | W17: =D17 -> 0.11613893 | X17: =E17 -> 0.56020785 | Y17: ='uniforme cercle (rejet)'!AJ21 -> 0 | Z17: =(W17+X17)^2/SQRT(2*(W17+X17)^2) -> 0.4782494 | AA17: =SQRT((W17-0.5)^2+(X17-0.5)^2) -> 0.38855412 | AB17: =IF(ABS(AA17-Z17)<SQRT(2)/2/2,1,0) -> 1 | AC17: =IF($AB17=1,W17,NA()) -> 0.11613893 | AD17: =IF($AB17=1,X17,NA()) -> 0.56020785
A18: =1+A17 -> 13 | B18: =RAND() -> 0.035106747 | C18: =RAND()*2*PI() -> 0.16097792 | D18: =B18*COS(C18) -> 0.034652852 | E18: =B18*SIN(C18) -> 0.0056270343 | V18: 13 | W18: =D18 -> 0.034652852 | X18: =E18 -> 0.0056270343 | Y18: ='uniforme cercle (rejet)'!AJ22 -> 0 | Z18: =(W18+X18)^2/SQRT(2*(W18+X18)^2) -> 0.028482181 | AA18: =SQRT((W18-0.5)^2+(X18-0.5)^2) -> 0.6789349 | AB18: =IF(ABS(AA18-Z18)<SQRT(2)/2/2,1,0) -> 0 | AC18: =IF($AB18=1,W18,NA()) -> #N/A | AD18: =IF($AB18=1,X18,NA()) -> #N/A
... A29: =1+A28 -> 24 | B29: =RAND() -> 0.43033495 | C29: =RAND()*2*PI() -> 4.9691218 | D29: =B29*COS(C29) -> 0.10927142 | E29: =B29*SIN(C29) -> -0.41623062 | V29: 24 | W29: =D29 -> 0.10927142 | X29: =E29 -> -0.41623062 | Y29: ='uniforme cercle (rejet)'!AJ33 -> 0 | Z29: =(W29+X29)^2/SQRT(2*(W29+X29)^2) -> 0.21705293 | AA29: =SQRT((W29-0.5)^2+(X29-0.5)^2) -> 0.99606595 | AB29: =IF(ABS(AA29-Z29)<SQRT(2)/2/2,1,0) -> 0 | AC29: =IF($AB29=1,W29,NA()) -> #N/A | AD29: =IF($AB29=1,X29,NA()) -> #N/A
A30: =1+A29 -> 25 | B30: =RAND() -> 0.63232407 | C30: =RAND()*2*PI() -> 1.1796783 | D30: =B30*COS(C30) -> 0.241056 | E30: =B30*SIN(C30) -> 0.58457312 | H30: Fonction de répartition | V30: 25 | W30: =D30 -> 0.241056 | X30: =E30 -> 0.58457312 | Y30: ='uniforme cercle (rejet)'!AJ34 -> 0 | Z30: =(W30+X30)^2/SQRT(2*(W30+X30)^2) -> 0.58380795 | AA30: =SQRT((W30-0.5)^2+(X30-0.5)^2) -> 0.27240523 | AB30: =IF(ABS(AA30-Z30)<SQRT(2)/2/2,1,0) -> 1 | AC30: =IF($AB30=1,W30,NA()) -> 0.241056 | AD30: =IF($AB30=1,X30,NA()) -> 0.58457312
A31: =1+A30 -> 26 | B31: =RAND() -> 0.61858995 | C31: =RAND()*2*PI() -> 4.6495314 | D31: =B31*COS(C31) -> -0.038857473 | E31: =B31*SIN(C31) -> -0.61736831 | H31: Min | I31: 0 | V31: 26 | W31: =D31 -> -0.038857473 | X31: =E31 -> -0.61736831 | Y31: ='uniforme cercle (rejet)'!AJ35 -> 0 | Z31: =(W31+X31)^2/SQRT(2*(W31+X31)^2) -> 0.4640217 | AA31: =SQRT((W31-0.5)^2+(X31-0.5)^2) -> 1.2405157 | AB31: =IF(ABS(AA31-Z31)<SQRT(2)/2/2,1,0) -> 0 | AC31: =IF($AB31=1,W31,NA()) -> #N/A | AD31: =IF($AB31=1,X31,NA()) -> #N/A
A32: =1+A31 -> 27 | B32: =RAND() -> 0.86768171 | C32: =RAND()*2*PI() -> 5.0887685 | D32: =B32*COS(C32) -> 0.31892147 | E32: =B32*SIN(C32) -> -0.80694526 | H32: Max | I32: 1 | V32: 27 | W32: =D32 -> 0.31892147 | X32: =E32 -> -0.80694526 | Y32: ='uniforme cercle (rejet)'!AJ36 -> 0 | Z32: =(W32+X32)^2/SQRT(2*(W32+X32)^2) -> 0.34508493 | AA32: =SQRT((W32-0.5)^2+(X32-0.5)^2) -> 1.3194299 | AB32: =IF(ABS(AA32-Z32)<SQRT(2)/2/2,1,0) -> 0 | AC32: =IF($AB32=1,W32,NA()) -> #N/A | AD32: =IF($AB32=1,X32,NA()) -> #N/A
A33: =1+A32 -> 28 | B33: =RAND() -> 0.62379844 | C33: =RAND()*2*PI() -> 0.161706 | D33: =B33*COS(C33) -> 0.6156604 | E33: =B33*SIN(C33) -> 0.10043291 | H33: Nombre de bins | I33: 11 | V33: 28 | W33: =D33 -> 0.6156604 | X33: =E33 -> 0.10043291 | Y33: ='uniforme cercle (rejet)'!AJ37 -> 0 | Z33: =(W33+X33)^2/SQRT(2*(W33+X33)^2) -> 0.50635444 | AA33: =SQRT((W33-0.5)^2+(X33-0.5)^2) -> 0.41597017 | AB33: =IF(ABS(AA33-Z33)<SQRT(2)/2/2,1,0) -> 1 | AC33: =IF($AB33=1,W33,NA()) -> 0.6156604 | AD33: =IF($AB33=1,X33,NA()) -> 0.10043291
A34: =1+A33 -> 29 | B34: =RAND() -> 0.86113199 | C34: =RAND()*2*PI() -> 5.2659781 | D34: =B34*COS(C34) -> 0.45273468 | E34: =B34*SIN(C34) -> -0.73251595 | H34: Bins | I34: x | J34: P(X<=x) | K34: Histogramme | V34: 29 | W34: =D34 -> 0.45273468 | X34: =E34 -> -0.73251595 | Y34: ='uniforme cercle (rejet)'!AJ38 -> 0 | Z34: =(W34+X34)^2/SQRT(2*(W34+X34)^2) -> 0.19783523 | AA34: =SQRT((W34-0.5)^2+(X34-0.5)^2) -> 1.2334219 | AB34: =IF(ABS(AA34-Z34)<SQRT(2)/2/2,1,0) -> 0 | AC34: =IF($AB34=1,W34,NA()) -> #N/A | AD34: =IF($AB34=1,X34,NA()) -> #N/A
A35: =1+A34 -> 30 | B35: =RAND() -> 0.5080841 | C35: =RAND()*2*PI() -> 2.5486183 | D35: =B35*COS(C35) -> -0.42134511 | E35: =B35*SIN(C35) -> 0.28393265 | H35: 0 | I35: =I$31+H35/(I$33-1)*(I$32-I$31) -> 0 | J35: =COUNTIF(echantillon,"<="&I35)/COUNT(echantillon) -> 0 | K35: =J35-0 -> 0 | V35: 30 | W35: =D35 -> -0.42134511 | X35: =E35 -> 0.28393265 | Y35: ='uniforme cercle (rejet)'!AJ39 -> 0 | Z35: =(W35+X35)^2/SQRT(2*(W35+X35)^2) -> 0.097165278 | AA35: =SQRT((W35-0.5)^2+(X35-0.5)^2) -> 0.94634132 | AB35: =IF(ABS(AA35-Z35)<SQRT(2)/2/2,1,0) -> 0 | AC35: =IF($AB35=1,W35,NA()) -> #N/A | AD35: =IF($AB35=1,X35,NA()) -> #N/A
A36: =1+A35 -> 31 | B36: =RAND() -> 0.0057703909 | C36: =RAND()*2*PI() -> 6.0625426 | D36: =B36*COS(C36) -> 0.0056304993 | E36: =B36*SIN(C36) -> -0.001262889 | H36: =H35+1 -> 1 | I36: =I$31+H36/(I$33-1)*(I$32-I$31) -> 0.1 | J36: =COUNTIF(echantillon,"<="&I36)/COUNT(echantillon) -> 0.074 | K36: =J36-J35 -> 0.074 | V36: 31 | W36: =D36 -> 0.0056304993 | X36: =E36 -> -0.001262889 | Y36: ='uniforme cercle (rejet)'!AJ40 -> 0 | Z36: =(W36+X36)^2/SQRT(2*(W36+X36)^2) -> 0.0030883668 | AA36: =SQRT((W36-0.5)^2+(X36-0.5)^2) -> 0.70403529 | AB36: =IF(ABS(AA36-Z36)<SQRT(2)/2/2,1,0) -> 0 | AC36: =IF($AB36=1,W36,NA()) -> #N/A | AD36: =IF($AB36=1,X36,NA()) -> #N/A
A37: =1+A36 -> 32 | B37: =RAND() -> 0.32268244 | C37: =RAND()*2*PI() -> 5.6724028 | D37: =B37*COS(C37) -> 0.2643413 | E37: =B37*SIN(C37) -> -0.18506116 | H37: =H36+1 -> 2 | I37: =I$31+H37/(I$33-1)*(I$32-I$31) -> 0.2 | J37: =COUNTIF(echantillon,"<="&I37)/COUNT(echantillon) -> 0.168 | K37: =J37-J36 -> 0.094 | V37: 32 | W37: =D37 -> 0.2643413 | X37: =E37 -> -0.18506116 | Y37: ='uniforme cercle (rejet)'!AJ41 -> 0 | Z37: =(W37+X37)^2/SQRT(2*(W37+X37)^2) -> 0.056059521 | AA37: =SQRT((W37-0.5)^2+(X37-0.5)^2) -> 0.72446106 | AB37: =IF(ABS(AA37-Z37)<SQRT(2)/2/2,1,0) -> 0 | AC37: =IF($AB37=1,W37,NA()) -> #N/A | AD37: =IF($AB37=1,X37,NA()) -> #N/A
A38: =1+A37 -> 33 | B38: =RAND() -> 0.78453004 | C38: =RAND()*2*PI() -> 2.0158214 | D38: =B38*COS(C38) -> -0.33772491 | E38: =B38*SIN(C38) -> 0.70811671 | H38: =H37+1 -> 3 | I38: =I$31+H38/(I$33-1)*(I$32-I$31) -> 0.3 | J38: =COUNTIF(echantillon,"<="&I38)/COUNT(echantillon) -> 0.256 | K38: =J38-J37 -> 0.088 | V38: 33 | W38: =D38 -> -0.33772491 | X38: =E38 -> 0.70811671 | Y38: ='uniforme cercle (rejet)'!AJ42 -> 0 | Z38: =(W38+X38)^2/SQRT(2*(W38+X38)^2) -> 0.26190655 | AA38: =SQRT((W38-0.5)^2+(X38-0.5)^2) -> 0.8631892 | AB38: =IF(ABS(AA38-Z38)<SQRT(2)/2/2,1,0) -> 0 | AC38: =IF($AB38=1,W38,NA()) -> #N/A | AD38: =IF($AB38=1,X38,NA()) -> #N/A
A39: =1+A38 -> 34 | B39: =RAND() -> 0.23755413 | C39: =RAND()*2*PI() -> 5.7472736 | D39: =B39*COS(C39) -> 0.20424986 | E39: =B39*SIN(C39) -> -0.12130112 | H39: =H38+1 -> 4 | I39: =I$31+H39/(I$33-1)*(I$32-I$31) -> 0.4 | J39: =COUNTIF(echantillon,"<="&I39)/COUNT(echantillon) -> 0.346 | K39: =J39-J38 -> 0.09 | V39: 34 | W39: =D39 -> 0.20424986 | X39: =E39 -> -0.12130112 | Y39: ='uniforme cercle (rejet)'!AJ43 -> 0 | Z39: =(W39+X39)^2/SQRT(2*(W39+X39)^2) -> 0.058653612 | AA39: =SQRT((W39-0.5)^2+(X39-0.5)^2) -> 0.68810118 | AB39: =IF(ABS(AA39-Z39)<SQRT(2)/2/2,1,0) -> 0 | AC39: =IF($AB39=1,W39,NA()) -> #N/A | AD39: =IF($AB39=1,X39,NA()) -> #N/A
A40: =1+A39 -> 35 | B40: =RAND() -> 0.67928748 | C40: =RAND()*2*PI() -> 5.9812522 | D40: =B40*COS(C40) -> 0.64855885 | E40: =B40*SIN(C40) -> -0.20199728 | H40: =H39+1 -> 5 | I40: =I$31+H40/(I$33-1)*(I$32-I$31) -> 0.5 | J40: =COUNTIF(echantillon,"<="&I40)/COUNT(echantillon) -> 0.47 | K40: =J40-J39 -> 0.124 | V40: 35 | W40: =D40 -> 0.64855885 | X40: =E40 -> -0.20199728 | Y40: ='uniforme cercle (rejet)'!AJ44 -> 0 | Z40: =(W40+X40)^2/SQRT(2*(W40+X40)^2) -> 0.31576672 | AA40: =SQRT((W40-0.5)^2+(X40-0.5)^2) -> 0.71754436 | AB40: =IF(ABS(AA40-Z40)<SQRT(2)/2/2,1,0) -> 0 | AC40: =IF($AB40=1,W40,NA()) -> #N/A | AD40: =IF($AB40=1,X40,NA()) -> #N/A
A41: =1+A40 -> 36 | B41: =RAND() -> 0.80147047 | C41: =RAND()*2*PI() -> 4.0848356 | D41: =B41*COS(C41) -> -0.47059628 | E41: =B41*SIN(C41) -> -0.64876348 | H41: =H40+1 -> 6 | I41: =I$31+H41/(I$33-1)*(I$32-I$31) -> 0.6 | J41: =COUNTIF(echantillon,"<="&I41)/COUNT(echantillon) -> 0.584 | K41: =J41-J40 -> 0.114 | V41: 36 | W41: =D41 -> -0.47059628 | X41: =E41 -> -0.64876348 | Y41: ='uniforme cercle (rejet)'!AJ45 -> 0 | Z41: =(W41+X41)^2/SQRT(2*(W41+X41)^2) -> 0.79150688 | AA41: =SQRT((W41-0.5)^2+(X41-0.5)^2) -> 1.5038998 | AB41: =IF(ABS(AA41-Z41)<SQRT(2)/2/2,1,0) -> 0 | AC41: =IF($AB41=1,W41,NA()) -> #N/A | AD41: =IF($AB41=1,X41,NA()) -> #N/A
A42: =1+A41 -> 37 | B42: =RAND() -> 0.038153376 | C42: =RAND()*2*PI() -> 2.5262526 | D42: =B42*COS(C42) -> -0.031155176 | E42: =B42*SIN(C42) -> 0.022023513 | H42: =H41+1 -> 7 | I42: =I$31+H42/(I$33-1)*(I$32-I$31) -> 0.7 | J42: =COUNTIF(echantillon,"<="&I42)/COUNT(echantillon) -> 0.676 | K42: =J42-J41 -> 0.092 | V42: 37 | W42: =D42 -> -0.031155176 | X42: =E42 -> 0.022023513 | Y42: ='uniforme cercle (rejet)'!AJ46 -> 0 | Z42: =(W42+X42)^2/SQRT(2*(W42+X42)^2) -> 0.0064570612 | AA42: =SQRT((W42-0.5)^2+(X42-0.5)^2) -> 0.71455395 | AB42: =IF(ABS(AA42-Z42)<SQRT(2)/2/2,1,0) -> 0 | AC42: =IF($AB42=1,W42,NA()) -> #N/A | AD42: =IF($AB42=1,X42,NA()) -> #N/A
A43: =1+A42 -> 38 | B43: =RAND() -> 0.090767352 | C43: =RAND()*2*PI() -> 5.3889488 | D43: =B43*COS(C43) -> 0.056830742 | E43: =B43*SIN(C43) -> -0.070774141 | H43: =H42+1 -> 8 | I43: =I$31+H43/(I$33-1)*(I$32-I$31) -> 0.8 | J43: =COUNTIF(echantillon,"<="&I43)/COUNT(echantillon) -> 0.774 | K43: =J43-J42 -> 0.098 | V43: 38 | W43: =D43 -> 0.056830742 | X43: =E43 -> -0.070774141 | Y43: ='uniforme cercle (rejet)'!AJ47 -> 0 | Z43: =(W43+X43)^2/SQRT(2*(W43+X43)^2) -> 0.0098594722 | AA43: =SQRT((W43-0.5)^2+(X43-0.5)^2) -> 0.72262169 | AB43: =IF(ABS(AA43-Z43)<SQRT(2)/2/2,1,0) -> 0 | AC43: =IF($AB43=1,W43,NA()) -> #N/A | AD43: =IF($AB43=1,X43,NA()) -> #N/A
A44: =1+A43 -> 39 | B44: =RAND() -> 0.93168962 | C44: =RAND()*2*PI() -> 0.69839524 | D44: =B44*COS(C44) -> 0.7135578 | E44: =B44*SIN(C44) -> 0.59906661 | H44: =H43+1 -> 9 | I44: =I$31+H44/(I$33-1)*(I$32-I$31) -> 0.9 | J44: =COUNTIF(echantillon,"<="&I44)/COUNT(echantillon) -> 0.898 | K44: =J44-J43 -> 0.124 | V44: 39 | W44: =D44 -> 0.7135578 | X44: =E44 -> 0.59906661 | Y44: ='uniforme cercle (rejet)'!AJ48 -> 0 | Z44: =(W44+X44)^2/SQRT(2*(W44+X44)^2) -> 0.92816562 | AA44: =SQRT((W44-0.5)^2+(X44-0.5)^2) -> 0.23541692 | AB44: =IF(ABS(AA44-Z44)<SQRT(2)/2/2,1,0) -> 0 | AC44: =IF($AB44=1,W44,NA()) -> #N/A | AD44: =IF($AB44=1,X44,NA()) -> #N/A
A45: =1+A44 -> 40 | B45: =RAND() -> 0.9342133 | C45: =RAND()*2*PI() -> 0.32123241 | D45: =B45*COS(C45) -> 0.88642551 | E45: =B45*SIN(C45) -> 0.29496493 | H45: =H44+1 -> 10 | I45: =I$31+H45/(I$33-1)*(I$32-I$31) -> 1 | J45: =COUNTIF(echantillon,"<="&I45)/COUNT(echantillon) -> 1 | K45: =J45-J44 -> 0.102 | V45: 40 | W45: =D45 -> 0.88642551 | X45: =E45 -> 0.29496493 | Y45: ='uniforme cercle (rejet)'!AJ49 -> 0 | Z45: =(W45+X45)^2/SQRT(2*(W45+X45)^2) -> 0.83536919 | AA45: =SQRT((W45-0.5)^2+(X45-0.5)^2) -> 0.43745177 | AB45: =IF(ABS(AA45-Z45)<SQRT(2)/2/2,1,0) -> 0 | AC45: =IF($AB45=1,W45,NA()) -> #N/A | AD45: =IF($AB45=1,X45,NA()) -> #N/A
A46: =1+A45 -> 41 | B46: =RAND() -> 0.51261149 | C46: =RAND()*2*PI() -> 0.37970146 | D46: =B46*COS(C46) -> 0.47610091 | E46: =B46*SIN(C46) -> 0.18999597 | V46: 41 | W46: =D46 -> 0.47610091 | X46: =E46 -> 0.18999597 | Y46: ='uniforme cercle (rejet)'!AJ50 -> 0 | Z46: =(W46+X46)^2/SQRT(2*(W46+X46)^2) -> 0.47100162 | AA46: =SQRT((W46-0.5)^2+(X46-0.5)^2) -> 0.31092389 | AB46: =IF(ABS(AA46-Z46)<SQRT(2)/2/2,1,0) -> 1 | AC46: =IF($AB46=1,W46,NA()) -> 0.47610091 | AD46: =IF($AB46=1,X46,NA()) -> 0.18999597
A47: =1+A46 -> 42 | B47: =RAND() -> 0.50708304 | C47: =RAND()*2*PI() -> 6.142992 | D47: =B47*COS(C47) -> 0.50210804 | E47: =B47*SIN(C47) -> -0.070857018 | V47: 42 | W47: =D47 -> 0.50210804 | X47: =E47 -> -0.070857018 | Y47: ='uniforme cercle (rejet)'!AJ51 -> 0 | Z47: =(W47+X47)^2/SQRT(2*(W47+X47)^2) -> 0.30494053 | AA47: =SQRT((W47-0.5)^2+(X47-0.5)^2) -> 0.57086091 | AB47: =IF(ABS(AA47-Z47)<SQRT(2)/2/2,1,0) -> 1 | AC47: =IF($AB47=1,W47,NA()) -> 0.50210804 | AD47: =IF($AB47=1,X47,NA()) -> -0.070857018
A48: =1+A47 -> 43 | B48: =RAND() -> 0.66731926 | C48: =RAND()*2*PI() -> 3.0161696 | D48: =B48*COS(C48) -> -0.66207736 | E48: =B48*SIN(C48) -> 0.083477958 | V48: 43 | W48: =D48 -> -0.66207736 | X48: =E48 -> 0.083477958 | Y48: ='uniforme cercle (rejet)'!AJ52 -> 0 | Z48: =(W48+X48)^2/SQRT(2*(W48+X48)^2) -> 0.40913156 | AA48: =SQRT((W48-0.5)^2+(X48-0.5)^2) -> 1.2344693 | AB48: =IF(ABS(AA48-Z48)<SQRT(2)/2/2,1,0) -> 0 | AC48: =IF($AB48=1,W48,NA()) -> #N/A | AD48: =IF($AB48=1,X48,NA()) -> #N/A
A49: =1+A48 -> 44 | B49: =RAND() -> 0.83537538 | C49: =RAND()*2*PI() -> 2.611388 | D49: =B49*COS(C49) -> -0.72068136 | E49: =B49*SIN(C49) -> 0.42245758 | V49: 44 | W49: =D49 -> -0.72068136 | X49: =E49 -> 0.42245758 | Y49: ='uniforme cercle (rejet)'!AJ53 -> 0 | Z49: =(W49+X49)^2/SQRT(2*(W49+X49)^2) -> 0.21087606 | AA49: =SQRT((W49-0.5)^2+(X49-0.5)^2) -> 1.2231418 | AB49: =IF(ABS(AA49-Z49)<SQRT(2)/2/2,1,0) -> 0 | AC49: =IF($AB49=1,W49,NA()) -> #N/A | AD49: =IF($AB49=1,X49,NA()) -> #N/A
A50: =1+A49 -> 45 | B50: =RAND() -> 0.42681197 | C50: =RAND()*2*PI() -> 5.9073809 | D50: =B50*COS(C50) -> 0.39702591 | E50: =B50*SIN(C50) -> -0.15664892 | V50: 45 | W50: =D50 -> 0.39702591 | X50: =E50 -> -0.15664892 | Y50: ='uniforme cercle (rejet)'!AJ54 -> 0 | Z50: =(W50+X50)^2/SQRT(2*(W50+X50)^2) -> 0.1699722 | AA50: =SQRT((W50-0.5)^2+(X50-0.5)^2) -> 0.66467395 | AB50: =IF(ABS(AA50-Z50)<SQRT(2)/2/2,1,0) -> 0 | AC50: =IF($AB50=1,W50,NA()) -> #N/A | AD50: =IF($AB50=1,X50,NA()) -> #N/A
A51: =1+A50 -> 46 | B51: =RAND() -> 0.89519903 | C51: =RAND()*2*PI() -> 0.27168571 | D51: =B51*COS(C51) -> 0.86236304 | E51: =B51*SIN(C51) -> 0.24023176 | V51: 46 | W51: =D51 -> 0.86236304 | X51: =E51 -> 0.24023176 | Y51: ='uniforme cercle (rejet)'!AJ55 -> 0 | Z51: =(W51+X51)^2/SQRT(2*(W51+X51)^2) -> 0.77965226 | AA51: =SQRT((W51-0.5)^2+(X51-0.5)^2) -> 0.44585481 | AB51: =IF(ABS(AA51-Z51)<SQRT(2)/2/2,1,0) -> 1 | AC51: =IF($AB51=1,W51,NA()) -> 0.86236304 | AD51: =IF($AB51=1,X51,NA()) -> 0.24023176
...
