Workbook
Name A: 'F. utilite'!$E$3
Name B: 'F. utilite'!$E$4
Name PalisadeReportWorkbookCreatedBy: "PrecisionTree"
Name RT: 'F. utilite'!$E$5

Sheet treeCalc_3
A1: Name | B1: Achat Info (parfaite) | E1: Ptree1 Compatibility | F1: 3 | H1: Output Label | K1: R-Value Ref. | L1: ='F. utilite'!$E$5 -> 1249.8333
A2: SheetRef | B2: ='Valeur Info Parfaite'!#REF! -> #REF! | E2: Eval. Function | F2: =_xll.PTreeEvaluate5(B3,$L$11:$L$23,$J$11:$J$23,$K$11:$K$23,$N$11:$N$23,$G$11:$G$23,,L1) -> 7590165
A3: GenInfo | B3: -1,3,1,-1,-1,Exponential, 0,1,-1,0,-1,-1,.0001 | E3: Creation Version | F3: 5.7.1 | H3: Output Value NF | I3: <NF>
A4: Def. Link | B4: ='Valeur Info Parfaite'!$C$11 -> 100 | E4: Required Version | F4: 5.0.0 | H4: Output Prob NF | I4: Automatic
A5: EXT REFS | B5: 0 | D5: 0 | E5: Recommended Version | F5: 5.0.0 | H5: Input Value NF | I5: <NF>
A6: Def. Form | E6: Last Modified By Version | F6: 8.0.1 | H6: Input Prob NF | I6: Automatic
A7: Calc Macro | F7: 3B76C5F
A8: Highest# | B8: 13
A10: Anchor Cell | B10: Branch Name | C10: bformtype | D10: valformula | E10: pbformula | F10: distribution | G10: cumPayoffFunction | H10: link | I10: ENDNODEFORMULA | J10: VAL | K10: PB | L10: GenInfo | M10: IntRefs | N10: RefRefs | O10: NodeNames | P10: Collapsed
A11: ='Valeur Info Parfaite'!$C$28 -> 0.034832757 | B11: =B1 -> Achat Info (parfaite) | C11: 0 | H11: ='Valeur Info Parfaite'!$C$5 -> 1 | I11: DEFAULT | J11: ='Valeur Info Parfaite'!$B$28 -> 0 | K11: ='Valeur Info Parfaite'!$B$27 -> 0 | L11: 1,0,1,3,2,3,4,0,0,0 | M11: 0 | O11: ='Valeur Info Parfaite'!$C$27 -> Météo | P11: FALSE
A12: ='Valeur Info Parfaite'!$D$22 -> 0.076893502 | B12: Ensoleillé | C12: 0 | H12: ='Valeur Info Parfaite'!$C$4 -> 100 | I12: DEFAULT | J12: ='Valeur Info Parfaite'!$C$22 -> 1 | K12: ='Valeur Info Parfaite'!$C$21 -> 0.3 | L12: 2,0,0,3,5,6,7,1,0,0 | M12: 0 | O12: ='Valeur Info Parfaite'!$D$21 -> Decision | P12: FALSE
A13: ='Valeur Info Parfaite'!$D$32 -> 0.039215686 | B13: Nuageux | C13: 0 | H13: ='Valeur Info Parfaite'!$C$4 -> 100 | I13: DEFAULT | J13: ='Valeur Info Parfaite'!$C$32 -> 2 | K13: ='Valeur Info Parfaite'!$C$31 -> 0.3 | L13: 2,0,0,3,8,9,10,1,0,0 | M13: 0 | O13: ='Valeur Info Parfaite'!$D$31 -> Decision | P13: FALSE
A14: ='Valeur Info Parfaite'!$D$40 -> 0 | B14: Averse | C14: 0 | H14: ='Valeur Info Parfaite'!$C$4 -> 100 | I14: DEFAULT | J14: ='Valeur Info Parfaite'!$C$40 -> 3 | K14: ='Valeur Info Parfaite'!$C$39 -> 0.4 | L14: 2,0,0,3,11,12,13,1,0,0 | M14: 0 | O14: ='Valeur Info Parfaite'!$D$39 -> Decision | P14: FALSE
A15: ='Valeur Info Parfaite'!$E$20 -> 0 | B15: 0 litre | C15: 0 | H15: DEFAULT | I15: DEFAULT | J15: ='Valeur Info Parfaite'!$D$20 -> 0 | L15: 4,0,0,0,2,0,0 | M15: 0 | P15: FALSE
A16: ='Valeur Info Parfaite'!$E$24 -> 0.039215686 | B16: 50 litres | C16: 0 | H16: DEFAULT | I16: DEFAULT | J16: ='Valeur Info Parfaite'!$D$24 -> 50 | L16: 4,0,0,0,2,0,0 | M16: 0 | P16: FALSE
A17: ='Valeur Info Parfaite'!$E$26 -> 0.076893502 | B17: 100 litres | C17: 0 | H17: DEFAULT | I17: DEFAULT | J17: ='Valeur Info Parfaite'!$D$26 -> 100 | L17: 4,0,0,0,2,0,0 | M17: 0 | P17: FALSE
A18: ='Valeur Info Parfaite'!$E$30 -> 0 | B18: 0 litre | C18: 0 | H18: DEFAULT | I18: DEFAULT | J18: ='Valeur Info Parfaite'!$D$30 -> 0 | L18: 4,0,0,0,3,0,0 | M18: 0 | P18: FALSE
A19: ='Valeur Info Parfaite'!$E$34 -> 0.039215686 | B19: 50 litres | C19: 0 | H19: DEFAULT | I19: DEFAULT | J19: ='Valeur Info Parfaite'!$D$34 -> 50 | L19: 4,0,0,0,3,0,0 | M19: 0 | P19: FALSE
A20: ='Valeur Info Parfaite'!$E$36 -> 0 | B20: 100 litres | C20: 0 | H20: DEFAULT | I20: DEFAULT | J20: ='Valeur Info Parfaite'!$D$36 -> 100 | L20: 4,0,0,0,3,0,0 | M20: 0 | P20: FALSE
A21: ='Valeur Info Parfaite'!$E$38 -> 0 | B21: 0 litre | C21: 0 | H21: DEFAULT | I21: DEFAULT | J21: ='Valeur Info Parfaite'!$D$38 -> 0 | L21: 4,0,0,0,4,0,0 | M21: 0 | P21: FALSE
A22: ='Valeur Info Parfaite'!$E$42 -> -0.040816327 | B22: 50 litres | C22: 0 | H22: DEFAULT | I22: DEFAULT | J22: ='Valeur Info Parfaite'!$D$42 -> 50 | L22: 4,0,0,0,4,0,0 | M22: 0 | P22: FALSE
A23: ='Valeur Info Parfaite'!$E$44 -> -0.083298626 | B23: 100 litres | C23: 0 | H23: DEFAULT | I23: DEFAULT | J23: ='Valeur Info Parfaite'!$D$44 -> 100 | L23: 4,0,0,0,4,0,0 | M23: 0 | P23: FALSE

Sheet treeCalc_4
A1: Name | B1: Achat Info (imparfaite) | E1: Ptree1 Compatibility | F1: 3 | H1: Output Label | K1: R-Value Ref. | L1: ='F. utilite'!$E$5 -> 1249.8333
A2: SheetRef | B2: ='Valeur Info Imparfaite'!#REF! -> #REF! | E2: Eval. Function | F2: =_xll.PTreeEvaluate5(B3,$L$11:$L$37,$J$11:$J$37,$K$11:$K$37,$N$11:$N$37,$G$11:$G$37,,L1) -> 7641622
A3: GenInfo | B3: -1,4,1,-1,-1,Exponential, 0,1,-1,0,-1,-1,.0001 | E3: Creation Version | F3: 5.7.1 | H3: Output Value NF | I3: <NF>
A4: Def. Link | B4: ='Valeur Info Imparfaite'!$C$11 -> 100 | E4: Required Version | F4: 5.0.0 | H4: Output Prob NF | I4: Automatic
A5: EXT REFS | B5: 0 | D5: 0 | E5: Recommended Version | F5: 5.0.0 | H5: Input Value NF | I5: <NF>
A6: Def. Form | E6: Last Modified By Version | F6: 8.0.1 | H6: Input Prob NF | I6: Automatic
A7: Calc Macro | F7: C562C5
A8: Highest# | B8: 27
A10: Anchor Cell | B10: Branch Name | C10: bformtype | D10: valformula | E10: pbformula | F10: distribution | G10: cumPayoffFunction | H10: link | I10: ENDNODEFORMULA | J10: VAL | K10: PB | L10: GenInfo | M10: IntRefs | N10: RefRefs | O10: NodeNames | P10: Collapsed
A11: ='Valeur Info Imparfaite'!$C$47 -> 0.023068051 | B11: =B1 -> Achat Info (imparfaite) | C11: 0 | I11: DEFAULT | J11: ='Valeur Info Imparfaite'!$B$47 -> 0 | K11: ='Valeur Info Imparfaite'!$B$46 -> 0 | L11: 1,0,1,2,2,3,0,0,0 | M11: 0 | O11: ='Valeur Info Imparfaite'!$C$46 -> Prévision météo. | P11: FALSE
A12: ='Valeur Info Imparfaite'!$D$29 -> 0 | B12: Temp. non-clémente | C12: 0 | H12: ='Valeur Info Imparfaite'!$C$4 -> 100 | I12: DEFAULT | J12: ='Valeur Info Imparfaite'!$C$29 -> 0 | K12: ='Valeur Info Imparfaite'!$C$28 -> 0.55 | L12: 2,0,0,3,5,6,7,1,0,0 | M12: 0 | O12: ='Valeur Info Imparfaite'!$D$28 -> Decision | P12: FALSE
A13: ='Valeur Info Imparfaite'!$D$57 -> 0.051262335 | B13: Temp. clémente | C13: 0 | H13: ='Valeur Info Imparfaite'!$C$4 -> 100 | I13: DEFAULT | J13: ='Valeur Info Imparfaite'!$C$57 -> 1 | K13: ='Valeur Info Imparfaite'!$C$56 -> 0.45 | L13: 2,0,0,3,8,9,10,1,0,0 | M13: 0 | O13: ='Valeur Info Imparfaite'!$D$56 -> Decision | P13: FALSE
A14: ='Valeur Info Imparfaite'!$F$21 -> 0 | B14: Ensoleillé | C14: 0 | H14: DEFAULT | I14: DEFAULT | J14: ='Valeur Info Imparfaite'!$E$21 -> 1 | K14: ='Valeur Info Imparfaite'!$E$20 -> 0 | L14: 4,0,0,0,5,0,0 | M14: 0 | P14: FALSE
A15: ='Valeur Info Imparfaite'!$E$23 -> 0 | B15: 0 litre | C15: 0 | H15: ='Valeur Info Imparfaite'!$C$5 -> 1 | I15: DEFAULT | J15: ='Valeur Info Imparfaite'!$D$23 -> 0 | L15: 1,0,0,3,4,11,12,2,0,0 | M15: 0 | O15: ='Valeur Info Imparfaite'!$E$22 -> Météo | P15: FALSE
A16: ='Valeur Info Imparfaite'!$E$33 -> -0.019207683 | B16: 50 litres | C16: 0 | H16: ='Valeur Info Imparfaite'!$C$5 -> 1 | I16: DEFAULT | J16: ='Valeur Info Imparfaite'!$D$33 -> 50 | L16: 1,0,0,3,13,14,15,2,0,0 | M16: 0 | O16: ='Valeur Info Imparfaite'!$E$32 -> Météo | P16: FALSE
A17: ='Valeur Info Imparfaite'!$E$41 -> -0.060807997 | B17: 100 litres | C17: 0 | H17: ='Valeur Info Imparfaite'!$C$5 -> 1 | I17: DEFAULT | J17: ='Valeur Info Imparfaite'!$D$41 -> 100 | L17: 1,0,0,3,16,17,18,2,0,0 | M17: 0 | O17: ='Valeur Info Imparfaite'!$E$40 -> Météo | P17: FALSE
A18: ='Valeur Info Imparfaite'!$E$51 -> 0 | B18: 0 litre | C18: 0 | H18: ='Valeur Info Imparfaite'!$C$5 -> 1 | I18: DEFAULT | J18: ='Valeur Info Imparfaite'!$D$51 -> 0 | L18: 1,0,0,3,19,20,21,3,0,0 | M18: 0 | O18: ='Valeur Info Imparfaite'!$E$50 -> Météo | P18: FALSE
A19: ='Valeur Info Imparfaite'!$E$61 -> 0.039215686 | B19: 50 litres | C19: 0 | H19: ='Valeur Info Imparfaite'!$C$5 -> 1 | I19: DEFAULT | J19: ='Valeur Info Imparfaite'!$D$61 -> 50 | L19: 1,0,0,3,22,23,24,3,0,0 | M19: 0 | O19: ='Valeur Info Imparfaite'!$E$60 -> Météo | P19: FALSE
A20: ='Valeur Info Imparfaite'!$E$69 -> 0.051262335 | B20: 100 litres | C20: 0 | H20: ='Valeur Info Imparfaite'!$C$5 -> 1 | I20: DEFAULT | J20: ='Valeur Info Imparfaite'!$D$69 -> 100 | L20: 1,0,0,3,25,26,27,3,0,0 | M20: 0 | O20: ='Valeur Info Imparfaite'!$E$68 -> Météo | P20: FALSE
A21: ='Valeur Info Imparfaite'!$F$25 -> 0 | B21: Nuageux | C21: 0 | H21: DEFAULT | I21: DEFAULT | J21: ='Valeur Info Imparfaite'!$E$25 -> 2 | K21: ='Valeur Info Imparfaite'!$E$24 -> 0.27 | L21: 4,0,0,0,5,0,0 | M21: 0 | P21: FALSE
A22: ='Valeur Info Imparfaite'!$F$27 -> 0 | B22: Averse | C22: 0 | H22: DEFAULT | I22: DEFAULT | J22: ='Valeur Info Imparfaite'!$E$27 -> 3 | K22: ='Valeur Info Imparfaite'!$E$26 -> 0.73 | L22: 4,0,0,0,5,0,0 | M22: 0 | P22: FALSE
A23: ='Valeur Info Imparfaite'!$F$31 -> 0.039215686 | B23: Ensoleillé | C23: 0 | H23: DEFAULT | I23: DEFAULT | J23: ='Valeur Info Imparfaite'!$E$31 -> 1 | K23: ='Valeur Info Imparfaite'!$E$30 -> 0 | L23: 4,0,0,0,6,0,0 | M23: 0 | P23: FALSE
A24: ='Valeur Info Imparfaite'!$F$35 -> 0.039215686 | B24: Nuageux | C24: 0 | H24: DEFAULT | I24: DEFAULT | J24: ='Valeur Info Imparfaite'!$E$35 -> 2 | K24: ='Valeur Info Imparfaite'!$E$34 -> 0.27 | L24: 4,0,0,0,6,0,0 | M24: 0 | P24: FALSE
A25: ='Valeur Info Imparfaite'!$F$37 -> -0.040816327 | B25: Averse | C25: 0 | H25: DEFAULT | I25: DEFAULT | J25: ='Valeur Info Imparfaite'!$E$37 -> 3 | K25: ='Valeur Info Imparfaite'!$E$36 -> 0.73 | L25: 4,0,0,0,6,0,0 | M25: 0 | P25: FALSE
A26: ='Valeur Info Imparfaite'!$F$39 -> 0.076893502 | B26: Ensoleillé | C26: 0 | H26: DEFAULT | I26: DEFAULT | J26: ='Valeur Info Imparfaite'!$E$39 -> 1 | K26: ='Valeur Info Imparfaite'!$E$38 -> 0 | L26: 4,0,0,0,7,0,0 | M26: 0 | P26: FALSE
A27: ='Valeur Info Imparfaite'!$F$43 -> 0 | B27: Nuageux | C27: 0 | H27: DEFAULT | I27: DEFAULT | J27: ='Valeur Info Imparfaite'!$E$43 -> 2 | K27: ='Valeur Info Imparfaite'!$E$42 -> 0.27 | L27: 4,0,0,0,7,0,0 | M27: 0 | P27: FALSE
A28: ='Valeur Info Imparfaite'!$F$45 -> -0.083298626 | B28: Averse | C28: 0 | H28: DEFAULT | I28: DEFAULT | J28: ='Valeur Info Imparfaite'!$E$45 -> 3 | K28: ='Valeur Info Imparfaite'!$E$44 -> 0.73 | L28: 4,0,0,0,7,0,0 | M28: 0 | P28: FALSE
A29: ='Valeur Info Imparfaite'!$F$49 -> 0 | B29: Ensoleillé | C29: 0 | H29: DEFAULT | I29: DEFAULT | J29: ='Valeur Info Imparfaite'!$E$49 -> 1 | K29: ='Valeur Info Imparfaite'!$E$48 -> 0.66666667 | L29: 4,0,0,0,8,0,0 | M29: 0 | P29: FALSE
A30: ='Valeur Info Imparfaite'!$F$53 -> 0 | B30: Nuageux | C30: 0 | H30: DEFAULT | I30: DEFAULT | J30: ='Valeur Info Imparfaite'!$E$53 -> 2 | K30: ='Valeur Info Imparfaite'!$E$52 -> 0.33333333 | L30: 4,0,0,0,8,0,0 | M30: 0 | P30: FALSE
A31: ='Valeur Info Imparfaite'!$F$55 -> 0 | B31: Averse | C31: 0 | H31: DEFAULT | I31: DEFAULT | J31: ='Valeur Info Imparfaite'!$E$55 -> 3 | K31: ='Valeur Info Imparfaite'!$E$54 -> 0 | L31: 4,0,0,0,8,0,0 | M31: 0 | P31: FALSE
A32: ='Valeur Info Imparfaite'!$F$59 -> 0.039215686 | B32: Ensoleillé | C32: 0 | H32: DEFAULT | I32: DEFAULT | J32: ='Valeur Info Imparfaite'!$E$59 -> 1 | K32: ='Valeur Info Imparfaite'!$E$58 -> 0.66666667 | L32: 4,0,0,0,9,0,0 | M32: 0 | P32: FALSE
A33: ='Valeur Info Imparfaite'!$F$63 -> 0.039215686 | B33: Nuageux | C33: 0 | H33: DEFAULT | I33: DEFAULT | J33: ='Valeur Info Imparfaite'!$E$63 -> 2 | K33: ='Valeur Info Imparfaite'!$E$62 -> 0.33333333 | L33: 4,0,0,0,9,0,0 | M33: 0 | P33: FALSE
A34: ='Valeur Info Imparfaite'!$F$65 -> -0.040816327 | B34: Averse | C34: 0 | H34: DEFAULT | I34: DEFAULT | J34: ='Valeur Info Imparfaite'!$E$65 -> 3 | K34: ='Valeur Info Imparfaite'!$E$64 -> 0 | L34: 4,0,0,0,9,0,0 | M34: 0 | P34: FALSE
A35: ='Valeur Info Imparfaite'!$F$67 -> 0.076893502 | B35: Ensoleillé | C35: 0 | H35: DEFAULT | I35: DEFAULT | J35: ='Valeur Info Imparfaite'!$E$67 -> 1 | K35: ='Valeur Info Imparfaite'!$E$66 -> 0.66666667 | L35: 4,0,0,0,10,0,0 | M35: 0 | P35: FALSE
A36: ='Valeur Info Imparfaite'!$F$71 -> 0 | B36: Nuageux | C36: 0 | H36: DEFAULT | I36: DEFAULT | J36: ='Valeur Info Imparfaite'!$E$71 -> 2 | K36: ='Valeur Info Imparfaite'!$E$70 -> 0.33333333 | L36: 4,0,0,0,10,0,0 | M36: 0 | P36: FALSE
A37: ='Valeur Info Imparfaite'!$F$73 -> -0.083298626 | B37: Averse | C37: 0 | H37: DEFAULT | I37: DEFAULT | J37: ='Valeur Info Imparfaite'!$E$73 -> 3 | K37: ='Valeur Info Imparfaite'!$E$72 -> 0 | L37: 4,0,0,0,10,0,0 | M37: 0 | P37: FALSE

Sheet F. utilite
A1: min | B1: -100
A2: max | B2: 100
A3: Delta | B3: =(B2-A4)/20 -> 10 | D3: a | E3: =B*EXP(-A4/RT) -> 6.762496
A4: =B1 -> -100 | B4: =$E$3-$E$4*EXP(-A4/$E$5) -> 0 | D4: b | E4: =1/(EXP(-A4/RT)-EXP(-A24/RT)) -> 6.242504
A5: =A4+$B$3 -> -90 | B5: =$E$3-$E$4*EXP(-A5/$E$5) -> 0.053891302 | D5: R | E5: =ABS(I30)/LN(M17/M22) -> 1249.8333
A6: =A5+$B$3 -> -80 | B6: =$E$3-$E$4*EXP(-A6/$E$5) -> 0.10735314
A7: =A6+$B$3 -> -70 | B7: =$E$3-$E$4*EXP(-A7/$E$5) -> 0.16038892
A8: =A7+$B$3 -> -60 | B8: =$E$3-$E$4*EXP(-A8/$E$5) -> 0.21300206
A9: =A8+$B$3 -> -50 | B9: =$E$3-$E$4*EXP(-A9/$E$5) -> 0.26519592
A10: =A9+$B$3 -> -40 | B10: =$E$3-$E$4*EXP(-A10/$E$5) -> 0.31697384
A11: =A10+$B$3 -> -30 | B11: =$E$3-$E$4*EXP(-A11/$E$5) -> 0.36833913
A12: =A11+$B$3 -> -20 | B12: =$E$3-$E$4*EXP(-A12/$E$5) -> 0.41929508
A13: =A12+$B$3 -> -10 | B13: =$E$3-$E$4*EXP(-A13/$E$5) -> 0.46984496 | Q13: Stratégie optimale
A14: =A13+$B$3 -> 0 | B14: =$E$3-$E$4*EXP(-A14/$E$5) -> 0.519992 | Q14: =IF(Arbre!$C$16=TRUE,"0 litre",IF(Arbre!$C$26=TRUE,"50 litres",IF(Arbre!$C$34=TRUE,"100 litres",0))) -> 50 litres
A15: =A14+$B$3 -> 10 | B15: =$E$3-$E$4*EXP(-A15/$E$5) -> 0.56973941
A16: =A15+$B$3 -> 20 | B16: =$E$3-$E$4*EXP(-A16/$E$5) -> 0.61909038
A17: =A16+$B$3 -> 30 | B17: =$E$3-$E$4*EXP(-A17/$E$5) -> 0.66804806 | M17: 0.51
A18: =A17+$B$3 -> 40 | B18: =$E$3-$E$4*EXP(-A18/$E$5) -> 0.71661559 | M18: Pile
A19: =A18+$B$3 -> 50 | B19: =$E$3-$E$4*EXP(-A19/$E$5) -> 0.76479608 | P19: =SUM(M20,I22) -> 100
A20: =A19+$B$3 -> 60 | B20: =$E$3-$E$4*EXP(-A20/$E$5) -> 0.81259261 | I20: Jouer | M20: =B2 -> 100 | N20: =P19 -> 100
A21: =A20+$B$3 -> 70 | B21: =$E$3-$E$4*EXP(-A21/$E$5) -> 0.86000825 | N21: =A-B*EXP(-N20/RT) -> 1
A22: =A21+$B$3 -> 80 | B22: =$E$3-$E$4*EXP(-A22/$E$5) -> 0.90704602 | I22: 0 | J22: =-LN((A-J23)/B)*RT -> 50 | M22: =1-M17 -> 0.49
A23: =A22+$B$3 -> 90 | B23: =$E$3-$E$4*EXP(-A23/$E$5) -> 0.95370894 | J23: =IF(ABS(1-SUM(M17,M22))<=0.00001,SUM(M17*N21,M22*N26),NA()) -> 0.76479608 | M23: Face
A24: =A23+$B$3 -> 100 | B24: =$E$3-$E$4*EXP(-A24/$E$5) -> 1 | P24: =SUM(M25,I22) -> 0
G25: =IF(F26=J22,1,IF(F26=J30,2)) -> 2 | M25: 0 | N25: =P24 -> 0
F26: =MAX(J22,J30) -> 50 | N26: =A-B*EXP(-N25/RT) -> 0.519992
F27: =A-B*EXP(-F26/RT) -> 0.76479608
I28: Ne pas jouer
P29: =SUM(I30) -> 50
I30: =M20/2 -> 50 | J30: =P29 -> 50
J31: =A-B*EXP(-J30/RT) -> 0.76479608
GH1000: ID | GI1000: Name | GJ1000: Value | GK1000: Prob | GL1000: Pred | GM1000: Kind | GN1000: NS | GO1000: S1 | GP1000: S2 | GQ1000: S3 | GR1000: S4 | GS1000: S5 | GT1000: Row | GU1000: Col | GV1000: Mark
GH1001: 0 | GI1001: TreePlan | GJ1001: 0 | GK1001: 0 | GL1001: 0 | GM1001: D | GN1001: 2 | GO1001: 1 | GP1001: 2 | GQ1001: 0 | GR1001: 0 | GS1001: 0 | GT1001: 8 | GU1001: 1 | GV1001: TRUE
GH1002: 1 | GK1002: 0 | GL1002: 0 | GM1002: E | GN1002: 2 | GO1002: 3 | GP1002: 4 | GQ1002: 0 | GR1002: 0 | GS1002: 0 | GT1002: 4 | GU1002: 5 | GV1002: TRUE
GH1003: 2 | GK1003: 0 | GL1003: 0 | GM1003: T | GN1003: 0 | GO1003: 0 | GP1003: 0 | GQ1003: 0 | GR1003: 0 | GS1003: 0 | GT1003: 12 | GU1003: 5 | GV1003: TRUE
GH1004: 3 | GL1004: 1 | GM1004: T | GN1004: 0 | GO1004: 0 | GP1004: 0 | GQ1004: 0 | GR1004: 0 | GS1004: 0 | GT1004: 2 | GU1004: 9 | GV1004: TRUE
GH1005: 4 | GL1005: 1 | GM1005: T | GN1005: 0 | GO1005: 0 | GP1005: 0 | GQ1005: 0 | GR1005: 0 | GS1005: 0 | GT1005: 7 | GU1005: 9 | GV1005: TRUE

Sheet Meteo
A1: N | B1: 3
A2: Demande max. | B2: 100
A3: Id | B3: Type | C3: Probabilité | D3: Niveau de temp. | E3: Demande
A4: 1 | B4: Ensoleillé | C4: 0.3 | D4: 1 | E4: =D4*$B$2 -> 100
A5: 2 | B5: Nuageux | C5: 0.3 | D5: =D4-1/($B$1-1) -> 0.5 | E5: =D5*$B$2 -> 50
A6: 3 | B6: Averse | C6: 0.4 | D6: =D5-1/($B$1-1) -> 0 | E6: =D6*$B$2 -> 0

Sheet treeCalc_1
A1: Name | B1: Stand Limonade | E1: Ptree1 Compatibility | F1: 3 | H1: Output Label | K1: R-Value Ref. | L1: 1000
A2: SheetRef | B2: =Arbre!#REF! -> #REF! | E2: Eval. Function | F2: =_xll.PTreeEvaluate5(B3,$L$11:$L$23,$J$11:$J$23,$K$11:$K$23,$N$11:$N$23,$G$11:$G$23,,L1) -> 7538707
A3: GenInfo | B3: -1,1,1,-1,0,Exponential, 0,0,-1,0,-1,-1,.0001 | E3: Creation Version | F3: 5.7.1 | H3: Output Value NF | I3: <NF>
A4: Def. Link | B4: =Arbre!$C$10 -> -100 | E4: Required Version | F4: 5.0.0 | H4: Output Prob NF | I4: Automatic
A5: EXT REFS | B5: 0 | E5: Recommended Version | F5: 5.0.0 | H5: Input Value NF | I5: <NF>
A6: Def. Form | E6: Last Modified By Version | F6: 8.0.1 | H6: Input Prob NF | I6: Automatic
A7: Calc Macro | F7: 2BCD88B3
A8: Highest# | B8: 13
A10: Anchor Cell | B10: Branch Name | C10: bformtype | D10: valformula | E10: pbformula | F10: distribution | G10: cumPayoffFunction | H10: link | I10: ENDNODEFORMULA | J10: VAL | K10: PB | L10: GenInfo | M10: IntRefs | N10: RefRefs | O10: NodeNames | P10: Collapsed
A11: =Arbre!$C$23 -> 10 | B11: =B1 -> Stand Limonade | C11: 0 | H11: =Arbre!$C$4 -> 100 | I11: DEFAULT | J11: =Arbre!$B$23 -> 0 | K11: =Arbre!$B$22 -> 0 | L11: 2,0,1,3,2,3,4,0,0,0 | M11: 0 | O11: =Arbre!$C$22 -> Production | P11: FALSE
A12: =Arbre!$D$17 -> 0 | B12: 0 litre | C12: 0 | H12: =Arbre!$C$5 -> 3 | I12: DEFAULT | J12: =Arbre!$C$17 -> 0 | L12: 1,0,1,3,5,6,7,1,0,0 | M12: 0 | O12: =Arbre!$D$16 -> Météo | P12: FALSE
A13: =Arbre!$D$27 -> 10 | B13: 50 litres | C13: 0 | H13: =Arbre!$C$5 -> 3 | I13: DEFAULT | J13: =Arbre!$C$27 -> 50 | L13: 1,0,1,3,8,9,10,1,0,0 | M13: 0 | O13: =Arbre!$D$26 -> Météo | P13: FALSE
A14: =Arbre!$D$35 -> -10 | B14: 100 litres | C14: 0 | H14: =Arbre!$C$5 -> 3 | I14: DEFAULT | J14: =Arbre!$C$35 -> 100 | L14: 1,0,1,3,11,12,13,1,0,0 | M14: 0 | O14: =Arbre!$D$34 -> Météo | P14: FALSE
A15: =Arbre!$E$15 -> 0 | B15: Ensoleillé | C15: 0 | H15: DEFAULT | I15: DEFAULT | J15: =Arbre!$D$15 -> 1 | K15: =Arbre!$D$14 -> 0.3 | L15: 4,0,0,0,2,0,0 | M15: 0 | P15: FALSE
A16: =Arbre!$E$19 -> 0 | B16: Nuageux | C16: 0 | H16: DEFAULT | I16: DEFAULT | J16: =Arbre!$D$19 -> 2 | K16: =Arbre!$D$18 -> 0.3 | L16: 4,0,0,0,2,0,0 | M16: 0 | P16: FALSE
A17: =Arbre!$E$21 -> 0 | B17: Averse | C17: 0 | H17: DEFAULT | I17: DEFAULT | J17: =Arbre!$D$21 -> 3 | K17: =Arbre!$D$20 -> 0.4 | L17: 4,0,0,0,2,0,0 | M17: 0 | P17: FALSE
A18: =Arbre!$E$25 -> 50 | B18: Ensoleillé | C18: 0 | H18: DEFAULT | I18: DEFAULT | J18: =Arbre!$D$25 -> 1 | K18: =Arbre!$D$24 -> 0.3 | L18: 4,0,0,0,3,0,0 | M18: 0 | P18: FALSE
A19: =Arbre!$E$29 -> 50 | B19: Nuageux | C19: 0 | H19: DEFAULT | I19: DEFAULT | J19: =Arbre!$D$29 -> 2 | K19: =Arbre!$D$28 -> 0.3 | L19: 4,0,0,0,3,0,0 | M19: 0 | P19: FALSE
A20: =Arbre!$E$31 -> -50 | B20: Averse | C20: 0 | H20: DEFAULT | I20: DEFAULT | J20: =Arbre!$D$31 -> 3 | K20: =Arbre!$D$30 -> 0.4 | L20: 4,0,0,0,3,0,0 | M20: 0 | P20: FALSE
A21: =Arbre!$E$33 -> 100 | B21: Ensoleillé | C21: 0 | H21: DEFAULT | I21: DEFAULT | J21: =Arbre!$D$33 -> 1 | K21: =Arbre!$D$32 -> 0.3 | L21: 4,0,0,0,4,0,0 | M21: 0 | P21: FALSE
A22: =Arbre!$E$37 -> 0 | B22: Nuageux | C22: 0 | H22: DEFAULT | I22: DEFAULT | J22: =Arbre!$D$37 -> 2 | K22: =Arbre!$D$36 -> 0.3 | L22: 4,0,0,0,4,0,0 | M22: 0 | P22: FALSE
A23: =Arbre!$E$39 -> -100 | B23: Averse | C23: 0 | H23: DEFAULT | I23: DEFAULT | J23: =Arbre!$D$39 -> 3 | K23: =Arbre!$D$38 -> 0.4 | L23: 4,0,0,0,4,0,0 | M23: 0 | P23: FALSE

Sheet Arbre
B2: Prix de vente ($/litre) | C2: 2
B3: Coûts prod. ($/litre) | C3: 1
B4: Litres produits | C4: 100
B5: Météo (id) | C5: 3
B6: Météo (type) | C6: =VLOOKUP(C5,Meteo!A4:E6,2,FALSE) -> Averse
B7: Demande | C7: =VLOOKUP(C5,Meteo!A4:E6,5) -> 0
B8: Revenus | C8: =MIN(C4,C7)*C2 -> 0
B9: Couts | C9: =C4*C3 -> 100
B10: Profits | C10: =C8-C9 -> -100
D14: 0.3 | E14: =_xll.PTreeNodeProbability(treeCalc_1!$F$2,5) -> 0
D15: 1 | E15: =_xll.PTreeNodeValue(treeCalc_1!$F$2,5) -> 0
C16: =_xll.PTreeNodeDecision(treeCalc_1!$F$2,2) -> FALSE | D16: Météo
C17: 0 | D17: =_xll.PTreeNodeValue(treeCalc_1!$F$2,2) -> 0
D18: 0.3 | E18: =_xll.PTreeNodeProbability(treeCalc_1!$F$2,6) -> 0
D19: 2 | E19: =_xll.PTreeNodeValue(treeCalc_1!$F$2,6) -> 0
D20: 0.4 | E20: =_xll.PTreeNodeProbability(treeCalc_1!$F$2,7) -> 0
D21: 3 | E21: =_xll.PTreeNodeValue(treeCalc_1!$F$2,7) -> 0
C22: Production
C23: =_xll.PTreeNodeValue(treeCalc_1!$F$2,1) -> 10
D24: 0.3 | E24: =_xll.PTreeNodeProbability(treeCalc_1!$F$2,8) -> 0.3
D25: 1 | E25: =_xll.PTreeNodeValue(treeCalc_1!$F$2,8) -> 50
C26: =_xll.PTreeNodeDecision(treeCalc_1!$F$2,3) -> TRUE | D26: Météo
C27: 50 | D27: =_xll.PTreeNodeValue(treeCalc_1!$F$2,3) -> 10
D28: 0.3 | E28: =_xll.PTreeNodeProbability(treeCalc_1!$F$2,9) -> 0.3
D29: 2 | E29: =_xll.PTreeNodeValue(treeCalc_1!$F$2,9) -> 50
D30: 0.4 | E30: =_xll.PTreeNodeProbability(treeCalc_1!$F$2,10) -> 0.4
D31: 3 | E31: =_xll.PTreeNodeValue(treeCalc_1!$F$2,10) -> -50
D32: 0.3 | E32: =_xll.PTreeNodeProbability(treeCalc_1!$F$2,11) -> 0
D33: 1 | E33: =_xll.PTreeNodeValue(treeCalc_1!$F$2,11) -> 100
C34: =_xll.PTreeNodeDecision(treeCalc_1!$F$2,4) -> FALSE | D34: Météo
C35: 100 | D35: =_xll.PTreeNodeValue(treeCalc_1!$F$2,4) -> -10
D36: 0.3 | E36: =_xll.PTreeNodeProbability(treeCalc_1!$F$2,12) -> 0
D37: 2 | E37: =_xll.PTreeNodeValue(treeCalc_1!$F$2,12) -> 0
D38: 0.4 | E38: =_xll.PTreeNodeProbability(treeCalc_1!$F$2,13) -> 0
D39: 3 | E39: =_xll.PTreeNodeValue(treeCalc_1!$F$2,13) -> -100

Sheet Valeur Info Parfaite
B2: Prix de vente ($/litre) | C2: 2
B3: Coûts prod. ($/litre) | C3: 1
B4: Litres produits | C4: 100
B5: Météo | C5: 1
B6: Météo (type) | C6: =VLOOKUP(C5,Meteo!A4:E6,2,FALSE) -> Ensoleillé
B7: Demande | C7: =VLOOKUP(C5,Meteo!A4:E6,5) -> 100
B8: Revenus | C8: =MIN(C4,C7)*C2 -> 200
B9: Couts de production | C9: =C4*C3 -> 100
B10: Coût de l'information | C10: 0
B11: Profits | C11: =C8-C9-C10 -> 100
B13: Utilité espérée avec info | C13: =C28 -> 0.034832757
B14: Utilité espérée sans info | C14: =Arbre!C23 -> 10
B15: Différence | C15: =C13-C14 -> -9.9651672
D19: =_xll.PTreeNodeDecision(treeCalc_3!$F$2,5) -> FALSE | E19: =_xll.PTreeNodeProbability(treeCalc_3!$F$2,5) -> 0
D20: 0 | E20: =_xll.PTreeNodeValue(treeCalc_3!$F$2,5) -> 0
C21: 0.3 | D21: Decision
C22: 1 | D22: =_xll.PTreeNodeValue(treeCalc_3!$F$2,2) -> 0.076893502
D23: =_xll.PTreeNodeDecision(treeCalc_3!$F$2,6) -> FALSE | E23: =_xll.PTreeNodeProbability(treeCalc_3!$F$2,6) -> 0
D24: 50 | E24: =_xll.PTreeNodeValue(treeCalc_3!$F$2,6) -> 0.039215686
D25: =_xll.PTreeNodeDecision(treeCalc_3!$F$2,7) -> TRUE | E25: =_xll.PTreeNodeProbability(treeCalc_3!$F$2,7) -> 0.3
D26: 100 | E26: =_xll.PTreeNodeValue(treeCalc_3!$F$2,7) -> 0.076893502
C27: Météo
C28: =_xll.PTreeNodeValue(treeCalc_3!$F$2,1) -> 0.034832757
D29: =_xll.PTreeNodeDecision(treeCalc_3!$F$2,8) -> FALSE | E29: =_xll.PTreeNodeProbability(treeCalc_3!$F$2,8) -> 0
D30: 0 | E30: =_xll.PTreeNodeValue(treeCalc_3!$F$2,8) -> 0
C31: 0.3 | D31: Decision
C32: 2 | D32: =_xll.PTreeNodeValue(treeCalc_3!$F$2,3) -> 0.039215686
D33: =_xll.PTreeNodeDecision(treeCalc_3!$F$2,9) -> TRUE | E33: =_xll.PTreeNodeProbability(treeCalc_3!$F$2,9) -> 0.3
D34: 50 | E34: =_xll.PTreeNodeValue(treeCalc_3!$F$2,9) -> 0.039215686
D35: =_xll.PTreeNodeDecision(treeCalc_3!$F$2,10) -> FALSE | E35: =_xll.PTreeNodeProbability(treeCalc_3!$F$2,10) -> 0
D36: 100 | E36: =_xll.PTreeNodeValue(treeCalc_3!$F$2,10) -> 0
D37: =_xll.PTreeNodeDecision(treeCalc_3!$F$2,11) -> TRUE | E37: =_xll.PTreeNodeProbability(treeCalc_3!$F$2,11) -> 0.4
D38: 0 | E38: =_xll.PTreeNodeValue(treeCalc_3!$F$2,11) -> 0
C39: 0.4 | D39: Decision
C40: 3 | D40: =_xll.PTreeNodeValue(treeCalc_3!$F$2,4) -> 0
D41: =_xll.PTreeNodeDecision(treeCalc_3!$F$2,12) -> FALSE | E41: =_xll.PTreeNodeProbability(treeCalc_3!$F$2,12) -> 0
D42: 50 | E42: =_xll.PTreeNodeValue(treeCalc_3!$F$2,12) -> -0.040816327
D43: =_xll.PTreeNodeDecision(treeCalc_3!$F$2,13) -> FALSE | E43: =_xll.PTreeNodeProbability(treeCalc_3!$F$2,13) -> 0
D44: 100 | E44: =_xll.PTreeNodeValue(treeCalc_3!$F$2,13) -> -0.083298626

Sheet Valeur Info Imparfaite
B2: Prix de vente ($/litre) | C2: 2
B3: Coûts prod. ($/litre) | C3: 1
B4: Litres produits | C4: 100
B5: Météo | C5: 1
B6: Météo (type) | C6: =VLOOKUP(C5,Meteo!A4:E6,2,FALSE) -> Ensoleillé
B7: Demande | C7: =VLOOKUP(C5,Meteo!A4:E6,5) -> 100
B8: Revenus | C8: =MIN(C4,C7)*C2 -> 200
B9: Couts de production | C9: =C4*C3 -> 100
B10: Coût de l'information | C10: 0
B11: Profits | C11: =C8-C9-C10 -> 100
B13: Utilité espérée avec info | C13: =C47 -> 0.023068051
B14: Utilité espérée sans info | C14: =Arbre!C23 -> 10
B15: Différence | C15: =C13-C14 -> -9.9769319
E20: 0 | F20: =_xll.PTreeNodeProbability(treeCalc_4!$F$2,4) -> 0
E21: 1 | F21: =_xll.PTreeNodeValue(treeCalc_4!$F$2,4) -> 0
D22: =_xll.PTreeNodeDecision(treeCalc_4!$F$2,5) -> TRUE | E22: Météo
D23: 0 | E23: =_xll.PTreeNodeValue(treeCalc_4!$F$2,5) -> 0
E24: 0.27 | F24: =_xll.PTreeNodeProbability(treeCalc_4!$F$2,11) -> 0.1485
E25: 2 | F25: =_xll.PTreeNodeValue(treeCalc_4!$F$2,11) -> 0
E26: 0.73 | F26: =_xll.PTreeNodeProbability(treeCalc_4!$F$2,12) -> 0.4015
E27: 3 | F27: =_xll.PTreeNodeValue(treeCalc_4!$F$2,12) -> 0
C28: 0.55 | D28: Decision
C29: 0 | D29: =_xll.PTreeNodeValue(treeCalc_4!$F$2,2) -> 0
E30: 0 | F30: =_xll.PTreeNodeProbability(treeCalc_4!$F$2,13) -> 0
E31: 1 | F31: =_xll.PTreeNodeValue(treeCalc_4!$F$2,13) -> 0.039215686
D32: =_xll.PTreeNodeDecision(treeCalc_4!$F$2,6) -> FALSE | E32: Météo
D33: 50 | E33: =_xll.PTreeNodeValue(treeCalc_4!$F$2,6) -> -0.019207683
E34: 0.27 | F34: =_xll.PTreeNodeProbability(treeCalc_4!$F$2,14) -> 0
E35: 2 | F35: =_xll.PTreeNodeValue(treeCalc_4!$F$2,14) -> 0.039215686
E36: 0.73 | F36: =_xll.PTreeNodeProbability(treeCalc_4!$F$2,15) -> 0
E37: 3 | F37: =_xll.PTreeNodeValue(treeCalc_4!$F$2,15) -> -0.040816327
E38: 0 | F38: =_xll.PTreeNodeProbability(treeCalc_4!$F$2,16) -> 0
E39: 1 | F39: =_xll.PTreeNodeValue(treeCalc_4!$F$2,16) -> 0.076893502
D40: =_xll.PTreeNodeDecision(treeCalc_4!$F$2,7) -> FALSE | E40: Météo
D41: 100 | E41: =_xll.PTreeNodeValue(treeCalc_4!$F$2,7) -> -0.060807997
E42: 0.27 | F42: =_xll.PTreeNodeProbability(treeCalc_4!$F$2,17) -> 0
E43: 2 | F43: =_xll.PTreeNodeValue(treeCalc_4!$F$2,17) -> 0
E44: 0.73 | F44: =_xll.PTreeNodeProbability(treeCalc_4!$F$2,18) -> 0
E45: 3 | F45: =_xll.PTreeNodeValue(treeCalc_4!$F$2,18) -> -0.083298626
C46: Prévision météo.
...
