Workbook
Name PalisadeReportWorkbookCreatedBy: "PrecisionTree"

Sheet Meteo
A1: N | B1: 3
A2: Demande max. | B2: 100
A3: Id | B3: Type | C3: Probabilité | D3: Niveau de temp. | E3: Demande
A4: 1 | B4: Ensoleillé | C4: 0.3 | D4: =100% -> 1 | E4: =D4*$B$2 -> 100
A5: 2 | B5: Nuageux | C5: 0.3 | D5: =D4-1/($B$1-1) -> 0.5 | E5: =D5*$B$2 -> 50
A6: 3 | B6: Averse | C6: 0.4 | D6: =D5-1/($B$1-1) -> 0 | E6: =D6*$B$2 -> 0

Sheet treeCalc_1
A1: Name | B1: Stand Limonade | E1: Ptree1 Compatibility | F1: 3 | H1: Output Label | K1: R-Value Ref. | L1: 100
A2: SheetRef | B2: =Standard!#REF! -> #REF! | E2: Eval. Function | F2: =_xll.PTreeEvaluate5(B3,$L$11:$L$23,$J$11:$J$23,$K$11:$K$23,$N$11:$N$23,$G$11:$G$23,,L1) -> 2701843
A3: GenInfo | B3: -1,1,1,-1,0,Exponential, 0,0,-1,0,-1,-1,.0001 | E3: Creation Version | F3: 5.7.1 | H3: Output Value NF | I3: <NF>
A4: Def. Link | B4: =Standard!$C$10 -> -100 | E4: Required Version | F4: 5.0.0 | H4: Output Prob NF | I4: Automatic
A5: EXT REFS | B5: 0 | E5: Recommended Version | F5: 5.0.0 | H5: Input Value NF | I5: <NF>
A6: Def. Form | E6: Last Modified By Version | F6: 7.6.1 | H6: Input Prob NF | I6: Automatic
A7: Calc Macro | F7: 7AAA3F5
A8: Highest# | B8: 13
A10: Anchor Cell | B10: Branch Name | C10: bformtype | D10: valformula | E10: pbformula | F10: distribution | G10: cumPayoffFunction | H10: link | I10: ENDNODEFORMULA | J10: VAL | K10: PB | L10: GenInfo | M10: IntRefs | N10: RefRefs | O10: NodeNames | P10: Collapsed
A11: =Standard!$C$23 -> 10 | B11: =B1 -> Stand Limonade | C11: 0 | H11: =Standard!$C$4 -> 100 | I11: DEFAULT | J11: =Standard!$B$23 -> 0 | K11: =Standard!$B$22 -> 0 | L11: 2,0,1,3,2,3,4,0,0,0 | M11: 0 | O11: =Standard!$C$22 -> Production | P11: FALSE
A12: =Standard!$D$17 -> 0 | B12: 0 litre | C12: 0 | H12: =Standard!$C$5 -> 3 | I12: DEFAULT | J12: =Standard!$C$17 -> 0 | L12: 1,0,1,3,5,6,7,1,0,0 | M12: 0 | O12: =Standard!$D$16 -> Météo | P12: FALSE
A13: =Standard!$D$27 -> 10 | B13: 50 litres | C13: 0 | H13: =Standard!$C$5 -> 3 | I13: DEFAULT | J13: =Standard!$C$27 -> 50 | L13: 1,0,1,3,8,9,10,1,0,0 | M13: 0 | O13: =Standard!$D$26 -> Météo | P13: FALSE
A14: =Standard!$D$35 -> -10 | B14: 100 litres | C14: 0 | H14: =Standard!$C$5 -> 3 | I14: DEFAULT | J14: =Standard!$C$35 -> 100 | L14: 1,0,1,3,11,12,13,1,0,0 | M14: 0 | O14: =Standard!$D$34 -> Météo | P14: FALSE
A15: =Standard!$E$15 -> 0 | B15: Ensoleillé | C15: 0 | H15: DEFAULT | I15: DEFAULT | J15: =Standard!$D$15 -> 1 | K15: =Standard!$D$14 -> 0.3 | L15: 4,0,0,0,2,0,0 | M15: 0 | P15: FALSE
A16: =Standard!$E$19 -> 0 | B16: Nuageux | C16: 0 | H16: DEFAULT | I16: DEFAULT | J16: =Standard!$D$19 -> 2 | K16: =Standard!$D$18 -> 0.3 | L16: 4,0,0,0,2,0,0 | M16: 0 | P16: FALSE
A17: =Standard!$E$21 -> 0 | B17: Averse | C17: 0 | H17: DEFAULT | I17: DEFAULT | J17: =Standard!$D$21 -> 3 | K17: =Standard!$D$20 -> 0.4 | L17: 4,0,0,0,2,0,0 | M17: 0 | P17: FALSE
A18: =Standard!$E$25 -> 50 | B18: Ensoleillé | C18: 0 | H18: DEFAULT | I18: DEFAULT | J18: =Standard!$D$25 -> 1 | K18: =Standard!$D$24 -> 0.3 | L18: 4,0,0,0,3,0,0 | M18: 0 | P18: FALSE
A19: =Standard!$E$29 -> 50 | B19: Nuageux | C19: 0 | H19: DEFAULT | I19: DEFAULT | J19: =Standard!$D$29 -> 2 | K19: =Standard!$D$28 -> 0.3 | L19: 4,0,0,0,3,0,0 | M19: 0 | P19: FALSE
A20: =Standard!$E$31 -> -50 | B20: Averse | C20: 0 | H20: DEFAULT | I20: DEFAULT | J20: =Standard!$D$31 -> 3 | K20: =Standard!$D$30 -> 0.4 | L20: 4,0,0,0,3,0,0 | M20: 0 | P20: FALSE
A21: =Standard!$E$33 -> 100 | B21: Ensoleillé | C21: 0 | H21: DEFAULT | I21: DEFAULT | J21: =Standard!$D$33 -> 1 | K21: =Standard!$D$32 -> 0.3 | L21: 4,0,0,0,4,0,0 | M21: 0 | P21: FALSE
A22: =Standard!$E$37 -> 0 | B22: Nuageux | C22: 0 | H22: DEFAULT | I22: DEFAULT | J22: =Standard!$D$37 -> 2 | K22: =Standard!$D$36 -> 0.3 | L22: 4,0,0,0,4,0,0 | M22: 0 | P22: FALSE
A23: =Standard!$E$39 -> -100 | B23: Averse | C23: 0 | H23: DEFAULT | I23: DEFAULT | J23: =Standard!$D$39 -> 3 | K23: =Standard!$D$38 -> 0.4 | L23: 4,0,0,0,4,0,0 | M23: 0 | P23: FALSE

Sheet Standard données
B2: Prix de vente ($/litre) | C2: 2
B3: Coûts prod. ($/litre) | C3: 1
B4: Litres produits | C4: 100
B5: Météo (id) | C5: 3
B6: Météo (type) | C6: =VLOOKUP(C5,Meteo!A4:E6,2,FALSE) -> Averse
B7: Demande | C7: =VLOOKUP(C5,Meteo!A4:E6,5) -> 0
B8: Revenus | C8: =MIN(C4,C7)*C2 -> 0
B9: Couts | C9: =C4*C3 -> 100
B10: Profits | C10: =C8-C9 -> -100

Sheet Standard
B2: Prix de vente ($/litre) | C2: 2
B3: Coûts prod. ($/litre) | C3: 1 | F3: Bouton de droite de la sourie
B4: Litres produits | C4: 100
B5: Météo (id) | C5: 3 | I5: Collapse child branch : permet de cacher les branches d'un nœud
B6: Météo (type) | C6: =VLOOKUP(C5,Meteo!A4:E6,2,FALSE) -> Averse | I6: Copy subtree : permet de copier la structure d'un sous arbre pour le copier dans un autre nœud
B7: Demande | C7: =VLOOKUP(C5,Meteo!A4:E6,5) -> 0 | I7: Paste Subtree : permet de remplaced toutes la structure du sous arbre à partir de ce nœud par la structure copiée
B8: Revenus | C8: =MIN(C4,C7)*C2 -> 0
B9: Couts | C9: =C4*C3 -> 100
B10: Profits | C10: =C8-C9 -> -100
D14: 0.3 | E14: =_xll.PTreeNodeProbability(treeCalc_1!$F$2,5) -> 0
D15: 1 | E15: =_xll.PTreeNodeValue(treeCalc_1!$F$2,5) -> 0
C16: =_xll.PTreeNodeDecision(treeCalc_1!$F$2,2) -> FALSE | D16: Météo
C17: 0 | D17: =_xll.PTreeNodeValue(treeCalc_1!$F$2,2) -> 0
D18: 0.3 | E18: =_xll.PTreeNodeProbability(treeCalc_1!$F$2,6) -> 0
D19: 2 | E19: =_xll.PTreeNodeValue(treeCalc_1!$F$2,6) -> 0 | F19: Assurez-vous de rafraichir les calculs lorsque vous souhaiter connaître la solution optimale.
D20: 0.4 | E20: =_xll.PTreeNodeProbability(treeCalc_1!$F$2,7) -> 0
D21: 3 | E21: =_xll.PTreeNodeValue(treeCalc_1!$F$2,7) -> 0
C22: Production
C23: =_xll.PTreeNodeValue(treeCalc_1!$F$2,1) -> 10
D24: 0.3 | E24: =_xll.PTreeNodeProbability(treeCalc_1!$F$2,8) -> 0.3
D25: 1 | E25: =_xll.PTreeNodeValue(treeCalc_1!$F$2,8) -> 50
C26: =_xll.PTreeNodeDecision(treeCalc_1!$F$2,3) -> TRUE | D26: Météo
C27: 50 | D27: =_xll.PTreeNodeValue(treeCalc_1!$F$2,3) -> 10
D28: 0.3 | E28: =_xll.PTreeNodeProbability(treeCalc_1!$F$2,9) -> 0.3
D29: 2 | E29: =_xll.PTreeNodeValue(treeCalc_1!$F$2,9) -> 50
D30: 0.4 | E30: =_xll.PTreeNodeProbability(treeCalc_1!$F$2,10) -> 0.4
D31: 3 | E31: =_xll.PTreeNodeValue(treeCalc_1!$F$2,10) -> -50
D32: 0.3 | E32: =_xll.PTreeNodeProbability(treeCalc_1!$F$2,11) -> 0
D33: 1 | E33: =_xll.PTreeNodeValue(treeCalc_1!$F$2,11) -> 100
C34: =_xll.PTreeNodeDecision(treeCalc_1!$F$2,4) -> FALSE | D34: Météo
C35: 100 | D35: =_xll.PTreeNodeValue(treeCalc_1!$F$2,4) -> -10
D36: 0.3 | E36: =_xll.PTreeNodeProbability(treeCalc_1!$F$2,12) -> 0
D37: 2 | E37: =_xll.PTreeNodeValue(treeCalc_1!$F$2,12) -> 0
D38: 0.4 | E38: =_xll.PTreeNodeProbability(treeCalc_1!$F$2,13) -> 0
D39: 3 | E39: =_xll.PTreeNodeValue(treeCalc_1!$F$2,13) -> -100

Sheet treeCalc_2
A1: Name | B1: Stand Limonade (2) | E1: Ptree1 Compatibility | F1: 3 | H1: Output Label | K1: R-Value Ref. | L1: 100
A2: SheetRef | B2: ='Valeur Info Parfaite'!#REF! -> #REF! | E2: Eval. Function | F2: =_xll.PTreeEvaluate5(B3,$L$11:$L$35,$J$11:$J$35,$K$11:$K$35,$N$11:$N$35,$G$11:$G$35,,L1) -> 2753300
A3: GenInfo | B3: -1,2,1,-1,0,Exponential, 0,0,-1,0,-1,-1,.0001 | E3: Creation Version | F3: 5.7.1 | H3: Output Value NF | I3: <NF>
A4: Def. Link | B4: ='Valeur Info Parfaite'!$C$10 -> -100 | E4: Required Version | F4: 5.0.0 | H4: Output Prob NF | I4: Automatic
A5: EXT REFS | B5: 0 | D5: 0 | E5: Recommended Version | F5: 5.0.0 | H5: Input Value NF | I5: <NF>
A6: Def. Form | E6: Last Modified By Version | F6: 7.6.1 | H6: Input Prob NF | I6: Automatic
A7: Calc Macro | F7: 1AFBECD
A8: Highest# | B8: 25
A10: Anchor Cell | B10: Branch Name | C10: bformtype | D10: valformula | E10: pbformula | F10: distribution | G10: cumPayoffFunction | H10: link | I10: ENDNODEFORMULA | J10: VAL | K10: PB | L10: GenInfo | M10: IntRefs | N10: RefRefs | O10: NodeNames | P10: Collapsed
A11: ='Valeur Info Parfaite'!$C$23 -> 45 | B11: =B1 -> Stand Limonade (2) | C11: 0 | H11: ='Valeur Info Parfaite'!$C$5 -> 3 | I11: DEFAULT | J11: ='Valeur Info Parfaite'!$B$23 -> 0 | K11: ='Valeur Info Parfaite'!$B$22 -> 0 | L11: 1,0,1,3,2,6,10,0,0,0 | M11: 0 | O11: ='Valeur Info Parfaite'!$C$22 -> Météo | P11: FALSE
A12: ='Valeur Info Parfaite'!$D$17 -> 100 | B12: Ensoleillé | C12: 0 | H12: ='Valeur Info Parfaite'!$C$4 -> 100 | I12: DEFAULT | J12: ='Valeur Info Parfaite'!$C$17 -> 1 | K12: ='Valeur Info Parfaite'!$C$16 -> 0.3 | L12: 2,0,1,3,3,4,5,1,0,0 | M12: 0 | O12: ='Valeur Info Parfaite'!$D$16 -> Production | P12: FALSE
A13: ='Valeur Info Parfaite'!$E$15 -> 0 | B13: 0 litre | C13: 0 | H13: DEFAULT | I13: DEFAULT | J13: ='Valeur Info Parfaite'!$D$15 -> 0 | L13: 4,0,1,0,2,0,0 | M13: 0 | P13: FALSE
A14: ='Valeur Info Parfaite'!$E$19 -> 50 | B14: 50 litres | C14: 0 | H14: DEFAULT | I14: DEFAULT | J14: ='Valeur Info Parfaite'!$D$19 -> 50 | L14: 4,0,1,0,2,0,0 | M14: 0 | P14: FALSE
A15: ='Valeur Info Parfaite'!$E$21 -> 100 | B15: 100 litres | C15: 0 | H15: DEFAULT | I15: DEFAULT | J15: ='Valeur Info Parfaite'!$D$21 -> 100 | L15: 4,0,1,0,2,0,0 | M15: 0 | P15: FALSE
A16: ='Valeur Info Parfaite'!$D$27 -> 50 | B16: Nuageux | C16: 0 | H16: ='Valeur Info Parfaite'!$C$4 -> 100 | I16: DEFAULT | J16: ='Valeur Info Parfaite'!$C$27 -> 2 | K16: ='Valeur Info Parfaite'!$C$26 -> 0.3 | L16: 2,0,1,3,7,8,9,1,0,0 | M16: 0 | O16: ='Valeur Info Parfaite'!$D$26 -> Production | P16: FALSE
A17: ='Valeur Info Parfaite'!$E$25 -> 0 | B17: 0 litre | C17: 0 | H17: DEFAULT | I17: DEFAULT | J17: ='Valeur Info Parfaite'!$D$25 -> 0 | L17: 4,0,1,0,6,0,0 | M17: 0 | P17: FALSE
A18: ='Valeur Info Parfaite'!$E$29 -> 50 | B18: 50 litres | C18: 0 | H18: DEFAULT | I18: DEFAULT | J18: ='Valeur Info Parfaite'!$D$29 -> 50 | L18: 4,0,1,0,6,0,0 | M18: 0 | P18: FALSE
A19: ='Valeur Info Parfaite'!$E$31 -> 0 | B19: 100 litres | C19: 0 | H19: DEFAULT | I19: DEFAULT | J19: ='Valeur Info Parfaite'!$D$31 -> 100 | L19: 4,0,1,0,6,0,0 | M19: 0 | P19: FALSE
A20: ='Valeur Info Parfaite'!$D$35 -> 0 | B20: Averse | C20: 0 | H20: ='Valeur Info Parfaite'!$C$4 -> 100 | I20: DEFAULT | J20: ='Valeur Info Parfaite'!$C$35 -> 3 | K20: ='Valeur Info Parfaite'!$C$34 -> 0.4 | L20: 2,0,1,3,11,12,13,1,0,0 | M20: 0 | O20: ='Valeur Info Parfaite'!$D$34 -> Production | P20: FALSE
A21: ='Valeur Info Parfaite'!$E$33 -> 0 | B21: 0 litre | C21: 0 | H21: DEFAULT | I21: DEFAULT | J21: ='Valeur Info Parfaite'!$D$33 -> 0 | L21: 4,0,1,0,10,0,0 | M21: 0 | P21: FALSE
A22: ='Valeur Info Parfaite'!$E$37 -> -50 | B22: 50 litres | C22: 0 | H22: DEFAULT | I22: DEFAULT | J22: ='Valeur Info Parfaite'!$D$37 -> 50 | L22: 4,0,1,0,10,0,0 | M22: 0 | P22: FALSE
A23: ='Valeur Info Parfaite'!$E$39 -> -100 | B23: 100 litres | C23: 0 | H23: DEFAULT | I23: DEFAULT | J23: ='Valeur Info Parfaite'!$D$39 -> 100 | L23: 4,0,1,0,10,0,0 | M23: 0 | P23: FALSE

Sheet Valeur Info Parfaite
B2: Prix de vente ($/litre) | C2: 2
B3: Coûts prod. ($/litre) | C3: 1
B4: Litres produits | C4: 100 | E4: Valeur espérée sans info | F4: =Standard!C23 -> 10
B5: Météo (id) | C5: 3 | E5: Valeur espérée avec info | F5: =C23 -> 45
B6: Météo (type) | C6: =VLOOKUP(C5,Meteo!A4:E6,2,FALSE) -> Averse | E6: Valeur de l'info | F6: =F5-F4 -> 35
B7: Demande | C7: =VLOOKUP(C5,Meteo!A4:E6,5) -> 0
B8: Revenus | C8: =MIN(C4,C7)*C2 -> 0
B9: Couts | C9: =C4*C3 -> 100
B10: Profits | C10: =C8-C9 -> -100
D14: =_xll.PTreeNodeDecision(treeCalc_2!$F$2,3) -> FALSE | E14: =_xll.PTreeNodeProbability(treeCalc_2!$F$2,3) -> 0
D15: 0 | E15: =_xll.PTreeNodeValue(treeCalc_2!$F$2,3) -> 0
C16: 0.3 | D16: Production
C17: 1 | D17: =_xll.PTreeNodeValue(treeCalc_2!$F$2,2) -> 100
D18: =_xll.PTreeNodeDecision(treeCalc_2!$F$2,4) -> FALSE | E18: =_xll.PTreeNodeProbability(treeCalc_2!$F$2,4) -> 0
D19: 50 | E19: =_xll.PTreeNodeValue(treeCalc_2!$F$2,4) -> 50
D20: =_xll.PTreeNodeDecision(treeCalc_2!$F$2,5) -> TRUE | E20: =_xll.PTreeNodeProbability(treeCalc_2!$F$2,5) -> 0.3
D21: 100 | E21: =_xll.PTreeNodeValue(treeCalc_2!$F$2,5) -> 100
C22: Météo
C23: =_xll.PTreeNodeValue(treeCalc_2!$F$2,1) -> 45
D24: =_xll.PTreeNodeDecision(treeCalc_2!$F$2,7) -> FALSE | E24: =_xll.PTreeNodeProbability(treeCalc_2!$F$2,7) -> 0
D25: 0 | E25: =_xll.PTreeNodeValue(treeCalc_2!$F$2,7) -> 0
C26: 0.3 | D26: Production
C27: 2 | D27: =_xll.PTreeNodeValue(treeCalc_2!$F$2,6) -> 50
D28: =_xll.PTreeNodeDecision(treeCalc_2!$F$2,8) -> TRUE | E28: =_xll.PTreeNodeProbability(treeCalc_2!$F$2,8) -> 0.3
D29: 50 | E29: =_xll.PTreeNodeValue(treeCalc_2!$F$2,8) -> 50
D30: =_xll.PTreeNodeDecision(treeCalc_2!$F$2,9) -> FALSE | E30: =_xll.PTreeNodeProbability(treeCalc_2!$F$2,9) -> 0
D31: 100 | E31: =_xll.PTreeNodeValue(treeCalc_2!$F$2,9) -> 0
D32: =_xll.PTreeNodeDecision(treeCalc_2!$F$2,11) -> TRUE | E32: =_xll.PTreeNodeProbability(treeCalc_2!$F$2,11) -> 0.4
D33: 0 | E33: =_xll.PTreeNodeValue(treeCalc_2!$F$2,11) -> 0
C34: 0.4 | D34: Production
C35: 3 | D35: =_xll.PTreeNodeValue(treeCalc_2!$F$2,10) -> 0
D36: =_xll.PTreeNodeDecision(treeCalc_2!$F$2,12) -> FALSE | E36: =_xll.PTreeNodeProbability(treeCalc_2!$F$2,12) -> 0
D37: 50 | E37: =_xll.PTreeNodeValue(treeCalc_2!$F$2,12) -> -50
D38: =_xll.PTreeNodeDecision(treeCalc_2!$F$2,13) -> FALSE | E38: =_xll.PTreeNodeProbability(treeCalc_2!$F$2,13) -> 0
D39: 100 | E39: =_xll.PTreeNodeValue(treeCalc_2!$F$2,13) -> -100

Sheet treeCalc_3
A1: Name | B1: Stand Limonade (2) (2) | E1: Ptree1 Compatibility | F1: 3 | H1: Output Label | K1: R-Value Ref. | L1: 100
A2: SheetRef | B2: ='Valeur Info Imparfaite'!#REF! -> #REF! | E2: Eval. Function | F2: =_xll.PTreeEvaluate5(B3,$L$11:$L$37,$J$11:$J$37,$K$11:$K$37,$N$11:$N$37,$G$11:$G$37,,L1) -> 2804757
A3: GenInfo | B3: -1,3,1,-1,0,Exponential, 0,0,-1,0,-1,-1,.0001 | E3: Creation Version | F3: 5.7.1 | H3: Output Value NF | I3: <NF>
A4: Def. Link | B4: ='Valeur Info Imparfaite'!$C$10 -> -100 | E4: Required Version | F4: 5.0.0 | H4: Output Prob NF | I4: Automatic
A5: EXT REFS | B5: 0 | D5: 0 | E5: Recommended Version | F5: 5.0.0 | H5: Input Value NF | I5: <NF>
A6: Def. Form | E6: Last Modified By Version | F6: 7.6.1 | H6: Input Prob NF | I6: Automatic
A7: Calc Macro | F7: E4FC4B8
A8: Highest# | B8: 27
A10: Anchor Cell | B10: Branch Name | C10: bformtype | D10: valformula | E10: pbformula | F10: distribution | G10: cumPayoffFunction | H10: link | I10: ENDNODEFORMULA | J10: VAL | K10: PB | L10: GenInfo | M10: IntRefs | N10: RefRefs | O10: NodeNames | P10: Collapsed
A11: ='Valeur Info Imparfaite'!$C$41 -> 30 | B11: =B1 -> Stand Limonade (2) (2) | C11: 0 | I11: DEFAULT | J11: ='Valeur Info Imparfaite'!$B$41 -> 0 | K11: ='Valeur Info Imparfaite'!$B$40 -> 0 | L11: 1,0,1,2,2,6,0,0,0 | M11: 0 | O11: ='Valeur Info Imparfaite'!$C$40 -> Prévision expert | P11: FALSE
A12: ='Valeur Info Imparfaite'!$D$23 -> 66.666667 | B12: Clémente | C12: 0 | H12: ='Valeur Info Imparfaite'!$C$4 -> 100 | I12: DEFAULT | J12: ='Valeur Info Imparfaite'!$C$23 -> 0 | K12: ='Valeur Info Imparfaite'!$C$22 -> 0.45 | L12: 2,0,1,3,3,4,5,1,0,0 | M12: 0 | O12: ='Valeur Info Imparfaite'!$D$22 -> Production | P12: FALSE
A13: ='Valeur Info Imparfaite'!$E$17 -> 0 | B13: 0 litre | C13: 0 | H13: ='Valeur Info Imparfaite'!$C$5 -> 3 | I13: DEFAULT | J13: ='Valeur Info Imparfaite'!$D$17 -> 0 | L13: 1,0,1,3,14,18,22,2,0,0 | M13: 0 | O13: ='Valeur Info Imparfaite'!$E$16 -> Météo | P13: FALSE
A14: ='Valeur Info Imparfaite'!$E$27 -> 50 | B14: 50 litres | C14: 0 | H14: ='Valeur Info Imparfaite'!$C$5 -> 3 | I14: DEFAULT | J14: ='Valeur Info Imparfaite'!$D$27 -> 50 | L14: 1,0,1,3,10,11,12,2,0,0 | M14: 0 | O14: ='Valeur Info Imparfaite'!$E$26 -> Météo | P14: FALSE
A15: ='Valeur Info Imparfaite'!$E$35 -> 66.666667 | B15: 100 litres | C15: 0 | H15: ='Valeur Info Imparfaite'!$C$5 -> 3 | I15: DEFAULT | J15: ='Valeur Info Imparfaite'!$D$35 -> 100 | L15: 1,0,1,3,13,19,20,2,0,0 | M15: 0 | O15: ='Valeur Info Imparfaite'!$E$34 -> Météo | P15: FALSE
A16: ='Valeur Info Imparfaite'!$D$51 -> 0 | B16: Non-clémente | C16: 0 | H16: ='Valeur Info Imparfaite'!$C$4 -> 100 | I16: DEFAULT | J16: ='Valeur Info Imparfaite'!$C$51 -> 0 | K16: ='Valeur Info Imparfaite'!$C$50 -> 0.55 | L16: 2,0,1,3,7,16,17,1,0,0 | M16: 0 | O16: ='Valeur Info Imparfaite'!$D$50 -> Production | P16: FALSE
A17: ='Valeur Info Imparfaite'!$E$45 -> 0 | B17: 0 litre | C17: 0 | H17: ='Valeur Info Imparfaite'!$C$5 -> 3 | I17: DEFAULT | J17: ='Valeur Info Imparfaite'!$D$45 -> 0 | L17: 1,0,1,3,8,9,15,6,0,0 | M17: 0 | O17: ='Valeur Info Imparfaite'!$E$44 -> Météo | P17: FALSE
A18: ='Valeur Info Imparfaite'!$F$43 -> 0 | B18: Ensoleillé | C18: 0 | H18: DEFAULT | I18: DEFAULT | J18: ='Valeur Info Imparfaite'!$E$43 -> 1 | K18: ='Valeur Info Imparfaite'!$E$42 -> 0 | L18: 4,0,1,0,7,0,0 | M18: 0 | P18: FALSE
A19: ='Valeur Info Imparfaite'!$F$47 -> 0 | B19: Nuageux | C19: 0 | H19: DEFAULT | I19: DEFAULT | J19: ='Valeur Info Imparfaite'!$E$47 -> 2 | K19: ='Valeur Info Imparfaite'!$E$46 -> 0.27272727 | L19: 4,0,1,0,7,0,0 | M19: 0 | P19: FALSE
A20: ='Valeur Info Imparfaite'!$F$25 -> 50 | B20: Ensoleillé | C20: 0 | H20: DEFAULT | I20: DEFAULT | J20: ='Valeur Info Imparfaite'!$E$25 -> 1 | K20: ='Valeur Info Imparfaite'!$E$24 -> 0.66666667 | L20: 4,0,1,0,4,0,0 | M20: 0 | P20: FALSE
A21: ='Valeur Info Imparfaite'!$F$29 -> 50 | B21: Nuageux | C21: 0 | H21: DEFAULT | I21: DEFAULT | J21: ='Valeur Info Imparfaite'!$E$29 -> 2 | K21: ='Valeur Info Imparfaite'!$E$28 -> 0.33333333 | L21: 4,0,1,0,4,0,0 | M21: 0 | P21: FALSE
A22: ='Valeur Info Imparfaite'!$F$31 -> -50 | B22: Averse | C22: 0 | H22: DEFAULT | I22: DEFAULT | J22: ='Valeur Info Imparfaite'!$E$31 -> 3 | K22: ='Valeur Info Imparfaite'!$E$30 -> 0 | L22: 4,0,1,0,4,0,0 | M22: 0 | P22: FALSE
A23: ='Valeur Info Imparfaite'!$F$33 -> 100 | B23: Ensoleillé | C23: 0 | H23: DEFAULT | I23: DEFAULT | J23: ='Valeur Info Imparfaite'!$E$33 -> 1 | K23: ='Valeur Info Imparfaite'!$E$32 -> 0.66666667 | L23: 4,0,1,0,5,0,0 | M23: 0 | P23: FALSE
A24: ='Valeur Info Imparfaite'!$F$15 -> 0 | B24: Ensoleillé | C24: 0 | H24: DEFAULT | I24: DEFAULT | J24: ='Valeur Info Imparfaite'!$E$15 -> 1 | K24: ='Valeur Info Imparfaite'!$E$14 -> 0.66666667 | L24: 4,0,1,0,3,0,0 | M24: 0 | P24: FALSE
A25: ='Valeur Info Imparfaite'!$F$49 -> 0 | B25: Averse | C25: 0 | H25: DEFAULT | I25: DEFAULT | J25: ='Valeur Info Imparfaite'!$E$49 -> 3 | K25: ='Valeur Info Imparfaite'!$E$48 -> 0.72727273 | L25: 4,0,1,0,7,0,0 | M25: 0 | P25: FALSE
A26: ='Valeur Info Imparfaite'!$E$55 -> -22.727273 | B26: 50 litres | C26: 0 | H26: ='Valeur Info Imparfaite'!$C$5 -> 3 | I26: DEFAULT | J26: ='Valeur Info Imparfaite'!$D$55 -> 50 | L26: 1,0,1,3,21,23,24,6,0,0 | M26: 0 | O26: ='Valeur Info Imparfaite'!$E$54 -> Météo | P26: FALSE
A27: ='Valeur Info Imparfaite'!$E$63 -> -72.727273 | B27: 100 litres | C27: 0 | H27: ='Valeur Info Imparfaite'!$C$5 -> 3 | I27: DEFAULT | J27: ='Valeur Info Imparfaite'!$D$63 -> 100 | L27: 1,0,1,3,25,26,27,6,0,0 | M27: 0 | O27: ='Valeur Info Imparfaite'!$E$62 -> Météo | P27: FALSE
A28: ='Valeur Info Imparfaite'!$F$19 -> 0 | B28: Nuageux | C28: 0 | H28: DEFAULT | I28: DEFAULT | J28: ='Valeur Info Imparfaite'!$E$19 -> 2 | K28: ='Valeur Info Imparfaite'!$E$18 -> 0.33333333 | L28: 4,0,1,0,3,0,0 | M28: 0 | P28: FALSE
A29: ='Valeur Info Imparfaite'!$F$37 -> 0 | B29: Nuageux | C29: 0 | H29: DEFAULT | I29: DEFAULT | J29: ='Valeur Info Imparfaite'!$E$37 -> 2 | K29: ='Valeur Info Imparfaite'!$E$36 -> 0.33333333 | L29: 4,0,1,0,5,0,0 | M29: 0 | P29: FALSE
A30: ='Valeur Info Imparfaite'!$F$39 -> -100 | B30: Averse | C30: 0 | H30: DEFAULT | I30: DEFAULT | J30: ='Valeur Info Imparfaite'!$E$39 -> 3 | K30: ='Valeur Info Imparfaite'!$E$38 -> 0 | L30: 4,0,1,0,5,0,0 | M30: 0 | P30: FALSE
A31: ='Valeur Info Imparfaite'!$F$53 -> 50 | B31: Ensoleillé | C31: 0 | H31: DEFAULT | I31: DEFAULT | J31: ='Valeur Info Imparfaite'!$E$53 -> 1 | K31: ='Valeur Info Imparfaite'!$E$52 -> 0 | L31: 4,0,1,0,16,0,0 | M31: 0 | P31: FALSE
A32: ='Valeur Info Imparfaite'!$F$21 -> 0 | B32: Averse | C32: 0 | H32: DEFAULT | I32: DEFAULT | J32: ='Valeur Info Imparfaite'!$E$21 -> 3 | K32: ='Valeur Info Imparfaite'!$E$20 -> 0 | L32: 4,0,1,0,3,0,0 | M32: 0 | P32: FALSE
A33: ='Valeur Info Imparfaite'!$F$57 -> 50 | B33: Nuageux | C33: 0 | H33: DEFAULT | I33: DEFAULT | J33: ='Valeur Info Imparfaite'!$E$57 -> 2 | K33: ='Valeur Info Imparfaite'!$E$56 -> 0.27272727 | L33: 4,0,1,0,16,0,0 | M33: 0 | P33: FALSE
A34: ='Valeur Info Imparfaite'!$F$59 -> -50 | B34: Averse | C34: 0 | H34: DEFAULT | I34: DEFAULT | J34: ='Valeur Info Imparfaite'!$E$59 -> 3 | K34: ='Valeur Info Imparfaite'!$E$58 -> 0.72727273 | L34: 4,0,1,0,16,0,0 | M34: 0 | P34: FALSE
A35: ='Valeur Info Imparfaite'!$F$61 -> 100 | B35: Ensoleillé | C35: 0 | H35: DEFAULT | I35: DEFAULT | J35: ='Valeur Info Imparfaite'!$E$61 -> 1 | K35: ='Valeur Info Imparfaite'!$E$60 -> 0 | L35: 4,0,1,0,17,0,0 | M35: 0 | P35: FALSE
A36: ='Valeur Info Imparfaite'!$F$65 -> 0 | B36: Nuageux | C36: 0 | H36: DEFAULT | I36: DEFAULT | J36: ='Valeur Info Imparfaite'!$E$65 -> 2 | K36: ='Valeur Info Imparfaite'!$E$64 -> 0.27272727 | L36: 4,0,1,0,17,0,0 | M36: 0 | P36: FALSE
A37: ='Valeur Info Imparfaite'!$F$67 -> -100 | B37: Averse | C37: 0 | H37: DEFAULT | I37: DEFAULT | J37: ='Valeur Info Imparfaite'!$E$67 -> 3 | K37: ='Valeur Info Imparfaite'!$E$66 -> 0.72727273 | L37: 4,0,1,0,17,0,0 | M37: 0 | P37: FALSE

Sheet Statistiques
A2: Statistiques à propos de la qualité des prévisions de l'expert
B4: Observations | C4: Prévision | D4: Réalisation | F4: Fréquences
B5: #1-#10 | C5: Clémente | D5: Ensoleillé | F5: P(Clémente) | G5: =7/10 -> 0.7 | I5: P(Ensoleillé) | J5: =5/10 -> 0.5
B6: #11-#20 | C6: Clémente | D6: Ensoleillé | F6: P(Ensoleillé|Clémente) | G6: =5/7 -> 0.71428571 | I6: P(Nuageux) | J6: =4/10 -> 0.4
B7: #21-#30 | C7: Clémente | D7: Ensoleillé | F7: P(Nuageux|Clémente) | G7: =2/7 -> 0.28571429 | I7: P(Averse) | J7: =1/10 -> 0.1
B8: #31-#40 | C8: Clémente | D8: Ensoleillé | F8: P(Averse|Clémente) | G8: =0 -> 0 | I8: P(Clémente|Ensoleillé) | J8: =1 -> 1
B9: #41-#50 | C9: Clémente | D9: Ensoleillé | F9: P(Ensoleillé|Non-clémente) | G9: =0 -> 0 | I9: P(Clémente|Nuageux) | J9: =1/2 -> 0.5
B10: #51-#60 | C10: Clémente | D10: Nuageux | F10: P(Nuageux|Non-clémente) | G10: =2/3 -> 0.66666667 | I10: P(Clémente|Averse) | J10: =0 -> 0
B11: #61-#70 | C11: Clémente | D11: Nuageux | F11: P(Averse|Non-clémente) | G11: =1/3 -> 0.33333333
B12: #71-#80 | C12: Non-Clémente | D12: Nuageux
B13: #81-#90 | C13: Non-Clémente | D13: Nuageux
B14: #91-#100 | C14: Non-Clémente | D14: Averse
A16: Pour faire la révision Bayesienne:
A17: 1) sélectionner la cellule "météo"
A18: 2) Appuyer sur "Bayesian Revision"
A19: 3) Sélectionner "Ok"
D21: 1 | E21: =_xll.PTreeNodeProbability(treeCalc_6!$F$2,5) -> 0.3
D22: 0 | E22: =_xll.PTreeNodeValue(treeCalc_6!$F$2,5) -> 0
C23: 0.3 | D23: Prévision
C24: 0 | D24: =_xll.PTreeNodeValue(treeCalc_6!$F$2,2) -> 0
D25: 0 | E25: =_xll.PTreeNodeProbability(treeCalc_6!$F$2,6) -> 0
D26: 0 | E26: =_xll.PTreeNodeValue(treeCalc_6!$F$2,6) -> 0
C27: Météo
C28: =_xll.PTreeNodeValue(treeCalc_6!$F$2,1) -> 0
D29: 0.5 | E29: =_xll.PTreeNodeProbability(treeCalc_6!$F$2,7) -> 0.15
D30: 0 | E30: =_xll.PTreeNodeValue(treeCalc_6!$F$2,7) -> 0
C31: 0.3 | D31: Prévision
C32: 0 | D32: =_xll.PTreeNodeValue(treeCalc_6!$F$2,3) -> 0
D33: 0.5 | E33: =_xll.PTreeNodeProbability(treeCalc_6!$F$2,8) -> 0.15
D34: 0 | E34: =_xll.PTreeNodeValue(treeCalc_6!$F$2,8) -> 0
D35: 0 | E35: =_xll.PTreeNodeProbability(treeCalc_6!$F$2,9) -> 0
D36: 0 | E36: =_xll.PTreeNodeValue(treeCalc_6!$F$2,9) -> 0
C37: 0.4 | D37: Prévision
C38: 0 | D38: =_xll.PTreeNodeValue(treeCalc_6!$F$2,4) -> 0
D39: 1 | E39: =_xll.PTreeNodeProbability(treeCalc_6!$F$2,10) -> 0.4
D40: 0 | E40: =_xll.PTreeNodeValue(treeCalc_6!$F$2,10) -> 0
D47: 0.66666667 | E47: =_xll.PTreeNodeProbability(treeCalc_7!$F$2,6) -> 0.3
D48: 0 | E48: =_xll.PTreeNodeValue(treeCalc_7!$F$2,6) -> 0
D49: 0.33333333 | E49: =_xll.PTreeNodeProbability(treeCalc_7!$F$2,4) -> 0.15
D50: 0 | E50: =_xll.PTreeNodeValue(treeCalc_7!$F$2,4) -> 0
...

Sheet Valeur Info Imparfaite
H1: Théorème de Bayes
B2: Prix de vente ($/litre) | C2: 2 | J2: Info=Clémente | M2: Info = Non-clémente
B3: Coûts prod. ($/litre) | C3: 1 | H3: État | J3: P(Info) | K3: P(État & Info) | L3: P(État| Info) | M3: P(Info) | N3: P(État & Info) | O3: P(État| Info)
B4: Litres produits | C4: 100 | E4: Valeur espérée sans info | F4: =Standard!C23 -> 10 | H4: Ensoleillé | I4: =0.3 -> 0.3 | J4: =Statistiques!J8 -> 1 | K4: =J4*I4 -> 0.3 | L4: =K4/$K$7 -> 0.66666667 | M4: =1-J4 -> 0 | N4: =M4*I4 -> 0 | O4: =N4/$N$7 -> 0
B5: Météo (id) | C5: 3 | E5: Valeur espérée avec info | F5: =C41 -> 30 | H5: Nuageux | I5: 0.3 | J5: =Statistiques!J9 -> 0.5 | K5: =J5*I5 -> 0.15 | L5: =K5/$K$7 -> 0.33333333 | M5: =1-J5 -> 0.5 | N5: =M5*I5 -> 0.15 | O5: =N5/$N$7 -> 0.27272727
B6: Météo (type) | C6: =VLOOKUP(C5,Meteo!A4:E6,2,FALSE) -> Averse | E6: Valeur de l'info | F6: =F5-F4 -> 20 | H6: Averse | I6: 0.4 | J6: =Statistiques!J10 -> 0 | K6: =J6*I6 -> 0 | L6: =K6/$K$7 -> 0 | M6: =1-J6 -> 1 | N6: =M6*I6 -> 0.4 | O6: =N6/$N$7 -> 0.72727273
B7: Demande | C7: =VLOOKUP(C5,Meteo!A4:E6,5) -> 0 | J7: P(Info)= | K7: =SUM(K4:K6) -> 0.45 | M7: P(Info)= | N7: =SUM(N4:N6) -> 0.55
B8: Revenus | C8: =MIN(C4,C7)*C2 -> 0
B9: Couts | C9: =C4*C3 -> 100
B10: Profits | C10: =C8-C9 -> -100
E14: =$L$4 -> 0.66666667 | F14: =_xll.PTreeNodeProbability(treeCalc_3!$F$2,14) -> 0
E15: 1 | F15: =_xll.PTreeNodeValue(treeCalc_3!$F$2,14) -> 0
D16: =_xll.PTreeNodeDecision(treeCalc_3!$F$2,3) -> FALSE | E16: Météo
D17: 0 | E17: =_xll.PTreeNodeValue(treeCalc_3!$F$2,3) -> 0
E18: =$L$5 -> 0.33333333 | F18: =_xll.PTreeNodeProbability(treeCalc_3!$F$2,18) -> 0
E19: 2 | F19: =_xll.PTreeNodeValue(treeCalc_3!$F$2,18) -> 0
E20: =$L$6 -> 0 | F20: =_xll.PTreeNodeProbability(treeCalc_3!$F$2,22) -> 0
E21: 3 | F21: =_xll.PTreeNodeValue(treeCalc_3!$F$2,22) -> 0
C22: =K7 -> 0.45 | D22: Production
D23: =_xll.PTreeNodeValue(treeCalc_3!$F$2,2) -> 66.666667
E24: =$L$4 -> 0.66666667 | F24: =_xll.PTreeNodeProbability(treeCalc_3!$F$2,10) -> 0
E25: 1 | F25: =_xll.PTreeNodeValue(treeCalc_3!$F$2,10) -> 50
D26: =_xll.PTreeNodeDecision(treeCalc_3!$F$2,4) -> FALSE | E26: Météo
D27: 50 | E27: =_xll.PTreeNodeValue(treeCalc_3!$F$2,4) -> 50
E28: =$L$5 -> 0.33333333 | F28: =_xll.PTreeNodeProbability(treeCalc_3!$F$2,11) -> 0
E29: 2 | F29: =_xll.PTreeNodeValue(treeCalc_3!$F$2,11) -> 50
E30: =$L$6 -> 0 | F30: =_xll.PTreeNodeProbability(treeCalc_3!$F$2,12) -> 0
E31: 3 | F31: =_xll.PTreeNodeValue(treeCalc_3!$F$2,12) -> -50
E32: =$L$4 -> 0.66666667 | F32: =_xll.PTreeNodeProbability(treeCalc_3!$F$2,13) -> 0.3
E33: 1 | F33: =_xll.PTreeNodeValue(treeCalc_3!$F$2,13) -> 100
D34: =_xll.PTreeNodeDecision(treeCalc_3!$F$2,5) -> TRUE | E34: Météo
D35: 100 | E35: =_xll.PTreeNodeValue(treeCalc_3!$F$2,5) -> 66.666667
E36: =$L$5 -> 0.33333333 | F36: =_xll.PTreeNodeProbability(treeCalc_3!$F$2,19) -> 0.15
E37: 2 | F37: =_xll.PTreeNodeValue(treeCalc_3!$F$2,19) -> 0
E38: =$L$6 -> 0 | F38: =_xll.PTreeNodeProbability(treeCalc_3!$F$2,20) -> 0
E39: 3 | F39: =_xll.PTreeNodeValue(treeCalc_3!$F$2,20) -> -100
C40: Prévision expert
C41: =_xll.PTreeNodeValue(treeCalc_3!$F$2,1) -> 30
E42: =$O$4 -> 0 | F42: =_xll.PTreeNodeProbability(treeCalc_3!$F$2,8) -> 0
E43: 1 | F43: =_xll.PTreeNodeValue(treeCalc_3!$F$2,8) -> 0
...

Sheet treeCalc_5
A1: Name | B1: Stand Limonade (2) (2) (2) (2) | E1: Ptree1 Compatibility | F1: 3 | H1: Output Label | K1: R-Value Ref. | L1: 100
A2: SheetRef | B2: ='Valeur Info Imp. (erreur 2)'!#REF! -> #REF! | E2: Eval. Function | F2: =_xll.PTreeEvaluate5(B3,$L$11:$L$52,$J$11:$J$52,$K$11:$K$52,$N$11:$N$52,$G$11:$G$52,,L1) -> 2907671
A3: GenInfo | B3: -1,5,1,-1,0,Exponential, 0,0,-1,0,-1,-1,.0001 | E3: Creation Version | F3: 5.7.1 | H3: Output Value NF | I3: <NF>
A4: Def. Link | B4: ='Valeur Info Imp. (erreur 2)'!$C$10 -> -100 | E4: Required Version | F4: 5.0.0 | H4: Output Prob NF | I4: Automatic
A5: EXT REFS | B5: 0 | D5: 0 | E5: Recommended Version | F5: 5.0.0 | H5: Input Value NF | I5: <NF>
A6: Def. Form | E6: Last Modified By Version | F6: 7.6.1 | H6: Input Prob NF | I6: Automatic
A7: Calc Macro | F7: 28235E12
A8: Highest# | B8: 42
A10: Anchor Cell | B10: Branch Name | C10: bformtype | D10: valformula | E10: pbformula | F10: distribution | G10: cumPayoffFunction | H10: link | I10: ENDNODEFORMULA | J10: VAL | K10: PB | L10: GenInfo | M10: IntRefs | N10: RefRefs | O10: NodeNames | P10: Collapsed
A11: ='Valeur Info Imp. (erreur 2)'!$C$33 -> 45 | B11: =B1 -> Stand Limonade (2) (2) (2) (2) | C11: 0 | H11: ='Valeur Info Imp. (erreur 2)'!$C$5 -> 3 | I11: DEFAULT | J11: ='Valeur Info Imp. (erreur 2)'!$B$33 -> 0 | K11: ='Valeur Info Imp. (erreur 2)'!$B$32 -> 0 | L11: 1,0,1,3,2,6,42,0,0,0 | M11: 0 | O11: ='Valeur Info Imp. (erreur 2)'!$C$32 -> Météo | P11: FALSE
A12: ='Valeur Info Imp. (erreur 2)'!$D$23 -> 100 | B12: Ensoleillé | C12: 0 | I12: DEFAULT | J12: ='Valeur Info Imp. (erreur 2)'!$C$23 -> 1 | K12: ='Valeur Info Imp. (erreur 2)'!$C$22 -> 0.3 | L12: 1,0,1,2,3,29,1,0,0 | M12: 0 | O12: ='Valeur Info Imp. (erreur 2)'!$D$22 -> Prévision expert | P12: FALSE
A13: ='Valeur Info Imp. (erreur 2)'!$E$17 -> 100 | B13: Clémente | C13: 0 | H13: ='Valeur Info Imp. (erreur 2)'!$C$4 -> 100 | I13: DEFAULT | J13: ='Valeur Info Imp. (erreur 2)'!$D$17 -> 0 | K13: ='Valeur Info Imp. (erreur 2)'!$D$16 -> 1 | L13: 2,0,1,3,4,12,19,2,0,0 | M13: 0 | O13: ='Valeur Info Imp. (erreur 2)'!$E$16 -> Production | P13: FALSE
A14: ='Valeur Info Imp. (erreur 2)'!$F$15 -> 0 | B14: 0 litre | C14: 0 | H14: DEFAULT | I14: DEFAULT | J14: ='Valeur Info Imp. (erreur 2)'!$E$15 -> 0 | L14: 4,0,1,0,3,0,0 | M14: 0 | P14: FALSE
A15: ='Valeur Info Imp. (erreur 2)'!$F$25 -> 0 | B15: 0 litre | C15: 0 | H15: DEFAULT | I15: DEFAULT | J15: ='Valeur Info Imp. (erreur 2)'!$E$25 -> 0 | L15: 4,0,1,0,29,0,0 | M15: 0 | P15: FALSE
A16: ='Valeur Info Imp. (erreur 2)'!$D$43 -> 50 | B16: Nuageux | C16: 0 | I16: DEFAULT | J16: ='Valeur Info Imp. (erreur 2)'!$C$43 -> 2 | K16: ='Valeur Info Imp. (erreur 2)'!$C$42 -> 0.3 | L16: 1,0,1,2,7,14,1,0,0 | M16: 0 | O16: ='Valeur Info Imp. (erreur 2)'!$D$42 -> Prévision expert | P16: FALSE
A17: ='Valeur Info Imp. (erreur 2)'!$E$37 -> 50 | B17: Clémente | C17: 0 | H17: ='Valeur Info Imp. (erreur 2)'!$C$4 -> 100 | I17: DEFAULT | J17: ='Valeur Info Imp. (erreur 2)'!$D$37 -> 0 | K17: ='Valeur Info Imp. (erreur 2)'!$D$36 -> 0.5 | L17: 2,0,1,3,8,9,13,6,0,0 | M17: 0 | O17: ='Valeur Info Imp. (erreur 2)'!$E$36 -> Production | P17: FALSE
A18: ='Valeur Info Imp. (erreur 2)'!$F$35 -> 0 | B18: 0 litre | C18: 0 | H18: DEFAULT | I18: DEFAULT | J18: ='Valeur Info Imp. (erreur 2)'!$E$35 -> 0 | L18: 4,0,1,0,7,0,0 | M18: 0 | P18: FALSE
A19: ='Valeur Info Imp. (erreur 2)'!$F$39 -> 50 | B19: 50 litres | C19: 0 | H19: DEFAULT | I19: DEFAULT | J19: ='Valeur Info Imp. (erreur 2)'!$E$39 -> 50 | L19: 4,0,1,0,7,0,0 | M19: 0 | P19: FALSE
A20: ='Valeur Info Imp. (erreur 2)'!$F$29 -> 50 | B20: 50 litres | C20: 0 | H20: DEFAULT | I20: DEFAULT | J20: ='Valeur Info Imp. (erreur 2)'!$E$29 -> 50 | L20: 4,0,1,0,29,0,0 | M20: 0 | P20: FALSE
A21: ='Valeur Info Imp. (erreur 2)'!$F$31 -> 100 | B21: 100 litres | C21: 0 | H21: DEFAULT | I21: DEFAULT | J21: ='Valeur Info Imp. (erreur 2)'!$E$31 -> 100 | L21: 4,0,1,0,29,0,0 | M21: 0 | P21: FALSE
A22: ='Valeur Info Imp. (erreur 2)'!$F$19 -> 50 | B22: 50 litres | C22: 0 | H22: DEFAULT | I22: DEFAULT | J22: ='Valeur Info Imp. (erreur 2)'!$E$19 -> 50 | L22: 4,0,1,0,3,0,0 | M22: 0 | P22: FALSE
A23: ='Valeur Info Imp. (erreur 2)'!$F$41 -> 0 | B23: 100 litres | C23: 0 | H23: DEFAULT | I23: DEFAULT | J23: ='Valeur Info Imp. (erreur 2)'!$E$41 -> 100 | L23: 4,0,1,0,7,0,0 | M23: 0 | P23: FALSE
A24: ='Valeur Info Imp. (erreur 2)'!$E$47 -> 50 | B24: Non-clémente | C24: 0 | H24: ='Valeur Info Imp. (erreur 2)'!$C$4 -> 100 | I24: DEFAULT | J24: ='Valeur Info Imp. (erreur 2)'!$D$47 -> 0 | K24: ='Valeur Info Imp. (erreur 2)'!$D$46 -> 0.5 | L24: 2,0,1,3,15,16,17,6,0,0 | M24: 0 | O24: ='Valeur Info Imp. (erreur 2)'!$E$46 -> Production | P24: FALSE
A25: ='Valeur Info Imp. (erreur 2)'!$F$45 -> 0 | B25: 0 litre | C25: 0 | H25: DEFAULT | I25: DEFAULT | J25: ='Valeur Info Imp. (erreur 2)'!$E$45 -> 0 | L25: 4,0,1,0,14,0,0 | M25: 0 | P25: FALSE
A26: ='Valeur Info Imp. (erreur 2)'!$F$49 -> 50 | B26: 50 litres | C26: 0 | H26: DEFAULT | I26: DEFAULT | J26: ='Valeur Info Imp. (erreur 2)'!$E$49 -> 50 | L26: 4,0,1,0,14,0,0 | M26: 0 | P26: FALSE
A27: ='Valeur Info Imp. (erreur 2)'!$F$51 -> 0 | B27: 100 litres | C27: 0 | H27: DEFAULT | I27: DEFAULT | J27: ='Valeur Info Imp. (erreur 2)'!$E$51 -> 100 | L27: 4,0,1,0,14,0,0 | M27: 0 | P27: FALSE
A28: ='Valeur Info Imp. (erreur 2)'!$E$55 -> 0 | B28: Clémente | C28: 0 | H28: ='Valeur Info Imp. (erreur 2)'!$C$4 -> 100 | I28: DEFAULT | J28: ='Valeur Info Imp. (erreur 2)'!$D$55 -> 0 | K28: ='Valeur Info Imp. (erreur 2)'!$D$54 -> 0 | L28: 2,0,1,3,20,21,22,42,0,0 | M28: 0 | O28: ='Valeur Info Imp. (erreur 2)'!$E$54 -> Production | P28: FALSE
A29: ='Valeur Info Imp. (erreur 2)'!$F$21 -> 100 | B29: 100 litres | C29: 0 | H29: DEFAULT | I29: DEFAULT | J29: ='Valeur Info Imp. (erreur 2)'!$E$21 -> 100 | L29: 4,0,1,0,3,0,0 | M29: 0 | P29: FALSE
A30: ='Valeur Info Imp. (erreur 2)'!$F$53 -> 0 | B30: 0 litre | C30: 0 | H30: DEFAULT | I30: DEFAULT | J30: ='Valeur Info Imp. (erreur 2)'!$E$53 -> 0 | L30: 4,0,1,0,18,0,0 | M30: 0 | P30: FALSE
A31: ='Valeur Info Imp. (erreur 2)'!$F$57 -> -50 | B31: 50 litres | C31: 0 | H31: DEFAULT | I31: DEFAULT | J31: ='Valeur Info Imp. (erreur 2)'!$E$57 -> 50 | L31: 4,0,1,0,18,0,0 | M31: 0 | P31: FALSE
A32: ='Valeur Info Imp. (erreur 2)'!$F$59 -> -100 | B32: 100 litres | C32: 0 | H32: DEFAULT | I32: DEFAULT | J32: ='Valeur Info Imp. (erreur 2)'!$E$59 -> 100 | L32: 4,0,1,0,18,0,0 | M32: 0 | P32: FALSE
A33: ='Valeur Info Imp. (erreur 2)'!$E$65 -> 0 | B33: Non-clémente | C33: 0 | H33: ='Valeur Info Imp. (erreur 2)'!$C$4 -> 100 | I33: DEFAULT | J33: ='Valeur Info Imp. (erreur 2)'!$D$65 -> 0 | K33: ='Valeur Info Imp. (erreur 2)'!$D$64 -> 1 | L33: 2,0,1,3,24,25,26,42,0,0 | M33: 0 | O33: ='Valeur Info Imp. (erreur 2)'!$E$64 -> Production | P33: FALSE
A34: ='Valeur Info Imp. (erreur 2)'!$F$63 -> 0 | B34: 0 litre | C34: 0 | H34: DEFAULT | I34: DEFAULT | J34: ='Valeur Info Imp. (erreur 2)'!$E$63 -> 0 | L34: 4,0,1,0,23,0,0 | M34: 0 | P34: FALSE
A35: ='Valeur Info Imp. (erreur 2)'!$F$67 -> -50 | B35: 50 litres | C35: 0 | H35: DEFAULT | I35: DEFAULT | J35: ='Valeur Info Imp. (erreur 2)'!$E$67 -> 50 | L35: 4,0,1,0,23,0,0 | M35: 0 | P35: FALSE
A36: ='Valeur Info Imp. (erreur 2)'!$F$69 -> -100 | B36: 100 litres | C36: 0 | H36: DEFAULT | I36: DEFAULT | J36: ='Valeur Info Imp. (erreur 2)'!$E$69 -> 100 | L36: 4,0,1,0,23,0,0 | M36: 0 | P36: FALSE
A39: ='Valeur Info Imp. (erreur 2)'!$E$27 -> 100 | B39: Non-clémente | C39: 0 | H39: ='Valeur Info Imp. (erreur 2)'!$C$4 -> 100 | I39: DEFAULT | J39: ='Valeur Info Imp. (erreur 2)'!$D$27 -> 0 | K39: ='Valeur Info Imp. (erreur 2)'!$D$26 -> 0 | L39: 2,0,1,3,5,10,11,2,0,0 | M39: 0 | O39: ='Valeur Info Imp. (erreur 2)'!$E$26 -> Production | P39: FALSE
A52: ='Valeur Info Imp. (erreur 2)'!$D$61 -> 0 | B52: Averse | C52: 0 | I52: DEFAULT | J52: ='Valeur Info Imp. (erreur 2)'!$C$61 -> 3 | K52: ='Valeur Info Imp. (erreur 2)'!$C$60 -> 0.4 | L52: 1,0,1,2,18,23,1,0,0 | M52: 0 | O52: ='Valeur Info Imp. (erreur 2)'!$D$60 -> Prévision expert | P52: FALSE

Sheet treeCalc_4
A1: Name | B1: Stand Limonade (2) (2) (2) | E1: Ptree1 Compatibility | F1: 3 | H1: Output Label | K1: R-Value Ref. | L1: 100
A2: SheetRef | B2: ='Valeur Info Imparfaite (erreur)'!#REF! -> #REF! | E2: Eval. Function | F2: =_xll.PTreeEvaluate5(B3,$L$11:$L$37,$J$11:$J$37,$K$11:$K$37,$N$11:$N$37,$G$11:$G$37,,L1) -> 2856214
A3: GenInfo | B3: -1,4,1,-1,0,Exponential, 0,0,-1,0,-1,-1,.0001 | E3: Creation Version | F3: 5.7.1 | H3: Output Value NF | I3: <NF>
A4: Def. Link | B4: ='Valeur Info Imparfaite (erreur)'!$C$10 -> -100 | E4: Required Version | F4: 5.0.0 | H4: Output Prob NF | I4: Automatic
A5: EXT REFS | B5: 0 | D5: 0 | E5: Recommended Version | F5: 5.0.0 | H5: Input Value NF | I5: <NF>
A6: Def. Form | E6: Last Modified By Version | F6: 7.6.1 | H6: Input Prob NF | I6: Automatic
A7: Calc Macro | F7: 215C1A79
A8: Highest# | B8: 27
A10: Anchor Cell | B10: Branch Name | C10: bformtype | D10: valformula | E10: pbformula | F10: distribution | G10: cumPayoffFunction | H10: link | I10: ENDNODEFORMULA | J10: VAL | K10: PB | L10: GenInfo | M10: IntRefs | N10: RefRefs | O10: NodeNames | P10: Collapsed
A11: ='Valeur Info Imparfaite (erreur)'!$C$41 -> 55 | B11: =B1 -> Stand Limonade (2) (2) (2) | C11: 0 | I11: DEFAULT | J11: ='Valeur Info Imparfaite (erreur)'!$B$41 -> 0 | K11: ='Valeur Info Imparfaite (erreur)'!$B$40 -> 0 | L11: 1,0,1,2,2,6,0,0,0 | M11: 0 | O11: ='Valeur Info Imparfaite (erreur)'!$C$40 -> Prévision expert | P11: FALSE
A12: ='Valeur Info Imparfaite (erreur)'!$D$23 -> 71.428571 | B12: Clémente | C12: 0 | H12: ='Valeur Info Imparfaite (erreur)'!$C$4 -> 100 | I12: DEFAULT | J12: ='Valeur Info Imparfaite (erreur)'!$C$23 -> 0 | K12: ='Valeur Info Imparfaite (erreur)'!$C$22 -> 0.7 | L12: 2,0,1,3,3,4,5,1,0,0 | M12: 0 | O12: ='Valeur Info Imparfaite (erreur)'!$D$22 -> Production | P12: FALSE
A13: ='Valeur Info Imparfaite (erreur)'!$E$17 -> 0 | B13: 0 litre | C13: 0 | H13: ='Valeur Info Imparfaite (erreur)'!$C$5 -> 3 | I13: DEFAULT | J13: ='Valeur Info Imparfaite (erreur)'!$D$17 -> 0 | L13: 1,0,1,3,14,18,22,2,0,0 | M13: 0 | O13: ='Valeur Info Imparfaite (erreur)'!$E$16 -> Météo | P13: FALSE
A14: ='Valeur Info Imparfaite (erreur)'!$E$27 -> 50 | B14: 50 litres | C14: 0 | H14: ='Valeur Info Imparfaite (erreur)'!$C$5 -> 3 | I14: DEFAULT | J14: ='Valeur Info Imparfaite (erreur)'!$D$27 -> 50 | L14: 1,0,1,3,10,11,12,2,0,0 | M14: 0 | O14: ='Valeur Info Imparfaite (erreur)'!$E$26 -> Météo | P14: FALSE
A15: ='Valeur Info Imparfaite (erreur)'!$E$35 -> 71.428571 | B15: 100 litres | C15: 0 | H15: ='Valeur Info Imparfaite (erreur)'!$C$5 -> 3 | I15: DEFAULT | J15: ='Valeur Info Imparfaite (erreur)'!$D$35 -> 100 | L15: 1,0,1,3,13,19,20,2,0,0 | M15: 0 | O15: ='Valeur Info Imparfaite (erreur)'!$E$34 -> Météo | P15: FALSE
A16: ='Valeur Info Imparfaite (erreur)'!$D$51 -> 16.666667 | B16: Non-clémente | C16: 0 | H16: ='Valeur Info Imparfaite (erreur)'!$C$4 -> 100 | I16: DEFAULT | J16: ='Valeur Info Imparfaite (erreur)'!$C$51 -> 0 | K16: ='Valeur Info Imparfaite (erreur)'!$C$50 -> 0.3 | L16: 2,0,1,3,7,16,17,1,0,0 | M16: 0 | O16: ='Valeur Info Imparfaite (erreur)'!$D$50 -> Production | P16: FALSE
A17: ='Valeur Info Imparfaite (erreur)'!$E$45 -> 0 | B17: 0 litre | C17: 0 | H17: ='Valeur Info Imparfaite (erreur)'!$C$5 -> 3 | I17: DEFAULT | J17: ='Valeur Info Imparfaite (erreur)'!$D$45 -> 0 | L17: 1,0,1,3,8,9,15,6,0,0 | M17: 0 | O17: ='Valeur Info Imparfaite (erreur)'!$E$44 -> Météo | P17: FALSE
A18: ='Valeur Info Imparfaite (erreur)'!$F$43 -> 0 | B18: Ensoleillé | C18: 0 | H18: DEFAULT | I18: DEFAULT | J18: ='Valeur Info Imparfaite (erreur)'!$E$43 -> 1 | K18: ='Valeur Info Imparfaite (erreur)'!$E$42 -> 0 | L18: 4,0,1,0,7,0,0 | M18: 0 | P18: FALSE
A19: ='Valeur Info Imparfaite (erreur)'!$F$47 -> 0 | B19: Nuageux | C19: 0 | H19: DEFAULT | I19: DEFAULT | J19: ='Valeur Info Imparfaite (erreur)'!$E$47 -> 2 | K19: ='Valeur Info Imparfaite (erreur)'!$E$46 -> 0.66666667 | L19: 4,0,1,0,7,0,0 | M19: 0 | P19: FALSE
A20: ='Valeur Info Imparfaite (erreur)'!$F$25 -> 50 | B20: Ensoleillé | C20: 0 | H20: DEFAULT | I20: DEFAULT | J20: ='Valeur Info Imparfaite (erreur)'!$E$25 -> 1 | K20: ='Valeur Info Imparfaite (erreur)'!$E$24 -> 0.71428571 | L20: 4,0,1,0,4,0,0 | M20: 0 | P20: FALSE
A21: ='Valeur Info Imparfaite (erreur)'!$F$29 -> 50 | B21: Nuageux | C21: 0 | H21: DEFAULT | I21: DEFAULT | J21: ='Valeur Info Imparfaite (erreur)'!$E$29 -> 2 | K21: ='Valeur Info Imparfaite (erreur)'!$E$28 -> 0.28571429 | L21: 4,0,1,0,4,0,0 | M21: 0 | P21: FALSE
A22: ='Valeur Info Imparfaite (erreur)'!$F$31 -> -50 | B22: Averse | C22: 0 | H22: DEFAULT | I22: DEFAULT | J22: ='Valeur Info Imparfaite (erreur)'!$E$31 -> 3 | K22: ='Valeur Info Imparfaite (erreur)'!$E$30 -> 0 | L22: 4,0,1,0,4,0,0 | M22: 0 | P22: FALSE
A23: ='Valeur Info Imparfaite (erreur)'!$F$33 -> 100 | B23: Ensoleillé | C23: 0 | H23: DEFAULT | I23: DEFAULT | J23: ='Valeur Info Imparfaite (erreur)'!$E$33 -> 1 | K23: ='Valeur Info Imparfaite (erreur)'!$E$32 -> 0.71428571 | L23: 4,0,1,0,5,0,0 | M23: 0 | P23: FALSE
A24: ='Valeur Info Imparfaite (erreur)'!$F$15 -> 0 | B24: Ensoleillé | C24: 0 | H24: DEFAULT | I24: DEFAULT | J24: ='Valeur Info Imparfaite (erreur)'!$E$15 -> 1 | K24: ='Valeur Info Imparfaite (erreur)'!$E$14 -> 0.71428571 | L24: 4,0,1,0,3,0,0 | M24: 0 | P24: FALSE
A25: ='Valeur Info Imparfaite (erreur)'!$F$49 -> 0 | B25: Averse | C25: 0 | H25: DEFAULT | I25: DEFAULT | J25: ='Valeur Info Imparfaite (erreur)'!$E$49 -> 3 | K25: ='Valeur Info Imparfaite (erreur)'!$E$48 -> 0.33333333 | L25: 4,0,1,0,7,0,0 | M25: 0 | P25: FALSE
A26: ='Valeur Info Imparfaite (erreur)'!$E$55 -> 16.666667 | B26: 50 litres | C26: 0 | H26: ='Valeur Info Imparfaite (erreur)'!$C$5 -> 3 | I26: DEFAULT | J26: ='Valeur Info Imparfaite (erreur)'!$D$55 -> 50 | L26: 1,0,1,3,21,23,24,6,0,0 | M26: 0 | O26: ='Valeur Info Imparfaite (erreur)'!$E$54 -> Météo | P26: FALSE
A27: ='Valeur Info Imparfaite (erreur)'!$E$63 -> -33.333333 | B27: 100 litres | C27: 0 | H27: ='Valeur Info Imparfaite (erreur)'!$C$5 -> 3 | I27: DEFAULT | J27: ='Valeur Info Imparfaite (erreur)'!$D$63 -> 100 | L27: 1,0,1,3,25,26,27,6,0,0 | M27: 0 | O27: ='Valeur Info Imparfaite (erreur)'!$E$62 -> Météo | P27: FALSE
A28: ='Valeur Info Imparfaite (erreur)'!$F$19 -> 0 | B28: Nuageux | C28: 0 | H28: DEFAULT | I28: DEFAULT | J28: ='Valeur Info Imparfaite (erreur)'!$E$19 -> 2 | K28: ='Valeur Info Imparfaite (erreur)'!$E$18 -> 0.28571429 | L28: 4,0,1,0,3,0,0 | M28: 0 | P28: FALSE
A29: ='Valeur Info Imparfaite (erreur)'!$F$37 -> 0 | B29: Nuageux | C29: 0 | H29: DEFAULT | I29: DEFAULT | J29: ='Valeur Info Imparfaite (erreur)'!$E$37 -> 2 | K29: ='Valeur Info Imparfaite (erreur)'!$E$36 -> 0.28571429 | L29: 4,0,1,0,5,0,0 | M29: 0 | P29: FALSE
A30: ='Valeur Info Imparfaite (erreur)'!$F$39 -> -100 | B30: Averse | C30: 0 | H30: DEFAULT | I30: DEFAULT | J30: ='Valeur Info Imparfaite (erreur)'!$E$39 -> 3 | K30: ='Valeur Info Imparfaite (erreur)'!$E$38 -> 0 | L30: 4,0,1,0,5,0,0 | M30: 0 | P30: FALSE
A31: ='Valeur Info Imparfaite (erreur)'!$F$53 -> 50 | B31: Ensoleillé | C31: 0 | H31: DEFAULT | I31: DEFAULT | J31: ='Valeur Info Imparfaite (erreur)'!$E$53 -> 1 | K31: ='Valeur Info Imparfaite (erreur)'!$E$52 -> 0 | L31: 4,0,1,0,16,0,0 | M31: 0 | P31: FALSE
A32: ='Valeur Info Imparfaite (erreur)'!$F$21 -> 0 | B32: Averse | C32: 0 | H32: DEFAULT | I32: DEFAULT | J32: ='Valeur Info Imparfaite (erreur)'!$E$21 -> 3 | K32: ='Valeur Info Imparfaite (erreur)'!$E$20 -> 0 | L32: 4,0,1,0,3,0,0 | M32: 0 | P32: FALSE
A33: ='Valeur Info Imparfaite (erreur)'!$F$57 -> 50 | B33: Nuageux | C33: 0 | H33: DEFAULT | I33: DEFAULT | J33: ='Valeur Info Imparfaite (erreur)'!$E$57 -> 2 | K33: ='Valeur Info Imparfaite (erreur)'!$E$56 -> 0.66666667 | L33: 4,0,1,0,16,0,0 | M33: 0 | P33: FALSE
A34: ='Valeur Info Imparfaite (erreur)'!$F$59 -> -50 | B34: Averse | C34: 0 | H34: DEFAULT | I34: DEFAULT | J34: ='Valeur Info Imparfaite (erreur)'!$E$59 -> 3 | K34: ='Valeur Info Imparfaite (erreur)'!$E$58 -> 0.33333333 | L34: 4,0,1,0,16,0,0 | M34: 0 | P34: FALSE
A35: ='Valeur Info Imparfaite (erreur)'!$F$61 -> 100 | B35: Ensoleillé | C35: 0 | H35: DEFAULT | I35: DEFAULT | J35: ='Valeur Info Imparfaite (erreur)'!$E$61 -> 1 | K35: ='Valeur Info Imparfaite (erreur)'!$E$60 -> 0 | L35: 4,0,1,0,17,0,0 | M35: 0 | P35: FALSE
A36: ='Valeur Info Imparfaite (erreur)'!$F$65 -> 0 | B36: Nuageux | C36: 0 | H36: DEFAULT | I36: DEFAULT | J36: ='Valeur Info Imparfaite (erreur)'!$E$65 -> 2 | K36: ='Valeur Info Imparfaite (erreur)'!$E$64 -> 0.66666667 | L36: 4,0,1,0,17,0,0 | M36: 0 | P36: FALSE
A37: ='Valeur Info Imparfaite (erreur)'!$F$67 -> -100 | B37: Averse | C37: 0 | H37: DEFAULT | I37: DEFAULT | J37: ='Valeur Info Imparfaite (erreur)'!$E$67 -> 3 | K37: ='Valeur Info Imparfaite (erreur)'!$E$66 -> 0.33333333 | L37: 4,0,1,0,17,0,0 | M37: 0 | P37: FALSE

Sheet Valeur Info Imparfaite (erreur)
B2: Prix de vente ($/litre) | C2: 2
B3: Coûts prod. ($/litre) | C3: 1
B4: Litres produits | C4: 100 | E4: Valeur espérée sans info | F4: =Standard!C23 -> 10
B5: Météo (id) | C5: 3 | E5: Valeur espérée avec info | F5: =C41 -> 55
B6: Météo (type) | C6: =VLOOKUP(C5,Meteo!A4:E6,2,FALSE) -> Averse | E6: Valeur de l'info | F6: =F5-F4 -> 45
B7: Demande | C7: =VLOOKUP(C5,Meteo!A4:E6,5) -> 0
B8: Revenus | C8: =MIN(C4,C7)*C2 -> 0
B9: Couts | C9: =C4*C3 -> 100
B10: Profits | C10: =C8-C9 -> -100
E14: =Statistiques!$G$6 -> 0.71428571 | F14: =_xll.PTreeNodeProbability(treeCalc_4!$F$2,14) -> 0
E15: 1 | F15: =_xll.PTreeNodeValue(treeCalc_4!$F$2,14) -> 0
D16: =_xll.PTreeNodeDecision(treeCalc_4!$F$2,3) -> FALSE | E16: Météo
D17: 0 | E17: =_xll.PTreeNodeValue(treeCalc_4!$F$2,3) -> 0
E18: =Statistiques!$G$7 -> 0.28571429 | F18: =_xll.PTreeNodeProbability(treeCalc_4!$F$2,18) -> 0
E19: 2 | F19: =_xll.PTreeNodeValue(treeCalc_4!$F$2,18) -> 0
E20: =Statistiques!$G$8 -> 0 | F20: =_xll.PTreeNodeProbability(treeCalc_4!$F$2,22) -> 0
E21: 3 | F21: =_xll.PTreeNodeValue(treeCalc_4!$F$2,22) -> 0
C22: =Statistiques!G5 -> 0.7 | D22: Production
D23: =_xll.PTreeNodeValue(treeCalc_4!$F$2,2) -> 71.428571
E24: =Statistiques!$G$6 -> 0.71428571 | F24: =_xll.PTreeNodeProbability(treeCalc_4!$F$2,10) -> 0
E25: 1 | F25: =_xll.PTreeNodeValue(treeCalc_4!$F$2,10) -> 50
D26: =_xll.PTreeNodeDecision(treeCalc_4!$F$2,4) -> FALSE | E26: Météo
D27: 50 | E27: =_xll.PTreeNodeValue(treeCalc_4!$F$2,4) -> 50
E28: =Statistiques!$G$7 -> 0.28571429 | F28: =_xll.PTreeNodeProbability(treeCalc_4!$F$2,11) -> 0
E29: 2 | F29: =_xll.PTreeNodeValue(treeCalc_4!$F$2,11) -> 50
E30: =Statistiques!$G$8 -> 0 | F30: =_xll.PTreeNodeProbability(treeCalc_4!$F$2,12) -> 0
E31: 3 | F31: =_xll.PTreeNodeValue(treeCalc_4!$F$2,12) -> -50
E32: =Statistiques!$G$6 -> 0.71428571 | F32: =_xll.PTreeNodeProbability(treeCalc_4!$F$2,13) -> 0.5
E33: 1 | F33: =_xll.PTreeNodeValue(treeCalc_4!$F$2,13) -> 100
D34: =_xll.PTreeNodeDecision(treeCalc_4!$F$2,5) -> TRUE | E34: Météo
D35: 100 | E35: =_xll.PTreeNodeValue(treeCalc_4!$F$2,5) -> 71.428571
E36: =Statistiques!$G$7 -> 0.28571429 | F36: =_xll.PTreeNodeProbability(treeCalc_4!$F$2,19) -> 0.2
E37: 2 | F37: =_xll.PTreeNodeValue(treeCalc_4!$F$2,19) -> 0
E38: =Statistiques!$G$8 -> 0 | F38: =_xll.PTreeNodeProbability(treeCalc_4!$F$2,20) -> 0
E39: 3 | F39: =_xll.PTreeNodeValue(treeCalc_4!$F$2,20) -> -100
C40: Prévision expert
C41: =_xll.PTreeNodeValue(treeCalc_4!$F$2,1) -> 55
E42: =Statistiques!$G$9 -> 0 | F42: =_xll.PTreeNodeProbability(treeCalc_4!$F$2,8) -> 0
E43: 1 | F43: =_xll.PTreeNodeValue(treeCalc_4!$F$2,8) -> 0
D44: =_xll.PTreeNodeDecision(treeCalc_4!$F$2,7) -> FALSE | E44: Météo
...

Sheet Valeur Info Imp. (erreur 2)
B2: Prix de vente ($/litre) | C2: 2
B3: Coûts prod. ($/litre) | C3: 1
B4: Litres produits | C4: 100 | E4: Valeur espérée sans info | F4: =Standard!C23 -> 10
B5: Météo (id) | C5: 3 | E5: Valeur espérée avec info | F5: =C33 -> 45
B6: Météo (type) | C6: =VLOOKUP(C5,Meteo!A4:E6,2,FALSE) -> Averse | E6: Valeur de l'info | F6: =F5-F4 -> 35
B7: Demande | C7: =VLOOKUP(C5,Meteo!A4:E6,5) -> 0
B8: Revenus | C8: =MIN(C4,C7)*C2 -> 0
B9: Couts | C9: =C4*C3 -> 100
B10: Profits | C10: =C8-C9 -> -100
E14: =_xll.PTreeNodeDecision(treeCalc_5!$F$2,4) -> FALSE | F14: =_xll.PTreeNodeProbability(treeCalc_5!$F$2,4) -> 0
E15: 0 | F15: =_xll.PTreeNodeValue(treeCalc_5!$F$2,4) -> 0
D16: =Statistiques!$J$8 -> 1 | E16: Production
E17: =_xll.PTreeNodeValue(treeCalc_5!$F$2,3) -> 100
E18: =_xll.PTreeNodeDecision(treeCalc_5!$F$2,12) -> FALSE | F18: =_xll.PTreeNodeProbability(treeCalc_5!$F$2,12) -> 0
E19: 50 | F19: =_xll.PTreeNodeValue(treeCalc_5!$F$2,12) -> 50
E20: =_xll.PTreeNodeDecision(treeCalc_5!$F$2,19) -> TRUE | F20: =_xll.PTreeNodeProbability(treeCalc_5!$F$2,19) -> 0.3
E21: 100 | F21: =_xll.PTreeNodeValue(treeCalc_5!$F$2,19) -> 100
C22: =Meteo!C4 -> 0.3 | D22: Prévision expert
C23: 1 | D23: =_xll.PTreeNodeValue(treeCalc_5!$F$2,2) -> 100
E24: =_xll.PTreeNodeDecision(treeCalc_5!$F$2,5) -> FALSE | F24: =_xll.PTreeNodeProbability(treeCalc_5!$F$2,5) -> 0
E25: 0 | F25: =_xll.PTreeNodeValue(treeCalc_5!$F$2,5) -> 0
D26: =1-D16 -> 0 | E26: Production
E27: =_xll.PTreeNodeValue(treeCalc_5!$F$2,29) -> 100
E28: =_xll.PTreeNodeDecision(treeCalc_5!$F$2,10) -> FALSE | F28: =_xll.PTreeNodeProbability(treeCalc_5!$F$2,10) -> 0
E29: 50 | F29: =_xll.PTreeNodeValue(treeCalc_5!$F$2,10) -> 50
E30: =_xll.PTreeNodeDecision(treeCalc_5!$F$2,11) -> TRUE | F30: =_xll.PTreeNodeProbability(treeCalc_5!$F$2,11) -> 0
E31: 100 | F31: =_xll.PTreeNodeValue(treeCalc_5!$F$2,11) -> 100
C32: Météo
C33: =_xll.PTreeNodeValue(treeCalc_5!$F$2,1) -> 45
E34: =_xll.PTreeNodeDecision(treeCalc_5!$F$2,8) -> FALSE | F34: =_xll.PTreeNodeProbability(treeCalc_5!$F$2,8) -> 0
E35: 0 | F35: =_xll.PTreeNodeValue(treeCalc_5!$F$2,8) -> 0
D36: =Statistiques!$J$9 -> 0.5 | E36: Production
E37: =_xll.PTreeNodeValue(treeCalc_5!$F$2,7) -> 50
E38: =_xll.PTreeNodeDecision(treeCalc_5!$F$2,9) -> TRUE | F38: =_xll.PTreeNodeProbability(treeCalc_5!$F$2,9) -> 0.15
E39: 50 | F39: =_xll.PTreeNodeValue(treeCalc_5!$F$2,9) -> 50
E40: =_xll.PTreeNodeDecision(treeCalc_5!$F$2,13) -> FALSE | F40: =_xll.PTreeNodeProbability(treeCalc_5!$F$2,13) -> 0
E41: 100 | F41: =_xll.PTreeNodeValue(treeCalc_5!$F$2,13) -> 0
C42: =Meteo!C5 -> 0.3 | D42: Prévision expert
C43: 2 | D43: =_xll.PTreeNodeValue(treeCalc_5!$F$2,6) -> 50
E44: =_xll.PTreeNodeDecision(treeCalc_5!$F$2,15) -> FALSE | F44: =_xll.PTreeNodeProbability(treeCalc_5!$F$2,15) -> 0
...

Sheet treeCalc_7
A1: Name | B1: Prévision --> Météo | E1: Ptree1 Compatibility | F1: 3 | H1: Output Label | K1: R-Value Ref. | L1: 100
A2: SheetRef | B2: =Statistiques!#REF! -> #REF! | E2: Eval. Function | F2: =_xll.PTreeEvaluate5(B3,$L$11:$L$20,$J$11:$J$20,$K$11:$K$20,$N$11:$N$20,$G$11:$G$20,,L1) -> 2058649
A3: GenInfo | B3: 0,7,1,0,0,Exponential, 0,0,-1,0,-1,-1,.0001 | E3: Creation Version | F3: 7.6.1 | H3: Output Value NF | I3: <NF>
A4: Def. Link | B4: = | E4: Required Version | F4: 5.0.0 | H4: Output Prob NF | I4: Automatic
A5: EXT REFS | B5: 0 | E5: Recommended Version | F5: 5.0.0 | H5: Input Value NF | I5: <NF>
A6: Def. Form | E6: Last Modified By Version | F6: 7.6.1 | H6: Input Prob NF | I6: Automatic
A7: Calc Macro | E7: Model GUID | F7: 167B739F
A8: Highest# | B8: 10
A10: Anchor Cell | B10: Branch Name | C10: bformtype | D10: valformula | E10: pbformula | F10: distribution | G10: cumPayoffFunction | H10: link | I10: ENDNODEFORMULA | J10: VAL | K10: PB | L10: GenInfo | M10: IntRefs | N10: RefRefs | O10: NodeNames | P10: Collapsed
A11: =Statistiques!$C$56 -> 0 | B11: =B1 -> Prévision --> Météo | C11: 0 | I11: DEFAULT | J11: =Statistiques!$B$56 -> 0 | K11: =Statistiques!$B$55 -> 0 | L11: 1,0,0,2,2,3,0,0,0 | M11: 0 | O11: =Statistiques!$C$55 -> Prévision | P11: FALSE
A12: =Statistiques!$D$52 -> 0 | B12: Clémente | C12: 0 | I12: DEFAULT | J12: =Statistiques!$C$52 -> 0 | K12: =Statistiques!$C$51 -> 0.45 | L12: 1,0,0,3,6,4,5,1,0,0 | M12: 0 | O12: =Statistiques!$D$51 -> Météo | P12: FALSE
A13: =Statistiques!$D$62 -> 0 | B13: Non-clémente | C13: 0 | I13: DEFAULT | J13: =Statistiques!$C$62 -> 0 | K13: =Statistiques!$C$61 -> 0.55 | L13: 1,0,0,3,9,7,8,1,0,0 | M13: 0 | O13: =Statistiques!$D$61 -> Météo | P13: FALSE
A14: =Statistiques!$E$50 -> 0 | B14: Nuageux | C14: 0 | H14: DEFAULT | I14: DEFAULT | J14: =Statistiques!$D$50 -> 0 | K14: =Statistiques!$D$49 -> 0.33333333 | L14: 4,0,0,0,2,0,0 | M14: 0 | P14: FALSE
A15: =Statistiques!$E$54 -> 0 | B15: Averse | C15: 0 | H15: DEFAULT | I15: DEFAULT | J15: =Statistiques!$D$54 -> 0 | K15: =Statistiques!$D$53 -> 0 | L15: 4,0,0,0,2,0,0 | M15: 0 | P15: FALSE
A16: =Statistiques!$E$48 -> 0 | B16: Ensoleillé | C16: 0 | H16: DEFAULT | I16: DEFAULT | J16: =Statistiques!$D$48 -> 0 | K16: =Statistiques!$D$47 -> 0.66666667 | L16: 4,0,0,0,2,0,0 | M16: 0 | P16: FALSE
A17: =Statistiques!$E$60 -> 0 | B17: Nuageux | C17: 0 | H17: DEFAULT | I17: DEFAULT | J17: =Statistiques!$D$60 -> 0 | K17: =Statistiques!$D$59 -> 0.27272727 | L17: 4,0,0,0,3,0,0 | M17: 0 | P17: FALSE
A18: =Statistiques!$E$64 -> 0 | B18: Averse | C18: 0 | H18: DEFAULT | I18: DEFAULT | J18: =Statistiques!$D$64 -> 0 | K18: =Statistiques!$D$63 -> 0.72727273 | L18: 4,0,0,0,3,0,0 | M18: 0 | P18: FALSE
A19: =Statistiques!$E$58 -> 0 | B19: Ensoleillé | C19: 0 | H19: DEFAULT | I19: DEFAULT | J19: =Statistiques!$D$58 -> 0 | K19: =Statistiques!$D$57 -> 0 | L19: 4,0,0,0,3,0,0 | M19: 0 | P19: FALSE

Sheet treeCalc_6
A1: Name | B1: Météo --> Prévision | E1: Ptree1 Compatibility | F1: 3 | H1: Output Label | K1: R-Value Ref. | L1: 100
A2: SheetRef | B2: =Statistiques!#REF! -> #REF! | E2: Eval. Function | F2: =_xll.PTreeEvaluate5(B3,$L$11:$L$20,$J$11:$J$20,$K$11:$K$20,$N$11:$N$20,$G$11:$G$20,,L1) -> 2084376
A3: GenInfo | B3: 0,6,1,0,0,Exponential, 0,0,-1,0,-1,-1,.0001 | E3: Creation Version | F3: 7.6.1 | H3: Output Value NF | I3: <NF>
A4: Def. Link | B4: = | E4: Required Version | F4: 5.0.0 | H4: Output Prob NF | I4: Automatic
A5: EXT REFS | B5: 0 | E5: Recommended Version | F5: 5.0.0 | H5: Input Value NF | I5: <NF>
A6: Def. Form | E6: Last Modified By Version | F6: 7.6.1 | H6: Input Prob NF | I6: Automatic
A7: Calc Macro | E7: Model GUID | F7: 24C6AF37
A8: Highest# | B8: 10
A10: Anchor Cell | B10: Branch Name | C10: bformtype | D10: valformula | E10: pbformula | F10: distribution | G10: cumPayoffFunction | H10: link | I10: ENDNODEFORMULA | J10: VAL | K10: PB | L10: GenInfo | M10: IntRefs | N10: RefRefs | O10: NodeNames | P10: Collapsed
A11: =Statistiques!$C$28 -> 0 | B11: =B1 -> Météo --> Prévision | C11: 0 | I11: DEFAULT | J11: =Statistiques!$B$28 -> 0 | K11: =Statistiques!$B$27 -> 0 | L11: 1,0,0,3,2,3,4,0,0,0 | M11: 0 | O11: =Statistiques!$C$27 -> Météo | P11: FALSE
A12: =Statistiques!$D$24 -> 0 | B12: Ensoleillé | C12: 0 | I12: DEFAULT | J12: =Statistiques!$C$24 -> 0 | K12: =Statistiques!$C$23 -> 0.3 | L12: 1,0,0,2,5,6,1,0,0 | M12: 0 | O12: =Statistiques!$D$23 -> Prévision | P12: FALSE
A13: =Statistiques!$D$32 -> 0 | B13: Nuageux | C13: 0 | I13: DEFAULT | J13: =Statistiques!$C$32 -> 0 | K13: =Statistiques!$C$31 -> 0.3 | L13: 1,0,0,2,7,8,1,0,0 | M13: 0 | O13: =Statistiques!$D$31 -> Prévision | P13: FALSE
A14: =Statistiques!$D$38 -> 0 | B14: Averse | C14: 0 | I14: DEFAULT | J14: =Statistiques!$C$38 -> 0 | K14: =Statistiques!$C$37 -> 0.4 | L14: 1,0,0,2,9,10,1,0,0 | M14: 0 | O14: =Statistiques!$D$37 -> Prévision | P14: FALSE
A15: =Statistiques!$E$22 -> 0 | B15: Clémente | C15: 0 | H15: DEFAULT | I15: DEFAULT | J15: =Statistiques!$D$22 -> 0 | K15: =Statistiques!$D$21 -> 1 | L15: 4,0,0,0,2,0,0 | M15: 0 | P15: FALSE
A16: =Statistiques!$E$26 -> 0 | B16: Non-clémente | C16: 0 | H16: DEFAULT | I16: DEFAULT | J16: =Statistiques!$D$26 -> 0 | K16: =Statistiques!$D$25 -> 0 | L16: 4,0,0,0,2,0,0 | M16: 0 | P16: FALSE
A17: =Statistiques!$E$30 -> 0 | B17: Clémente | C17: 0 | H17: DEFAULT | I17: DEFAULT | J17: =Statistiques!$D$30 -> 0 | K17: =Statistiques!$D$29 -> 0.5 | L17: 4,0,0,0,3,0,0 | M17: 0 | P17: FALSE
A18: =Statistiques!$E$34 -> 0 | B18: Non-clémente | C18: 0 | H18: DEFAULT | I18: DEFAULT | J18: =Statistiques!$D$34 -> 0 | K18: =Statistiques!$D$33 -> 0.5 | L18: 4,0,0,0,3,0,0 | M18: 0 | P18: FALSE
A19: =Statistiques!$E$36 -> 0 | B19: Clémente | C19: 0 | H19: DEFAULT | I19: DEFAULT | J19: =Statistiques!$D$36 -> 0 | K19: =Statistiques!$D$35 -> 0 | L19: 4,0,0,0,4,0,0 | M19: 0 | P19: FALSE
A20: =Statistiques!$E$40 -> 0 | B20: Non-clémente | C20: 0 | H20: DEFAULT | I20: DEFAULT | J20: =Statistiques!$D$40 -> 0 | K20: =Statistiques!$D$39 -> 1 | L20: 4,0,0,0,4,0,0 | M20: 0 | P20: FALSE
