Workbook

Sheet Modèle
A2: Paramètres
B3: Valeurs
A4: Frais de compensation environnementale | B4: 0.75
A5: ($/g de CFC déversé)
A6: Marché en phase 1 (en tonnes) | B6: 10
A7: Coût de recherche (en millions de dollars) | B7: 16
A8: Succès si recherche : Valeur | B8: 1
A9: Marché en phase 2 (en tonnes) | B9: 28
A10: Part du marché CFC selon loi | B10: 0.6
A13: Décisions
B14: Recherche + Produire Phase 1 et 2
A15: Entreprendre recherche | B15: 1
A16: Produire Phase I | B16: 1
A17: Production Phase 2 | B17: 1
A19: Conséquences
A20: Phase I
A21: Profits des ventes (en millions de dollars) | B21: =B16*$B$6 -> 10
A22: assumant 1$/g de profit
A23: Coûts recherche (en millions de dollars) | B23: =B15*$B$7 -> 16
A24: Coûts environnementaux (en millions de dollars) | B24: =B16*$B$6*$B$4 -> 7.5
A25: Profits (en millions de dollars) | B25: =B21-B23-B24 -> -13.5
A26: Phase I --> II
A27: Dupont découvre alternative | B27: =$B$8*B15 -> 1
A28: Phase II
A29: Production CFC | B29: =B17*(1-B27) -> 0
A30: Production alternative | B30: =B17*B27 -> 1
A31: Vente CFC | B31: =$B$10*B29*$B$9 -> 0
A32: Vente alternative | B32: =B30*$B$9 -> 28
A33: Profits des ventes (en millions de dollars) | B33: =B32+B31 -> 28
A34: assumant 1$/g de profit
A35: Coûts environnementaux (en millions de dollars) | B35: =$B$4*B31 -> 0
A36: Profits (en millions de dollars) | B36: =B33-B35 -> 28
A38: Profit Total (en millions de dollars) | B38: =B25+B36 -> 14.5

Sheet References
A2: Paramètres
B3: Valeurs | C3: Nominal | D3: Borne Inf | E3: Borne Sup
A4: Frais de compensation environnementale | B4: =C4 -> 0.75 | C4: 0.75 | D4: 0 | E4: 1.5
A5: ($/g de CFC déversé)
A6: Marché en phase 1 (en tonnes) | B6: =C6 -> 10 | C6: 10 | D6: 7 | E6: 11
A7: Coût de recherche (en millions de dollars) | B7: =C7 -> 16 | C7: 16 | D7: 14 | E7: 20
A8: Succès si recherche : Valeur | B8: =C8 -> 1 | C8: 1 | D8: 0 | E8: 1
A9: Marché en phase 2 (en tonnes) | B9: =C9 -> 28 | C9: 28 | D9: 20 | E9: 30
A10: Part du marché CFC selon loi | B10: =C10 -> 0.6 | C10: 0.6 | D10: 0 | E10: 1
A13: Décisions
B14: Rech. + Prod. Phase 1 & 2 | C14: Rech. + Prod. Phase 2 | D14: Prod. CFC Phase 1 et 2 | E14: Prod. CFC Phase 1 | F14: Arrêter tout
A15: Entreprendre recherche | B15: 1 | C15: 1 | D15: 0 | E15: 0 | F15: 0
A16: Produire Phase I | B16: 1 | C16: 0 | D16: 1 | E16: 1 | F16: 0
A17: Production Phase 2 | B17: 1 | C17: 1 | D17: 1 | E17: 0 | F17: 0
A19: Conséquences
A20: Phase I
A21: Profits des ventes (en millions de dollars) | B21: =B16*$B$6 -> 10 | C21: =C16*$B$6 -> 0 | D21: =D16*$B$6 -> 10 | E21: =E16*$B$6 -> 10 | F21: =F16*$B$6 -> 0
A22: assumant 1$/g de profit
A23: Coûts recherche (en millions de dollars) | B23: =B15*$B$7 -> 16 | C23: =C15*$B$7 -> 16 | D23: =D15*$B$7 -> 0 | E23: =E15*$B$7 -> 0 | F23: =F15*$B$7 -> 0
A24: Coûts environnementaux (en millions de dollars) | B24: =B16*$B$6*$B$4 -> 7.5 | C24: =C16*$B$6*$B$4 -> 0 | D24: =D16*$B$6*$B$4 -> 7.5 | E24: =E16*$B$6*$B$4 -> 7.5 | F24: =F16*$B$6*$B$4 -> 0
A25: Profits (en millions de dollars) | B25: =B21-B23-B24 -> -13.5 | C25: =C21-C23-C24 -> -16 | D25: =D21-D23-D24 -> 2.5 | E25: =E21-E23-E24 -> 2.5 | F25: =F21-F23-F24 -> 0
A26: Phase I --> II
A27: Dupont découvre alternative | B27: =$B$8*B15 -> 1 | C27: =$B$8*C15 -> 1 | D27: =$B$8*D15 -> 0 | E27: =$B$8*E15 -> 0 | F27: =$B$8*F15 -> 0
A28: Phase II
A29: Production CFC | B29: =B17*(1-B27) -> 0 | C29: =C17*(1-C27) -> 0 | D29: =D17*(1-D27) -> 1 | E29: =E17*(1-E27) -> 0 | F29: =F17*(1-F27) -> 0
A30: Production alternative | B30: =B17*B27 -> 1 | C30: =C17*C27 -> 1 | D30: =D17*D27 -> 0 | E30: =E17*E27 -> 0 | F30: =F17*F27 -> 0
A31: Vente CFC | B31: =$B$10*B29*$B$9 -> 0 | C31: =$B$10*C29*$B$9 -> 0 | D31: =$B$10*D29*$B$9 -> 16.8 | E31: =$B$10*E29*$B$9 -> 0 | F31: =$B$10*F29*$B$9 -> 0
A32: Vente alternative | B32: =B30*$B$9 -> 28 | C32: =C30*$B$9 -> 28 | D32: =D30*$B$9 -> 0 | E32: =E30*$B$9 -> 0 | F32: =F30*$B$9 -> 0
A33: Profits des ventes (en millions de dollars) | B33: =B32+B31 -> 28 | C33: =C32+C31 -> 28 | D33: =D32+D31 -> 16.8 | E33: =E32+E31 -> 0 | F33: =F32+F31 -> 0
A34: assumant 1$/g de profit
A35: Coûts environnementaux (en millions de dollars) | B35: =$B$4*B31 -> 0 | C35: =$B$4*C31 -> 0 | D35: =$B$4*D31 -> 12.6 | E35: =$B$4*E31 -> 0 | F35: =$B$4*F31 -> 0
A36: Profits (en millions de dollars) | B36: =B33-B35 -> 28 | C36: =C33-C35 -> 28 | D36: =D33-D35 -> 4.2 | E36: =E33-E35 -> 0 | F36: =F33-F35 -> 0
A38: Profit Total (en millions de dollars) | B38: =B25+B36 -> 14.5 | C38: =C25+C36 -> 12 | D38: =D25+D36 -> 6.7 | E38: =E25+E36 -> 2.5 | F38: =F25+F36 -> 0
A41: Analyse de sensibilité
B42: Sensibilité de la performance | E42: Paramètre | F42: Profit total
B43: Frais de compensation environnementale
C44: élevé | E44: =E4 -> 1.5
C45: probable | E45: =C4 -> 0.75
C46: bas | E46: =D4 -> 0
B47: Marché Phase 1 | F47: =B38 -> 14.5
...

Sheet Sensibilité
A1: Table de sensibilité | E1: Diagramme Araignée
E3: =A4 -> Frais de compensation environnementale | F3: =A8 -> Marché Phase 1 | G3: =A12 -> Coût de recherche | H3: =A16 -> Succès si recherche | I3: =A20 -> Marché Phase 2 | J3: =A24 -> Part du marché Phase 2
A4: Frais de compensation environnementale
B5: élevé | C5: =References!E44 -> 1.5 | D5: =References!F44 -> 0 | E5: =(C5-$C$6)/$C$6 -> 1
B6: probable | C6: =References!E45 -> 0.75 | D6: =References!F45 -> 0 | E6: =(C6-$C$6)/$C$6 -> 0
B7: bas | C7: =References!E46 -> 0 | D7: =References!F46 -> 0 | E7: =(C7-$C$6)/$C$6 -> -1
A8: Marché Phase 1
B9: élevé | C9: =References!E48 -> 11 | D9: =References!F48 -> 14.75 | F9: =(C9-$C$10)/$C$10 -> 0.1
B10: probable | C10: =References!E49 -> 10 | D10: =References!F49 -> 14.5 | F10: =(C10-$C$10)/$C$10 -> 0
B11: bas | C11: =References!E50 -> 7 | D11: =References!F50 -> 13.75 | F11: =(C11-$C$10)/$C$10 -> -0.3
A12: Coût de recherche
B13: élevé | C13: =References!E52 -> 20 | D13: =References!F52 -> 10.5 | G13: =(C13-$C$14)/$C$14 -> 0.25
B14: probable | C14: =References!E53 -> 16 | D14: =References!F53 -> 14.5 | G14: =(C14-$C$14)/$C$14 -> 0
B15: bas | C15: =References!E54 -> 14 | D15: =References!F54 -> 16.5 | G15: =(C15-$C$14)/$C$14 -> -0.125
A16: Succès si recherche
B17: élevé | C17: =References!E56 -> 1 | D17: =References!F56 -> 14.5 | H17: =(C17-$C$18)/$C$18 -> 0
B18: probable | C18: =References!E57 -> 1 | D18: =References!F57 -> 14.5 | H18: =(C18-$C$18)/$C$18 -> 0
B19: bas | C19: =References!E58 -> 0 | D19: =References!F58 -> -9.3 | H19: =(C19-$C$18)/$C$18 -> -1
A20: Marché Phase 2
B21: élevé | C21: =References!E60 -> 30 | D21: =References!F60 -> 16.5 | I21: =(C21-$C$22)/$C$22 -> 0.071428571
B22: probable | C22: =References!E61 -> 28 | D22: =References!F61 -> 14.5 | I22: =(C22-$C$22)/$C$22 -> 0
B23: bas | C23: =References!E62 -> 20 | D23: =References!F62 -> 6.5 | I23: =(C23-$C$22)/$C$22 -> -0.28571429
A24: Part du marché Phase 2
B25: élevé | C25: =References!E64 -> 1 | D25: =References!F64 -> 14.5 | J25: =(C25-$C$26)/$C$26 -> 0.66666667
B26: probable | C26: =References!E65 -> 0.6 | D26: =References!F65 -> 14.5 | J26: =(C26-$C$26)/$C$26 -> 0
B27: bas | C27: =References!E66 -> 0 | D27: =References!F66 -> 14.5 | J27: =(C27-$C$26)/$C$26 -> -1
E29: Diagramme Tornade
E31: =E3 -> Frais de compensation environnementale | F31: =F3 -> Marché Phase 1 | G31: =G3 -> Coût de recherche | H31: =H3 -> Succès si recherche | I31: =I3 -> Marché Phase 2 | J31: =A47 -> Part du marché Phase 2
A32: =A4 -> Frais de compensation environnementale | B32: =ABS(D32-D34) -> 0 | C32: =RANK(B32,$B$32:$B$47,1) -> 1 | D32: =D5 -> 0 | E32: =C32 -> 1
D33: =D6 -> 0 | E33: =E32 -> 1
D34: =D7 -> 0 | E34: =E33 -> 1
A35: =A8 -> Marché Phase 1 | B35: =ABS(D35-D37) -> 1 | C35: =RANK(B35,$B$32:$B$47,1) -> 3 | D35: =D9 -> 14.75 | F35: =C35 -> 3
D36: =D10 -> 14.5 | F36: =F35 -> 3
D37: =D11 -> 13.75 | F37: =F36 -> 3
A38: =A12 -> Coût de recherche | B38: =ABS(D38-D40) -> 6 | C38: =RANK(B38,$B$32:$B$47,1) -> 4 | D38: =D13 -> 10.5 | G38: =C38 -> 4
D39: =D14 -> 14.5 | G39: =G38 -> 4
D40: =D15 -> 16.5 | G40: =G38 -> 4
A41: =A16 -> Succès si recherche | B41: =ABS(D41-D43) -> 23.8 | C41: =RANK(B41,$B$32:$B$47,1) -> 6 | D41: =D17 -> 14.5 | H41: =C41 -> 6
D42: =D18 -> 14.5 | H42: =H41 -> 6
D43: =D19 -> -9.3 | H43: =H42 -> 6
...

Sheet Arc_en_ciel1
A5: Frais de compensation environnementale
B6: min | C6: =References!D70 -> 0 | D6: nb de pas | E6: 10
B7: max | C7: =References!D71 -> 1.5 | D7: taille des pas | E7: =(C7-C6)/E6 -> 0.15
E8: =References!F72 -> Rech. + Prod. Phase 1 & 2 | F8: =References!G72 -> Rech. + Prod. Phase 2 | G8: =References!H72 -> Prod. CFC Phase 1 et 2 | H8: =References!I72 -> Prod. CFC Phase 1 | I8: =References!J72 -> Arrêter tout
C9: élevé | D9: =References!E74 -> 1.5 | E9: =References!F74 -> 7 | F9: =References!G74 -> 12 | G9: =References!H74 -> -13.4 | H9: =References!I74 -> -5 | I9: =References!J74 -> 0
D10: =References!E75 -> 1.35 | E10: =References!F75 -> 8.5 | F10: =References!G75 -> 12 | G10: =References!H75 -> -9.38 | H10: =References!I75 -> -3.5 | I10: =References!J75 -> 0
D11: =References!E76 -> 1.2 | E11: =References!F76 -> 10 | F11: =References!G76 -> 12 | G11: =References!H76 -> -5.36 | H11: =References!I76 -> -2 | I11: =References!J76 -> 0
D12: =References!E77 -> 1.05 | E12: =References!F77 -> 11.5 | F12: =References!G77 -> 12 | G12: =References!H77 -> -1.34 | H12: =References!I77 -> -0.5 | I12: =References!J77 -> 0
D13: =References!E78 -> 0.9 | E13: =References!F78 -> 13 | F13: =References!G78 -> 12 | G13: =References!H78 -> 2.68 | H13: =References!I78 -> 1 | I13: =References!J78 -> 0
D14: =References!E79 -> 0.75 | E14: =References!F79 -> 14.5 | F14: =References!G79 -> 12 | G14: =References!H79 -> 6.7 | H14: =References!I79 -> 2.5 | I14: =References!J79 -> 0
D15: =References!E80 -> 0.6 | E15: =References!F80 -> 16 | F15: =References!G80 -> 12 | G15: =References!H80 -> 10.72 | H15: =References!I80 -> 4 | I15: =References!J80 -> 0
D16: =References!E81 -> 0.45 | E16: =References!F81 -> 17.5 | F16: =References!G81 -> 12 | G16: =References!H81 -> 14.74 | H16: =References!I81 -> 5.5 | I16: =References!J81 -> 0
D17: =References!E82 -> 0.3 | E17: =References!F82 -> 19 | F17: =References!G82 -> 12 | G17: =References!H82 -> 18.76 | H17: =References!I82 -> 7 | I17: =References!J82 -> 0
D18: =References!E83 -> 0.15 | E18: =References!F83 -> 20.5 | F18: =References!G83 -> 12 | G18: =References!H83 -> 22.78 | H18: =References!I83 -> 8.5 | I18: =References!J83 -> 0
C19: bas | D19: =References!E84 -> 0 | E19: =References!F84 -> 22 | F19: =References!G84 -> 12 | G19: =References!H84 -> 26.8 | H19: =References!I84 -> 10 | I19: =References!J84 -> 0

Sheet Arc_en_ciel2
A1: Sensibilité de la décision (2 paramètres)
A2: =References!B87 -> Rech. + Prod. Phase 1 & 2 | E2: Frais de compensation environnementale
D3: Profit | E3: =References!F88 -> 1.5 | F3: =References!G88 -> 1.35 | G3: =References!H88 -> 1.2 | H3: =References!I88 -> 1.05 | I3: =References!J88 -> 0.9 | J3: =References!K88 -> 0.75 | K3: =References!L88 -> 0.6 | L3: =References!M88 -> 0.45 | ... O3: =References!P88 -> 0
C4: Part du marché Phase 2 | D4: =References!E89 -> 0 | E4: =References!F89 -> 0 | F4: =References!G89 -> 0 | G4: =References!H89 -> 0 | H4: =References!I89 -> 0 | I4: =References!J89 -> 0 | J4: =References!K89 -> 0 | K4: =References!L89 -> 0 | ... O4: =References!P89 -> 0
D5: =References!E90 -> 0.1 | E5: =References!F90 -> 0 | F5: =References!G90 -> 0 | G5: =References!H90 -> 0 | H5: =References!I90 -> 0 | I5: =References!J90 -> 0 | J5: =References!K90 -> 0 | K5: =References!L90 -> 0 | ... O5: =References!P90 -> 0
D6: =References!E91 -> 0.2 | E6: =References!F91 -> 0 | F6: =References!G91 -> 0 | G6: =References!H91 -> 0 | H6: =References!I91 -> 0 | I6: =References!J91 -> 0 | J6: =References!K91 -> 0 | K6: =References!L91 -> 0 | ... O6: =References!P91 -> 0
D7: =References!E92 -> 0.3 | E7: =References!F92 -> 0 | F7: =References!G92 -> 0 | G7: =References!H92 -> 0 | H7: =References!I92 -> 0 | I7: =References!J92 -> 0 | J7: =References!K92 -> 0 | K7: =References!L92 -> 0 | ... O7: =References!P92 -> 0
D8: =References!E93 -> 0.4 | E8: =References!F93 -> 0 | F8: =References!G93 -> 0 | G8: =References!H93 -> 0 | H8: =References!I93 -> 0 | I8: =References!J93 -> 0 | J8: =References!K93 -> 0 | K8: =References!L93 -> 0 | ... O8: =References!P93 -> 0
D9: =References!E94 -> 0.5 | E9: =References!F94 -> 0 | F9: =References!G94 -> 0 | G9: =References!H94 -> 0 | H9: =References!I94 -> 0 | I9: =References!J94 -> 0 | J9: =References!K94 -> 0 | K9: =References!L94 -> 0 | ... O9: =References!P94 -> 0
D10: =References!E95 -> 0.6 | E10: =References!F95 -> 0 | F10: =References!G95 -> 0 | G10: =References!H95 -> 0 | H10: =References!I95 -> 0 | I10: =References!J95 -> 0 | J10: =References!K95 -> 0 | K10: =References!L95 -> 0 | ... O10: =References!P95 -> 0
D11: =References!E96 -> 0.7 | E11: =References!F96 -> 0 | F11: =References!G96 -> 0 | G11: =References!H96 -> 0 | H11: =References!I96 -> 0 | I11: =References!J96 -> 0 | J11: =References!K96 -> 0 | K11: =References!L96 -> 0 | ... O11: =References!P96 -> 0
D12: =References!E97 -> 0.8 | E12: =References!F97 -> 0 | F12: =References!G97 -> 0 | G12: =References!H97 -> 0 | H12: =References!I97 -> 0 | I12: =References!J97 -> 0 | J12: =References!K97 -> 0 | K12: =References!L97 -> 0 | ... O12: =References!P97 -> 0
D13: =References!E98 -> 0.9 | E13: =References!F98 -> 0 | F13: =References!G98 -> 0 | G13: =References!H98 -> 0 | H13: =References!I98 -> 0 | I13: =References!J98 -> 0 | J13: =References!K98 -> 0 | K13: =References!L98 -> 0 | ... O13: =References!P98 -> 0
D14: =References!E99 -> 1 | E14: =References!F99 -> 0 | F14: =References!G99 -> 0 | G14: =References!H99 -> 0 | H14: =References!I99 -> 0 | I14: =References!J99 -> 0 | J14: =References!K99 -> 0 | K14: =References!L99 -> 0 | ... O14: =References!P99 -> 0
A16: =References!B101 -> Rech. + Prod. Phase 2
D17: Profit | E17: =References!F102 -> 1.5 | F17: =References!G102 -> 1.35 | G17: =References!H102 -> 1.2 | H17: =References!I102 -> 1.05 | I17: =References!J102 -> 0.9 | J17: =References!K102 -> 0.75 | K17: =References!L102 -> 0.6 | L17: =References!M102 -> 0.45 | ... O17: =References!P102 -> 0
D18: =References!E103 -> 0 | E18: =References!F103 -> 12 | F18: =References!G103 -> 12 | G18: =References!H103 -> 12 | H18: =References!I103 -> 12 | I18: =References!J103 -> 12 | J18: =References!K103 -> 12 | K18: =References!L103 -> 12 | ... O18: =References!P103 -> 12
D19: =References!E104 -> 0.1 | E19: =References!F104 -> 12 | F19: =References!G104 -> 12 | G19: =References!H104 -> 12 | H19: =References!I104 -> 12 | I19: =References!J104 -> 12 | J19: =References!K104 -> 12 | K19: =References!L104 -> 12 | ... O19: =References!P104 -> 12
D20: =References!E105 -> 0.2 | E20: =References!F105 -> 12 | F20: =References!G105 -> 12 | G20: =References!H105 -> 12 | H20: =References!I105 -> 12 | I20: =References!J105 -> 12 | J20: =References!K105 -> 12 | K20: =References!L105 -> 12 | ... O20: =References!P105 -> 12
D21: =References!E106 -> 0.3 | E21: =References!F106 -> 12 | F21: =References!G106 -> 12 | G21: =References!H106 -> 12 | H21: =References!I106 -> 12 | I21: =References!J106 -> 12 | J21: =References!K106 -> 12 | K21: =References!L106 -> 12 | ... O21: =References!P106 -> 12
D22: =References!E107 -> 0.4 | E22: =References!F107 -> 12 | F22: =References!G107 -> 12 | G22: =References!H107 -> 12 | H22: =References!I107 -> 12 | I22: =References!J107 -> 12 | J22: =References!K107 -> 12 | K22: =References!L107 -> 12 | ... O22: =References!P107 -> 12
D23: =References!E108 -> 0.5 | E23: =References!F108 -> 12 | F23: =References!G108 -> 12 | G23: =References!H108 -> 12 | H23: =References!I108 -> 12 | I23: =References!J108 -> 12 | J23: =References!K108 -> 12 | K23: =References!L108 -> 12 | ... O23: =References!P108 -> 12
D24: =References!E109 -> 0.6 | E24: =References!F109 -> 12 | F24: =References!G109 -> 12 | G24: =References!H109 -> 12 | H24: =References!I109 -> 12 | I24: =References!J109 -> 12 | J24: =References!K109 -> 12 | K24: =References!L109 -> 12 | ... O24: =References!P109 -> 12
D25: =References!E110 -> 0.7 | E25: =References!F110 -> 12 | F25: =References!G110 -> 12 | G25: =References!H110 -> 12 | H25: =References!I110 -> 12 | I25: =References!J110 -> 12 | J25: =References!K110 -> 12 | K25: =References!L110 -> 12 | ... O25: =References!P110 -> 12
D26: =References!E111 -> 0.8 | E26: =References!F111 -> 12 | F26: =References!G111 -> 12 | G26: =References!H111 -> 12 | H26: =References!I111 -> 12 | I26: =References!J111 -> 12 | J26: =References!K111 -> 12 | K26: =References!L111 -> 12 | ... O26: =References!P111 -> 12
D27: =References!E112 -> 0.9 | E27: =References!F112 -> 12 | F27: =References!G112 -> 12 | G27: =References!H112 -> 12 | H27: =References!I112 -> 12 | I27: =References!J112 -> 12 | J27: =References!K112 -> 12 | K27: =References!L112 -> 12 | ... O27: =References!P112 -> 12
D28: =References!E113 -> 1 | E28: =References!F113 -> 12 | F28: =References!G113 -> 12 | G28: =References!H113 -> 12 | H28: =References!I113 -> 12 | I28: =References!J113 -> 12 | J28: =References!K113 -> 12 | K28: =References!L113 -> 12 | ... O28: =References!P113 -> 12
A30: =References!B115 -> Prod. CFC Phase 1 et 2
D31: Profit | E31: =References!F116 -> 1.5 | F31: =References!G116 -> 1.35 | G31: =References!H116 -> 1.2 | H31: =References!I116 -> 1.05 | I31: =References!J116 -> 0.9 | J31: =References!K116 -> 0.75 | K31: =References!L116 -> 0.6 | L31: =References!M116 -> 0.45 | ... O31: =References!P116 -> 0
D32: =References!E117 -> 0 | E32: =References!F117 -> -5 | F32: =References!G117 -> -3.5 | G32: =References!H117 -> -2 | H32: =References!I117 -> -0.5 | I32: =References!J117 -> 1 | J32: =References!K117 -> 2.5 | K32: =References!L117 -> 4 | ... O32: =References!P117 -> 10
D33: =References!E118 -> 0.1 | E33: =References!F118 -> -6.4 | F33: =References!G118 -> -4.48 | G33: =References!H118 -> -2.56 | H33: =References!I118 -> -0.64 | I33: =References!J118 -> 1.28 | J33: =References!K118 -> 3.2 | K33: =References!L118 -> 5.12 | ... O33: =References!P118 -> 12.8
D34: =References!E119 -> 0.2 | E34: =References!F119 -> -7.8 | F34: =References!G119 -> -5.46 | G34: =References!H119 -> -3.12 | H34: =References!I119 -> -0.78 | I34: =References!J119 -> 1.56 | J34: =References!K119 -> 3.9 | K34: =References!L119 -> 6.24 | ... O34: =References!P119 -> 15.6
D35: =References!E120 -> 0.3 | E35: =References!F120 -> -9.2 | F35: =References!G120 -> -6.44 | G35: =References!H120 -> -3.68 | H35: =References!I120 -> -0.92 | I35: =References!J120 -> 1.84 | J35: =References!K120 -> 4.6 | K35: =References!L120 -> 7.36 | ... O35: =References!P120 -> 18.4
D36: =References!E121 -> 0.4 | E36: =References!F121 -> -10.6 | F36: =References!G121 -> -7.42 | G36: =References!H121 -> -4.24 | H36: =References!I121 -> -1.06 | I36: =References!J121 -> 2.12 | J36: =References!K121 -> 5.3 | K36: =References!L121 -> 8.48 | ... O36: =References!P121 -> 21.2
D37: =References!E122 -> 0.5 | E37: =References!F122 -> -12 | F37: =References!G122 -> -8.4 | G37: =References!H122 -> -4.8 | H37: =References!I122 -> -1.2 | I37: =References!J122 -> 2.4 | J37: =References!K122 -> 6 | K37: =References!L122 -> 9.6 | ... O37: =References!P122 -> 24
D38: =References!E123 -> 0.6 | E38: =References!F123 -> -13.4 | F38: =References!G123 -> -9.38 | G38: =References!H123 -> -5.36 | H38: =References!I123 -> -1.34 | I38: =References!J123 -> 2.68 | J38: =References!K123 -> 6.7 | K38: =References!L123 -> 10.72 | ... O38: =References!P123 -> 26.8
D39: =References!E124 -> 0.7 | E39: =References!F124 -> -14.8 | F39: =References!G124 -> -10.36 | G39: =References!H124 -> -5.92 | H39: =References!I124 -> -1.48 | I39: =References!J124 -> 2.96 | J39: =References!K124 -> 7.4 | K39: =References!L124 -> 11.84 | ... O39: =References!P124 -> 29.6
D40: =References!E125 -> 0.8 | E40: =References!F125 -> -16.2 | F40: =References!G125 -> -11.34 | G40: =References!H125 -> -6.48 | H40: =References!I125 -> -1.62 | I40: =References!J125 -> 3.24 | J40: =References!K125 -> 8.1 | K40: =References!L125 -> 12.96 | ... O40: =References!P125 -> 32.4
D41: =References!E126 -> 0.9 | E41: =References!F126 -> -17.6 | F41: =References!G126 -> -12.32 | G41: =References!H126 -> -7.04 | H41: =References!I126 -> -1.76 | I41: =References!J126 -> 3.52 | J41: =References!K126 -> 8.8 | K41: =References!L126 -> 14.08 | ... O41: =References!P126 -> 35.2
D42: =References!E127 -> 1 | E42: =References!F127 -> -19 | F42: =References!G127 -> -13.3 | G42: =References!H127 -> -7.6 | H42: =References!I127 -> -1.9 | I42: =References!J127 -> 3.8 | J42: =References!K127 -> 9.5 | K42: =References!L127 -> 15.2 | ... O42: =References!P127 -> 38
...
